
WARNING 2023-11-29 15:48:33,410 django.request Thread-2 3268 log log.py 241 django.request log_response 4064 Not Found: /favicon.ico
WARNING 2023-11-29 15:48:33,413 django.server Thread-2 3268 basehttp basehttp.py 212 django.server log_message 4064 "GET /favicon.ico HTTP/1.1" 404 26333
WARNING 2023-11-29 15:48:33,516 django.request Thread-2 3268 log log.py 241 django.request log_response 4064 Not Found: /favicon.ico
WARNING 2023-11-29 15:48:33,519 django.server Thread-2 3268 basehttp basehttp.py 212 django.server log_message 4064 "GET /favicon.ico HTTP/1.1" 404 26332
WARNING 2023-11-29 15:48:36,801 django.server Thread-5 11724 basehttp basehttp.py 212 django.server log_message 4064 "GET /static/images/favicon.png HTTP/1.1" 404 1914
WARNING 2023-11-29 15:48:36,881 django.server Thread-4 11244 basehttp basehttp.py 212 django.server log_message 4064 "GET /static/images/favicon.png HTTP/1.1" 404 1914
WARNING 2023-11-29 15:48:49,960 django.server Thread-2 3268 basehttp basehttp.py 212 django.server log_message 4064 "GET /static/images/favicon.png HTTP/1.1" 404 1914
WARNING 2023-11-29 15:48:50,032 django.server Thread-3 9100 basehttp basehttp.py 212 django.server log_message 4064 "GET /static/images/favicon.png HTTP/1.1" 404 1914
WARNING 2023-11-29 15:55:32,627 django.request Thread-7 11672 log log.py 241 django.request log_response 4064 Not Found: /favicon.ico
WARNING 2023-11-29 15:55:32,627 django.server Thread-7 11672 basehttp basehttp.py 212 django.server log_message 4064 "GET /favicon.ico HTTP/1.1" 404 26333
WARNING 2023-11-29 15:55:32,719 django.request Thread-7 11672 log log.py 241 django.request log_response 4064 Not Found: /favicon.ico
WARNING 2023-11-29 15:55:32,719 django.server Thread-7 11672 basehttp basehttp.py 212 django.server log_message 4064 "GET /favicon.ico HTTP/1.1" 404 26332
WARNING 2023-11-29 17:28:57,198 django.server Thread-10 12436 basehttp basehttp.py 212 django.server log_message 4064 "GET /static/images/favicon.png HTTP/1.1" 404 1914
WARNING 2023-11-29 17:28:57,361 django.server Thread-11 2976 basehttp basehttp.py 212 django.server log_message 4064 "GET /static/images/favicon.png HTTP/1.1" 404 1914
WARNING 2023-11-29 18:43:43,568 django.server Thread-12 2500 basehttp basehttp.py 212 django.server log_message 4064 "GET /static/images/favicon.png HTTP/1.1" 404 1914
WARNING 2023-11-29 18:43:43,649 django.server Thread-13 7640 basehttp basehttp.py 212 django.server log_message 4064 "GET /static/images/favicon.png HTTP/1.1" 404 1914
WARNING 2023-11-29 18:43:49,061 django.server Thread-16 11064 basehttp basehttp.py 212 django.server log_message 4064 "GET /static/images/favicon.png HTTP/1.1" 404 1914
WARNING 2023-11-29 18:43:49,276 django.server Thread-15 5628 basehttp basehttp.py 212 django.server log_message 4064 "GET /static/images/favicon.png HTTP/1.1" 404 1914
ERROR 2023-11-29 18:43:52,798 django.request Thread-14 9868 log log.py 241 django.request log_response 4064 Internal Server Error: /profile/
Traceback (most recent call last):
  File "C:\Users\aky\AppData\Local\Programs\Python\Python38\courseu\lib\site-packages\django\template\base.py", line 880, in _resolve_lookup
    current = current[bit]
  File "C:\Users\aky\AppData\Local\Programs\Python\Python38\courseu\lib\site-packages\django\utils\functional.py", line 268, in inner
    return func(_wrapped, *args)
TypeError: 'User' object is not subscriptable

During handling of the above exception, another exception occurred:

Traceback (most recent call last):
  File "C:\Users\aky\AppData\Local\Programs\Python\Python38\courseu\lib\site-packages\django\db\models\fields\related_descriptors.py", line 473, in __get__
    rel_obj = self.related.get_cached_value(instance)
  File "C:\Users\aky\AppData\Local\Programs\Python\Python38\courseu\lib\site-packages\django\db\models\fields\mixins.py", line 15, in get_cached_value
    return instance._state.fields_cache[cache_name]
KeyError: 'userprofile'

During handling of the above exception, another exception occurred:

Traceback (most recent call last):
  File "C:\Users\aky\AppData\Local\Programs\Python\Python38\courseu\lib\site-packages\django\db\backends\utils.py", line 89, in _execute
    return self.cursor.execute(sql, params)
  File "C:\Users\aky\AppData\Local\Programs\Python\Python38\courseu\lib\site-packages\django\db\backends\mysql\base.py", line 75, in execute
    return self.cursor.execute(query, args)
  File "C:\Users\aky\AppData\Local\Programs\Python\Python38\courseu\lib\site-packages\MySQLdb\cursors.py", line 179, in execute
    res = self._query(mogrified_query)
  File "C:\Users\aky\AppData\Local\Programs\Python\Python38\courseu\lib\site-packages\MySQLdb\cursors.py", line 330, in _query
    db.query(q)
  File "C:\Users\aky\AppData\Local\Programs\Python\Python38\courseu\lib\site-packages\MySQLdb\connections.py", line 255, in query
    _mysql.connection.query(self, query)
MySQLdb.ProgrammingError: (1146, "Table 'courseu_db.website_userprofile' doesn't exist")

The above exception was the direct cause of the following exception:

Traceback (most recent call last):
  File "C:\Users\aky\AppData\Local\Programs\Python\Python38\courseu\lib\site-packages\django\core\handlers\exception.py", line 55, in inner
    response = get_response(request)
  File "C:\Users\aky\AppData\Local\Programs\Python\Python38\courseu\lib\site-packages\django\core\handlers\base.py", line 197, in _get_response
    response = wrapped_callback(request, *callback_args, **callback_kwargs)
  File "C:\Users\aky\AppData\Local\Programs\Python\Python38\courseu\lib\site-packages\django\contrib\auth\decorators.py", line 23, in _wrapper_view
    return view_func(request, *args, **kwargs)
  File "C:\Users\aky\AppData\Local\Programs\Python\Python38\eng_ver\apps\website\views.py", line 257, in user_profile
    return render(request, 'user/user_profile.html', context)
  File "C:\Users\aky\AppData\Local\Programs\Python\Python38\courseu\lib\site-packages\django\shortcuts.py", line 24, in render
    content = loader.render_to_string(template_name, context, request, using=using)
  File "C:\Users\aky\AppData\Local\Programs\Python\Python38\courseu\lib\site-packages\django\template\loader.py", line 62, in render_to_string
    return template.render(context, request)
  File "C:\Users\aky\AppData\Local\Programs\Python\Python38\courseu\lib\site-packages\django\template\backends\django.py", line 61, in render
    return self.template.render(context)
  File "C:\Users\aky\AppData\Local\Programs\Python\Python38\courseu\lib\site-packages\django\template\base.py", line 175, in render
    return self._render(context)
  File "C:\Users\aky\AppData\Local\Programs\Python\Python38\courseu\lib\site-packages\django\test\utils.py", line 112, in instrumented_test_render
    return self.nodelist.render(context)
  File "C:\Users\aky\AppData\Local\Programs\Python\Python38\courseu\lib\site-packages\django\template\base.py", line 1005, in render
    return SafeString("".join([node.render_annotated(context) for node in self]))
  File "C:\Users\aky\AppData\Local\Programs\Python\Python38\courseu\lib\site-packages\django\template\base.py", line 1005, in <listcomp>
    return SafeString("".join([node.render_annotated(context) for node in self]))
  File "C:\Users\aky\AppData\Local\Programs\Python\Python38\courseu\lib\site-packages\django\template\base.py", line 966, in render_annotated
    return self.render(context)
  File "C:\Users\aky\AppData\Local\Programs\Python\Python38\courseu\lib\site-packages\django\template\loader_tags.py", line 157, in render
    return compiled_parent._render(context)
  File "C:\Users\aky\AppData\Local\Programs\Python\Python38\courseu\lib\site-packages\django\test\utils.py", line 112, in instrumented_test_render
    return self.nodelist.render(context)
  File "C:\Users\aky\AppData\Local\Programs\Python\Python38\courseu\lib\site-packages\django\template\base.py", line 1005, in render
    return SafeString("".join([node.render_annotated(context) for node in self]))
  File "C:\Users\aky\AppData\Local\Programs\Python\Python38\courseu\lib\site-packages\django\template\base.py", line 1005, in <listcomp>
    return SafeString("".join([node.render_annotated(context) for node in self]))
  File "C:\Users\aky\AppData\Local\Programs\Python\Python38\courseu\lib\site-packages\django\template\base.py", line 966, in render_annotated
    return self.render(context)
  File "C:\Users\aky\AppData\Local\Programs\Python\Python38\courseu\lib\site-packages\django\template\defaulttags.py", line 321, in render
    return nodelist.render(context)
  File "C:\Users\aky\AppData\Local\Programs\Python\Python38\courseu\lib\site-packages\django\template\base.py", line 1005, in render
    return SafeString("".join([node.render_annotated(context) for node in self]))
  File "C:\Users\aky\AppData\Local\Programs\Python\Python38\courseu\lib\site-packages\django\template\base.py", line 1005, in <listcomp>
    return SafeString("".join([node.render_annotated(context) for node in self]))
  File "C:\Users\aky\AppData\Local\Programs\Python\Python38\courseu\lib\site-packages\django\template\base.py", line 966, in render_annotated
    return self.render(context)
  File "C:\Users\aky\AppData\Local\Programs\Python\Python38\courseu\lib\site-packages\django\template\loader_tags.py", line 63, in render
    result = block.nodelist.render(context)
  File "C:\Users\aky\AppData\Local\Programs\Python\Python38\courseu\lib\site-packages\django\template\base.py", line 1005, in render
    return SafeString("".join([node.render_annotated(context) for node in self]))
  File "C:\Users\aky\AppData\Local\Programs\Python\Python38\courseu\lib\site-packages\django\template\base.py", line 1005, in <listcomp>
    return SafeString("".join([node.render_annotated(context) for node in self]))
  File "C:\Users\aky\AppData\Local\Programs\Python\Python38\courseu\lib\site-packages\django\template\base.py", line 966, in render_annotated
    return self.render(context)
  File "C:\Users\aky\AppData\Local\Programs\Python\Python38\courseu\lib\site-packages\django\template\defaulttags.py", line 321, in render
    return nodelist.render(context)
  File "C:\Users\aky\AppData\Local\Programs\Python\Python38\courseu\lib\site-packages\django\template\base.py", line 1005, in render
    return SafeString("".join([node.render_annotated(context) for node in self]))
  File "C:\Users\aky\AppData\Local\Programs\Python\Python38\courseu\lib\site-packages\django\template\base.py", line 1005, in <listcomp>
    return SafeString("".join([node.render_annotated(context) for node in self]))
  File "C:\Users\aky\AppData\Local\Programs\Python\Python38\courseu\lib\site-packages\django\template\base.py", line 966, in render_annotated
    return self.render(context)
  File "C:\Users\aky\AppData\Local\Programs\Python\Python38\courseu\lib\site-packages\django\template\defaulttags.py", line 314, in render
    match = condition.eval(context)
  File "C:\Users\aky\AppData\Local\Programs\Python\Python38\courseu\lib\site-packages\django\template\defaulttags.py", line 877, in eval
    return self.value.resolve(context, ignore_failures=True)
  File "C:\Users\aky\AppData\Local\Programs\Python\Python38\courseu\lib\site-packages\django\template\base.py", line 715, in resolve
    obj = self.var.resolve(context)
  File "C:\Users\aky\AppData\Local\Programs\Python\Python38\courseu\lib\site-packages\django\template\base.py", line 847, in resolve
    value = self._resolve_lookup(context)
  File "C:\Users\aky\AppData\Local\Programs\Python\Python38\courseu\lib\site-packages\django\template\base.py", line 890, in _resolve_lookup
    current = getattr(current, bit)
  File "C:\Users\aky\AppData\Local\Programs\Python\Python38\courseu\lib\site-packages\django\utils\functional.py", line 268, in inner
    return func(_wrapped, *args)
  File "C:\Users\aky\AppData\Local\Programs\Python\Python38\courseu\lib\site-packages\django\db\models\fields\related_descriptors.py", line 481, in __get__
    rel_obj = self.get_queryset(instance=instance).get(**filter_args)
  File "C:\Users\aky\AppData\Local\Programs\Python\Python38\courseu\lib\site-packages\django\db\models\query.py", line 633, in get
    num = len(clone)
  File "C:\Users\aky\AppData\Local\Programs\Python\Python38\courseu\lib\site-packages\django\db\models\query.py", line 380, in __len__
    self._fetch_all()
  File "C:\Users\aky\AppData\Local\Programs\Python\Python38\courseu\lib\site-packages\django\db\models\query.py", line 1881, in _fetch_all
    self._result_cache = list(self._iterable_class(self))
  File "C:\Users\aky\AppData\Local\Programs\Python\Python38\courseu\lib\site-packages\django\db\models\query.py", line 91, in __iter__
    results = compiler.execute_sql(
  File "C:\Users\aky\AppData\Local\Programs\Python\Python38\courseu\lib\site-packages\django\db\models\sql\compiler.py", line 1562, in execute_sql
    cursor.execute(sql, params)
  File "C:\Users\aky\AppData\Local\Programs\Python\Python38\courseu\lib\site-packages\debug_toolbar\panels\sql\tracking.py", line 252, in execute
    return self._record(super().execute, sql, params)
  File "C:\Users\aky\AppData\Local\Programs\Python\Python38\courseu\lib\site-packages\debug_toolbar\panels\sql\tracking.py", line 177, in _record
    return method(sql, params)
  File "C:\Users\aky\AppData\Local\Programs\Python\Python38\courseu\lib\site-packages\django\db\backends\utils.py", line 102, in execute
    return super().execute(sql, params)
  File "C:\Users\aky\AppData\Local\Programs\Python\Python38\courseu\lib\site-packages\django\db\backends\utils.py", line 67, in execute
    return self._execute_with_wrappers(
  File "C:\Users\aky\AppData\Local\Programs\Python\Python38\courseu\lib\site-packages\django\db\backends\utils.py", line 80, in _execute_with_wrappers
    return executor(sql, params, many, context)
  File "C:\Users\aky\AppData\Local\Programs\Python\Python38\courseu\lib\site-packages\django\db\backends\utils.py", line 89, in _execute
    return self.cursor.execute(sql, params)
  File "C:\Users\aky\AppData\Local\Programs\Python\Python38\courseu\lib\site-packages\django\db\utils.py", line 91, in __exit__
    raise dj_exc_value.with_traceback(traceback) from exc_value
  File "C:\Users\aky\AppData\Local\Programs\Python\Python38\courseu\lib\site-packages\django\db\backends\utils.py", line 89, in _execute
    return self.cursor.execute(sql, params)
  File "C:\Users\aky\AppData\Local\Programs\Python\Python38\courseu\lib\site-packages\django\db\backends\mysql\base.py", line 75, in execute
    return self.cursor.execute(query, args)
  File "C:\Users\aky\AppData\Local\Programs\Python\Python38\courseu\lib\site-packages\MySQLdb\cursors.py", line 179, in execute
    res = self._query(mogrified_query)
  File "C:\Users\aky\AppData\Local\Programs\Python\Python38\courseu\lib\site-packages\MySQLdb\cursors.py", line 330, in _query
    db.query(q)
  File "C:\Users\aky\AppData\Local\Programs\Python\Python38\courseu\lib\site-packages\MySQLdb\connections.py", line 255, in query
    _mysql.connection.query(self, query)
django.db.utils.ProgrammingError: (1146, "Table 'courseu_db.website_userprofile' doesn't exist")
ERROR 2023-11-29 18:43:52,899 django.server Thread-14 9868 basehttp basehttp.py 212 django.server log_message 4064 "GET /profile/ HTTP/1.1" 500 365149
WARNING 2023-11-29 18:43:53,871 django.request Thread-14 9868 log log.py 241 django.request log_response 4064 Not Found: /favicon.ico
WARNING 2023-11-29 18:43:53,872 django.server Thread-14 9868 basehttp basehttp.py 212 django.server log_message 4064 "GET /favicon.ico HTTP/1.1" 404 26332
WARNING 2023-11-29 18:43:53,979 django.request Thread-14 9868 log log.py 241 django.request log_response 4064 Not Found: /favicon.ico
WARNING 2023-11-29 18:43:53,981 django.server Thread-14 9868 basehttp basehttp.py 212 django.server log_message 4064 "GET /favicon.ico HTTP/1.1" 404 26332
WARNING 2023-11-29 18:43:54,834 django.server Thread-14 9868 basehttp basehttp.py 212 django.server log_message 4064 "GET /static/images/favicon.png HTTP/1.1" 404 1914
WARNING 2023-11-29 18:46:03,883 django.server Thread-17 10440 basehttp basehttp.py 212 django.server log_message 4064 "GET /static/images/favicon.png HTTP/1.1" 404 1914
WARNING 2023-11-29 18:46:51,488 django.server Thread-18 10768 basehttp basehttp.py 212 django.server log_message 4064 "GET /static/images/favicon.png HTTP/1.1" 404 1914
WARNING 2023-11-29 18:46:51,555 django.server Thread-19 9252 basehttp basehttp.py 212 django.server log_message 4064 "GET /static/images/favicon.png HTTP/1.1" 404 1914
WARNING 2023-11-29 18:47:11,622 django.server Thread-20 14148 basehttp basehttp.py 212 django.server log_message 4064 "GET /static/images/favicon.png HTTP/1.1" 404 1914
WARNING 2023-11-29 18:47:11,727 django.server Thread-21 6396 basehttp basehttp.py 212 django.server log_message 4064 "GET /static/images/favicon.png HTTP/1.1" 404 1914
WARNING 2023-11-29 18:47:40,610 django.server Thread-22 9108 basehttp basehttp.py 212 django.server log_message 4064 "GET /static/images/favicon.png HTTP/1.1" 404 1914
WARNING 2023-11-29 18:47:42,682 django.server Thread-23 13564 basehttp basehttp.py 212 django.server log_message 4064 "GET /static/images/favicon.png HTTP/1.1" 404 1914
WARNING 2023-11-29 18:47:42,766 django.server Thread-24 14268 basehttp basehttp.py 212 django.server log_message 4064 "GET /static/images/favicon.png HTTP/1.1" 404 1914
WARNING 2023-11-29 19:13:28,627 django.server Thread-25 10944 basehttp basehttp.py 212 django.server log_message 4064 "GET /static/images/favicon.png HTTP/1.1" 404 1914
WARNING 2023-11-29 19:13:28,723 django.server Thread-26 912 basehttp basehttp.py 212 django.server log_message 4064 "GET /static/images/favicon.png HTTP/1.1" 404 1914
WARNING 2023-12-13 11:18:40,019 django.request Thread-3 1188 log log.py 241 django.request log_response 2344 Not Found: /favicon.ico
WARNING 2023-12-13 11:18:40,022 django.server Thread-3 1188 basehttp basehttp.py 212 django.server log_message 2344 "GET /favicon.ico HTTP/1.1" 404 26333
WARNING 2023-12-13 11:18:50,382 django.server Thread-3 1188 basehttp basehttp.py 212 django.server log_message 2344 "GET /static/images/favicon.png HTTP/1.1" 404 1914
ERROR 2023-12-13 11:19:29,028 django.request Thread-6 9228 log log.py 241 django.request log_response 2344 Internal Server Error: /profile/
Traceback (most recent call last):
  File "C:\Users\aky\AppData\Local\Programs\Python\Python38\courseu\lib\site-packages\django\template\base.py", line 880, in _resolve_lookup
    current = current[bit]
  File "C:\Users\aky\AppData\Local\Programs\Python\Python38\courseu\lib\site-packages\django\utils\functional.py", line 268, in inner
    return func(_wrapped, *args)
TypeError: 'User' object is not subscriptable

During handling of the above exception, another exception occurred:

Traceback (most recent call last):
  File "C:\Users\aky\AppData\Local\Programs\Python\Python38\courseu\lib\site-packages\django\db\models\fields\related_descriptors.py", line 473, in __get__
    rel_obj = self.related.get_cached_value(instance)
  File "C:\Users\aky\AppData\Local\Programs\Python\Python38\courseu\lib\site-packages\django\db\models\fields\mixins.py", line 15, in get_cached_value
    return instance._state.fields_cache[cache_name]
KeyError: 'userprofile'

During handling of the above exception, another exception occurred:

Traceback (most recent call last):
  File "C:\Users\aky\AppData\Local\Programs\Python\Python38\courseu\lib\site-packages\django\db\backends\utils.py", line 89, in _execute
    return self.cursor.execute(sql, params)
  File "C:\Users\aky\AppData\Local\Programs\Python\Python38\courseu\lib\site-packages\django\db\backends\mysql\base.py", line 75, in execute
    return self.cursor.execute(query, args)
  File "C:\Users\aky\AppData\Local\Programs\Python\Python38\courseu\lib\site-packages\MySQLdb\cursors.py", line 179, in execute
    res = self._query(mogrified_query)
  File "C:\Users\aky\AppData\Local\Programs\Python\Python38\courseu\lib\site-packages\MySQLdb\cursors.py", line 330, in _query
    db.query(q)
  File "C:\Users\aky\AppData\Local\Programs\Python\Python38\courseu\lib\site-packages\MySQLdb\connections.py", line 255, in query
    _mysql.connection.query(self, query)
MySQLdb.ProgrammingError: (1146, "Table 'courseu_db.website_userprofile' doesn't exist")

The above exception was the direct cause of the following exception:

Traceback (most recent call last):
  File "C:\Users\aky\AppData\Local\Programs\Python\Python38\courseu\lib\site-packages\django\core\handlers\exception.py", line 55, in inner
    response = get_response(request)
  File "C:\Users\aky\AppData\Local\Programs\Python\Python38\courseu\lib\site-packages\django\core\handlers\base.py", line 197, in _get_response
    response = wrapped_callback(request, *callback_args, **callback_kwargs)
  File "C:\Users\aky\AppData\Local\Programs\Python\Python38\courseu\lib\site-packages\django\contrib\auth\decorators.py", line 23, in _wrapper_view
    return view_func(request, *args, **kwargs)
  File "C:\Users\aky\AppData\Local\Programs\Python\Python38\eng_ver\apps\website\views.py", line 257, in user_profile
    return render(request, 'user/user_profile.html', context)
  File "C:\Users\aky\AppData\Local\Programs\Python\Python38\courseu\lib\site-packages\django\shortcuts.py", line 24, in render
    content = loader.render_to_string(template_name, context, request, using=using)
  File "C:\Users\aky\AppData\Local\Programs\Python\Python38\courseu\lib\site-packages\django\template\loader.py", line 62, in render_to_string
    return template.render(context, request)
  File "C:\Users\aky\AppData\Local\Programs\Python\Python38\courseu\lib\site-packages\django\template\backends\django.py", line 61, in render
    return self.template.render(context)
  File "C:\Users\aky\AppData\Local\Programs\Python\Python38\courseu\lib\site-packages\django\template\base.py", line 175, in render
    return self._render(context)
  File "C:\Users\aky\AppData\Local\Programs\Python\Python38\courseu\lib\site-packages\django\test\utils.py", line 112, in instrumented_test_render
    return self.nodelist.render(context)
  File "C:\Users\aky\AppData\Local\Programs\Python\Python38\courseu\lib\site-packages\django\template\base.py", line 1005, in render
    return SafeString("".join([node.render_annotated(context) for node in self]))
  File "C:\Users\aky\AppData\Local\Programs\Python\Python38\courseu\lib\site-packages\django\template\base.py", line 1005, in <listcomp>
    return SafeString("".join([node.render_annotated(context) for node in self]))
  File "C:\Users\aky\AppData\Local\Programs\Python\Python38\courseu\lib\site-packages\django\template\base.py", line 966, in render_annotated
    return self.render(context)
  File "C:\Users\aky\AppData\Local\Programs\Python\Python38\courseu\lib\site-packages\django\template\loader_tags.py", line 157, in render
    return compiled_parent._render(context)
  File "C:\Users\aky\AppData\Local\Programs\Python\Python38\courseu\lib\site-packages\django\test\utils.py", line 112, in instrumented_test_render
    return self.nodelist.render(context)
  File "C:\Users\aky\AppData\Local\Programs\Python\Python38\courseu\lib\site-packages\django\template\base.py", line 1005, in render
    return SafeString("".join([node.render_annotated(context) for node in self]))
  File "C:\Users\aky\AppData\Local\Programs\Python\Python38\courseu\lib\site-packages\django\template\base.py", line 1005, in <listcomp>
    return SafeString("".join([node.render_annotated(context) for node in self]))
  File "C:\Users\aky\AppData\Local\Programs\Python\Python38\courseu\lib\site-packages\django\template\base.py", line 966, in render_annotated
    return self.render(context)
  File "C:\Users\aky\AppData\Local\Programs\Python\Python38\courseu\lib\site-packages\django\template\defaulttags.py", line 321, in render
    return nodelist.render(context)
  File "C:\Users\aky\AppData\Local\Programs\Python\Python38\courseu\lib\site-packages\django\template\base.py", line 1005, in render
    return SafeString("".join([node.render_annotated(context) for node in self]))
  File "C:\Users\aky\AppData\Local\Programs\Python\Python38\courseu\lib\site-packages\django\template\base.py", line 1005, in <listcomp>
    return SafeString("".join([node.render_annotated(context) for node in self]))
  File "C:\Users\aky\AppData\Local\Programs\Python\Python38\courseu\lib\site-packages\django\template\base.py", line 966, in render_annotated
    return self.render(context)
  File "C:\Users\aky\AppData\Local\Programs\Python\Python38\courseu\lib\site-packages\django\template\loader_tags.py", line 63, in render
    result = block.nodelist.render(context)
  File "C:\Users\aky\AppData\Local\Programs\Python\Python38\courseu\lib\site-packages\django\template\base.py", line 1005, in render
    return SafeString("".join([node.render_annotated(context) for node in self]))
  File "C:\Users\aky\AppData\Local\Programs\Python\Python38\courseu\lib\site-packages\django\template\base.py", line 1005, in <listcomp>
    return SafeString("".join([node.render_annotated(context) for node in self]))
  File "C:\Users\aky\AppData\Local\Programs\Python\Python38\courseu\lib\site-packages\django\template\base.py", line 966, in render_annotated
    return self.render(context)
  File "C:\Users\aky\AppData\Local\Programs\Python\Python38\courseu\lib\site-packages\django\template\defaulttags.py", line 321, in render
    return nodelist.render(context)
  File "C:\Users\aky\AppData\Local\Programs\Python\Python38\courseu\lib\site-packages\django\template\base.py", line 1005, in render
    return SafeString("".join([node.render_annotated(context) for node in self]))
  File "C:\Users\aky\AppData\Local\Programs\Python\Python38\courseu\lib\site-packages\django\template\base.py", line 1005, in <listcomp>
    return SafeString("".join([node.render_annotated(context) for node in self]))
  File "C:\Users\aky\AppData\Local\Programs\Python\Python38\courseu\lib\site-packages\django\template\base.py", line 966, in render_annotated
    return self.render(context)
  File "C:\Users\aky\AppData\Local\Programs\Python\Python38\courseu\lib\site-packages\django\template\defaulttags.py", line 314, in render
    match = condition.eval(context)
  File "C:\Users\aky\AppData\Local\Programs\Python\Python38\courseu\lib\site-packages\django\template\defaulttags.py", line 877, in eval
    return self.value.resolve(context, ignore_failures=True)
  File "C:\Users\aky\AppData\Local\Programs\Python\Python38\courseu\lib\site-packages\django\template\base.py", line 715, in resolve
    obj = self.var.resolve(context)
  File "C:\Users\aky\AppData\Local\Programs\Python\Python38\courseu\lib\site-packages\django\template\base.py", line 847, in resolve
    value = self._resolve_lookup(context)
  File "C:\Users\aky\AppData\Local\Programs\Python\Python38\courseu\lib\site-packages\django\template\base.py", line 890, in _resolve_lookup
    current = getattr(current, bit)
  File "C:\Users\aky\AppData\Local\Programs\Python\Python38\courseu\lib\site-packages\django\utils\functional.py", line 268, in inner
    return func(_wrapped, *args)
  File "C:\Users\aky\AppData\Local\Programs\Python\Python38\courseu\lib\site-packages\django\db\models\fields\related_descriptors.py", line 481, in __get__
    rel_obj = self.get_queryset(instance=instance).get(**filter_args)
  File "C:\Users\aky\AppData\Local\Programs\Python\Python38\courseu\lib\site-packages\django\db\models\query.py", line 633, in get
    num = len(clone)
  File "C:\Users\aky\AppData\Local\Programs\Python\Python38\courseu\lib\site-packages\django\db\models\query.py", line 380, in __len__
    self._fetch_all()
  File "C:\Users\aky\AppData\Local\Programs\Python\Python38\courseu\lib\site-packages\django\db\models\query.py", line 1881, in _fetch_all
    self._result_cache = list(self._iterable_class(self))
  File "C:\Users\aky\AppData\Local\Programs\Python\Python38\courseu\lib\site-packages\django\db\models\query.py", line 91, in __iter__
    results = compiler.execute_sql(
  File "C:\Users\aky\AppData\Local\Programs\Python\Python38\courseu\lib\site-packages\django\db\models\sql\compiler.py", line 1562, in execute_sql
    cursor.execute(sql, params)
  File "C:\Users\aky\AppData\Local\Programs\Python\Python38\courseu\lib\site-packages\debug_toolbar\panels\sql\tracking.py", line 252, in execute
    return self._record(super().execute, sql, params)
  File "C:\Users\aky\AppData\Local\Programs\Python\Python38\courseu\lib\site-packages\debug_toolbar\panels\sql\tracking.py", line 177, in _record
    return method(sql, params)
  File "C:\Users\aky\AppData\Local\Programs\Python\Python38\courseu\lib\site-packages\django\db\backends\utils.py", line 102, in execute
    return super().execute(sql, params)
  File "C:\Users\aky\AppData\Local\Programs\Python\Python38\courseu\lib\site-packages\django\db\backends\utils.py", line 67, in execute
    return self._execute_with_wrappers(
  File "C:\Users\aky\AppData\Local\Programs\Python\Python38\courseu\lib\site-packages\django\db\backends\utils.py", line 80, in _execute_with_wrappers
    return executor(sql, params, many, context)
  File "C:\Users\aky\AppData\Local\Programs\Python\Python38\courseu\lib\site-packages\django\db\backends\utils.py", line 89, in _execute
    return self.cursor.execute(sql, params)
  File "C:\Users\aky\AppData\Local\Programs\Python\Python38\courseu\lib\site-packages\django\db\utils.py", line 91, in __exit__
    raise dj_exc_value.with_traceback(traceback) from exc_value
  File "C:\Users\aky\AppData\Local\Programs\Python\Python38\courseu\lib\site-packages\django\db\backends\utils.py", line 89, in _execute
    return self.cursor.execute(sql, params)
  File "C:\Users\aky\AppData\Local\Programs\Python\Python38\courseu\lib\site-packages\django\db\backends\mysql\base.py", line 75, in execute
    return self.cursor.execute(query, args)
  File "C:\Users\aky\AppData\Local\Programs\Python\Python38\courseu\lib\site-packages\MySQLdb\cursors.py", line 179, in execute
    res = self._query(mogrified_query)
  File "C:\Users\aky\AppData\Local\Programs\Python\Python38\courseu\lib\site-packages\MySQLdb\cursors.py", line 330, in _query
    db.query(q)
  File "C:\Users\aky\AppData\Local\Programs\Python\Python38\courseu\lib\site-packages\MySQLdb\connections.py", line 255, in query
    _mysql.connection.query(self, query)
django.db.utils.ProgrammingError: (1146, "Table 'courseu_db.website_userprofile' doesn't exist")
ERROR 2023-12-13 11:24:34,147 django.request Thread-4 4720 log log.py 241 django.request log_response 10632 Internal Server Error: /admin/survey/survey/
Traceback (most recent call last):
  File "C:\Users\aky\AppData\Local\Programs\Python\Python38\courseu\lib\site-packages\django\db\backends\utils.py", line 89, in _execute
    return self.cursor.execute(sql, params)
  File "C:\Users\aky\AppData\Local\Programs\Python\Python38\courseu\lib\site-packages\django\db\backends\mysql\base.py", line 75, in execute
    return self.cursor.execute(query, args)
  File "C:\Users\aky\AppData\Local\Programs\Python\Python38\courseu\lib\site-packages\MySQLdb\cursors.py", line 179, in execute
    res = self._query(mogrified_query)
  File "C:\Users\aky\AppData\Local\Programs\Python\Python38\courseu\lib\site-packages\MySQLdb\cursors.py", line 330, in _query
    db.query(q)
  File "C:\Users\aky\AppData\Local\Programs\Python\Python38\courseu\lib\site-packages\MySQLdb\connections.py", line 255, in query
    _mysql.connection.query(self, query)
MySQLdb.OperationalError: (1054, "Unknown column 'survey_survey.user_id' in 'field list'")

The above exception was the direct cause of the following exception:

Traceback (most recent call last):
  File "C:\Users\aky\AppData\Local\Programs\Python\Python38\courseu\lib\site-packages\django\core\handlers\exception.py", line 55, in inner
    response = get_response(request)
  File "C:\Users\aky\AppData\Local\Programs\Python\Python38\courseu\lib\site-packages\django\core\handlers\base.py", line 197, in _get_response
    response = wrapped_callback(request, *callback_args, **callback_kwargs)
  File "C:\Users\aky\AppData\Local\Programs\Python\Python38\courseu\lib\site-packages\django\contrib\admin\options.py", line 688, in wrapper
    return self.admin_site.admin_view(view)(*args, **kwargs)
  File "C:\Users\aky\AppData\Local\Programs\Python\Python38\courseu\lib\site-packages\django\utils\decorators.py", line 134, in _wrapper_view
    response = view_func(request, *args, **kwargs)
  File "C:\Users\aky\AppData\Local\Programs\Python\Python38\courseu\lib\site-packages\django\views\decorators\cache.py", line 62, in _wrapper_view_func
    response = view_func(request, *args, **kwargs)
  File "C:\Users\aky\AppData\Local\Programs\Python\Python38\courseu\lib\site-packages\django\contrib\admin\sites.py", line 242, in inner
    return view(request, *args, **kwargs)
  File "C:\Users\aky\AppData\Local\Programs\Python\Python38\courseu\lib\site-packages\django\utils\decorators.py", line 46, in _wrapper
    return bound_method(*args, **kwargs)
  File "C:\Users\aky\AppData\Local\Programs\Python\Python38\courseu\lib\site-packages\django\utils\decorators.py", line 134, in _wrapper_view
    response = view_func(request, *args, **kwargs)
  File "C:\Users\aky\AppData\Local\Programs\Python\Python38\courseu\lib\site-packages\django\contrib\admin\options.py", line 2065, in changelist_view
    "selection_note": _("0 of %(cnt)s selected") % {"cnt": len(cl.result_list)},
  File "C:\Users\aky\AppData\Local\Programs\Python\Python38\courseu\lib\site-packages\django\db\models\query.py", line 380, in __len__
    self._fetch_all()
  File "C:\Users\aky\AppData\Local\Programs\Python\Python38\courseu\lib\site-packages\django\db\models\query.py", line 1881, in _fetch_all
    self._result_cache = list(self._iterable_class(self))
  File "C:\Users\aky\AppData\Local\Programs\Python\Python38\courseu\lib\site-packages\django\db\models\query.py", line 91, in __iter__
    results = compiler.execute_sql(
  File "C:\Users\aky\AppData\Local\Programs\Python\Python38\courseu\lib\site-packages\django\db\models\sql\compiler.py", line 1562, in execute_sql
    cursor.execute(sql, params)
  File "C:\Users\aky\AppData\Local\Programs\Python\Python38\courseu\lib\site-packages\debug_toolbar\panels\sql\tracking.py", line 252, in execute
    return self._record(super().execute, sql, params)
  File "C:\Users\aky\AppData\Local\Programs\Python\Python38\courseu\lib\site-packages\debug_toolbar\panels\sql\tracking.py", line 177, in _record
    return method(sql, params)
  File "C:\Users\aky\AppData\Local\Programs\Python\Python38\courseu\lib\site-packages\django\db\backends\utils.py", line 102, in execute
    return super().execute(sql, params)
  File "C:\Users\aky\AppData\Local\Programs\Python\Python38\courseu\lib\site-packages\django\db\backends\utils.py", line 67, in execute
    return self._execute_with_wrappers(
  File "C:\Users\aky\AppData\Local\Programs\Python\Python38\courseu\lib\site-packages\django\db\backends\utils.py", line 80, in _execute_with_wrappers
    return executor(sql, params, many, context)
  File "C:\Users\aky\AppData\Local\Programs\Python\Python38\courseu\lib\site-packages\django\db\backends\utils.py", line 89, in _execute
    return self.cursor.execute(sql, params)
  File "C:\Users\aky\AppData\Local\Programs\Python\Python38\courseu\lib\site-packages\django\db\utils.py", line 91, in __exit__
    raise dj_exc_value.with_traceback(traceback) from exc_value
  File "C:\Users\aky\AppData\Local\Programs\Python\Python38\courseu\lib\site-packages\django\db\backends\utils.py", line 89, in _execute
    return self.cursor.execute(sql, params)
  File "C:\Users\aky\AppData\Local\Programs\Python\Python38\courseu\lib\site-packages\django\db\backends\mysql\base.py", line 75, in execute
    return self.cursor.execute(query, args)
  File "C:\Users\aky\AppData\Local\Programs\Python\Python38\courseu\lib\site-packages\MySQLdb\cursors.py", line 179, in execute
    res = self._query(mogrified_query)
  File "C:\Users\aky\AppData\Local\Programs\Python\Python38\courseu\lib\site-packages\MySQLdb\cursors.py", line 330, in _query
    db.query(q)
  File "C:\Users\aky\AppData\Local\Programs\Python\Python38\courseu\lib\site-packages\MySQLdb\connections.py", line 255, in query
    _mysql.connection.query(self, query)
django.db.utils.OperationalError: (1054, "Unknown column 'survey_survey.user_id' in 'field list'")
ERROR 2023-12-13 11:24:34,249 django.server Thread-4 4720 basehttp basehttp.py 212 django.server log_message 10632 "GET /admin/survey/survey/ HTTP/1.1" 500 232660
ERROR 2023-12-13 11:24:38,553 django.request Thread-4 4720 log log.py 241 django.request log_response 10632 Internal Server Error: /admin/survey/survey/
Traceback (most recent call last):
  File "C:\Users\aky\AppData\Local\Programs\Python\Python38\courseu\lib\site-packages\django\db\backends\utils.py", line 89, in _execute
    return self.cursor.execute(sql, params)
  File "C:\Users\aky\AppData\Local\Programs\Python\Python38\courseu\lib\site-packages\django\db\backends\mysql\base.py", line 75, in execute
    return self.cursor.execute(query, args)
  File "C:\Users\aky\AppData\Local\Programs\Python\Python38\courseu\lib\site-packages\MySQLdb\cursors.py", line 179, in execute
    res = self._query(mogrified_query)
  File "C:\Users\aky\AppData\Local\Programs\Python\Python38\courseu\lib\site-packages\MySQLdb\cursors.py", line 330, in _query
    db.query(q)
  File "C:\Users\aky\AppData\Local\Programs\Python\Python38\courseu\lib\site-packages\MySQLdb\connections.py", line 255, in query
    _mysql.connection.query(self, query)
MySQLdb.OperationalError: (1054, "Unknown column 'survey_survey.user_id' in 'field list'")

The above exception was the direct cause of the following exception:

Traceback (most recent call last):
  File "C:\Users\aky\AppData\Local\Programs\Python\Python38\courseu\lib\site-packages\django\core\handlers\exception.py", line 55, in inner
    response = get_response(request)
  File "C:\Users\aky\AppData\Local\Programs\Python\Python38\courseu\lib\site-packages\django\core\handlers\base.py", line 197, in _get_response
    response = wrapped_callback(request, *callback_args, **callback_kwargs)
  File "C:\Users\aky\AppData\Local\Programs\Python\Python38\courseu\lib\site-packages\django\contrib\admin\options.py", line 688, in wrapper
    return self.admin_site.admin_view(view)(*args, **kwargs)
  File "C:\Users\aky\AppData\Local\Programs\Python\Python38\courseu\lib\site-packages\django\utils\decorators.py", line 134, in _wrapper_view
    response = view_func(request, *args, **kwargs)
  File "C:\Users\aky\AppData\Local\Programs\Python\Python38\courseu\lib\site-packages\django\views\decorators\cache.py", line 62, in _wrapper_view_func
    response = view_func(request, *args, **kwargs)
  File "C:\Users\aky\AppData\Local\Programs\Python\Python38\courseu\lib\site-packages\django\contrib\admin\sites.py", line 242, in inner
    return view(request, *args, **kwargs)
  File "C:\Users\aky\AppData\Local\Programs\Python\Python38\courseu\lib\site-packages\django\utils\decorators.py", line 46, in _wrapper
    return bound_method(*args, **kwargs)
  File "C:\Users\aky\AppData\Local\Programs\Python\Python38\courseu\lib\site-packages\django\utils\decorators.py", line 134, in _wrapper_view
    response = view_func(request, *args, **kwargs)
  File "C:\Users\aky\AppData\Local\Programs\Python\Python38\courseu\lib\site-packages\django\contrib\admin\options.py", line 2065, in changelist_view
    "selection_note": _("0 of %(cnt)s selected") % {"cnt": len(cl.result_list)},
  File "C:\Users\aky\AppData\Local\Programs\Python\Python38\courseu\lib\site-packages\django\db\models\query.py", line 380, in __len__
    self._fetch_all()
  File "C:\Users\aky\AppData\Local\Programs\Python\Python38\courseu\lib\site-packages\django\db\models\query.py", line 1881, in _fetch_all
    self._result_cache = list(self._iterable_class(self))
  File "C:\Users\aky\AppData\Local\Programs\Python\Python38\courseu\lib\site-packages\django\db\models\query.py", line 91, in __iter__
    results = compiler.execute_sql(
  File "C:\Users\aky\AppData\Local\Programs\Python\Python38\courseu\lib\site-packages\django\db\models\sql\compiler.py", line 1562, in execute_sql
    cursor.execute(sql, params)
  File "C:\Users\aky\AppData\Local\Programs\Python\Python38\courseu\lib\site-packages\debug_toolbar\panels\sql\tracking.py", line 252, in execute
    return self._record(super().execute, sql, params)
  File "C:\Users\aky\AppData\Local\Programs\Python\Python38\courseu\lib\site-packages\debug_toolbar\panels\sql\tracking.py", line 177, in _record
    return method(sql, params)
  File "C:\Users\aky\AppData\Local\Programs\Python\Python38\courseu\lib\site-packages\django\db\backends\utils.py", line 102, in execute
    return super().execute(sql, params)
  File "C:\Users\aky\AppData\Local\Programs\Python\Python38\courseu\lib\site-packages\django\db\backends\utils.py", line 67, in execute
    return self._execute_with_wrappers(
  File "C:\Users\aky\AppData\Local\Programs\Python\Python38\courseu\lib\site-packages\django\db\backends\utils.py", line 80, in _execute_with_wrappers
    return executor(sql, params, many, context)
  File "C:\Users\aky\AppData\Local\Programs\Python\Python38\courseu\lib\site-packages\django\db\backends\utils.py", line 89, in _execute
    return self.cursor.execute(sql, params)
  File "C:\Users\aky\AppData\Local\Programs\Python\Python38\courseu\lib\site-packages\django\db\utils.py", line 91, in __exit__
    raise dj_exc_value.with_traceback(traceback) from exc_value
  File "C:\Users\aky\AppData\Local\Programs\Python\Python38\courseu\lib\site-packages\django\db\backends\utils.py", line 89, in _execute
    return self.cursor.execute(sql, params)
  File "C:\Users\aky\AppData\Local\Programs\Python\Python38\courseu\lib\site-packages\django\db\backends\mysql\base.py", line 75, in execute
    return self.cursor.execute(query, args)
  File "C:\Users\aky\AppData\Local\Programs\Python\Python38\courseu\lib\site-packages\MySQLdb\cursors.py", line 179, in execute
    res = self._query(mogrified_query)
  File "C:\Users\aky\AppData\Local\Programs\Python\Python38\courseu\lib\site-packages\MySQLdb\cursors.py", line 330, in _query
    db.query(q)
  File "C:\Users\aky\AppData\Local\Programs\Python\Python38\courseu\lib\site-packages\MySQLdb\connections.py", line 255, in query
    _mysql.connection.query(self, query)
django.db.utils.OperationalError: (1054, "Unknown column 'survey_survey.user_id' in 'field list'")
ERROR 2023-12-13 11:24:38,658 django.server Thread-4 4720 basehttp basehttp.py 212 django.server log_message 10632 "GET /admin/survey/survey/ HTTP/1.1" 500 232659
WARNING 2023-12-14 19:17:03,747 django.request Thread-4 9020 log log.py 241 django.request log_response 5944 Not Found: /favicon.ico
WARNING 2023-12-14 19:17:03,749 django.server Thread-4 9020 basehttp basehttp.py 212 django.server log_message 5944 "GET /favicon.ico HTTP/1.1" 404 26154
WARNING 2023-12-14 19:17:09,578 django.server Thread-4 9020 basehttp basehttp.py 212 django.server log_message 5944 "GET /static/images/favicon.png HTTP/1.1" 404 1914
WARNING 2023-12-14 19:17:31,983 django.server Thread-5 16980 basehttp basehttp.py 212 django.server log_message 5944 "GET /static/css/survey.css HTTP/1.1" 404 1902
WARNING 2023-12-14 19:20:02,423 django.server Thread-2 9296 basehttp basehttp.py 212 django.server log_message 5944 "GET /static/css/survey.css HTTP/1.1" 404 1902
WARNING 2023-12-14 19:36:47,200 django.server Thread-8 15248 basehttp basehttp.py 212 django.server log_message 5956 "GET /static/css/survey.css HTTP/1.1" 404 1902
WARNING 2023-12-14 19:39:00,754 django.server Thread-12 16840 basehttp basehttp.py 212 django.server log_message 5956 "GET /static/css/survey.css HTTP/1.1" 404 1902
WARNING 2023-12-14 19:41:36,122 django.server Thread-5 4880 basehttp basehttp.py 212 django.server log_message 2520 "GET /static/css/survey.css HTTP/1.1" 404 1902
WARNING 2023-12-14 19:43:27,793 django.server Thread-2 3276 basehttp basehttp.py 212 django.server log_message 12944 "GET /static/css/survey.css HTTP/1.1" 404 1902
WARNING 2023-12-14 19:44:06,662 django.server Thread-2 3164 basehttp basehttp.py 212 django.server log_message 812 "GET /static/css/survey.css HTTP/1.1" 404 1902
WARNING 2023-12-14 19:44:10,435 django.server Thread-4 11076 basehttp basehttp.py 212 django.server log_message 812 "GET /static/css/survey.css HTTP/1.1" 404 1902
WARNING 2023-12-14 19:44:41,222 django.server Thread-6 14372 basehttp basehttp.py 212 django.server log_message 812 "GET /static/css/survey.css HTTP/1.1" 404 1902
WARNING 2023-12-14 20:00:03,811 django.server Thread-2 16420 basehttp basehttp.py 212 django.server log_message 2928 "GET /static/css/survey.css HTTP/1.1" 404 1902
WARNING 2023-12-14 20:02:19,621 django.server Thread-2 3492 basehttp basehttp.py 212 django.server log_message 4048 "GET /static/css/survey.css HTTP/1.1" 404 1902
WARNING 2023-12-14 20:02:25,716 django.server Thread-3 2564 basehttp basehttp.py 212 django.server log_message 4048 "GET /static/css/survey.css HTTP/1.1" 404 1902
WARNING 2023-12-14 20:03:56,954 django.server Thread-3 14644 basehttp basehttp.py 212 django.server log_message 14620 "GET /static/css/survey.css HTTP/1.1" 404 1902
WARNING 2023-12-14 20:04:00,646 django.server Thread-2 11624 basehttp basehttp.py 212 django.server log_message 14620 "GET /static/css/survey.css HTTP/1.1" 404 1902
WARNING 2023-12-14 20:04:03,693 django.server Thread-4 4556 basehttp basehttp.py 212 django.server log_message 14620 "GET /static/css/survey.css HTTP/1.1" 404 1902
WARNING 2023-12-14 20:06:11,941 django.server Thread-3 4576 basehttp basehttp.py 212 django.server log_message 14300 "GET /static/css/survey.css HTTP/1.1" 404 1902
WARNING 2023-12-14 20:17:12,142 django.server Thread-4 15216 basehttp basehttp.py 212 django.server log_message 14828 "GET /static/css/survey.css HTTP/1.1" 404 1902
WARNING 2023-12-14 20:22:32,461 django.server Thread-1 3740 basehttp basehttp.py 212 django.server log_message 3748 "GET /static/css/survey.css HTTP/1.1" 404 1902
WARNING 2023-12-14 20:23:36,653 django.server Thread-5 17220 basehttp basehttp.py 212 django.server log_message 3748 "GET /static/css/survey.css HTTP/1.1" 404 1902
WARNING 2023-12-14 20:23:39,136 django.server Thread-6 11624 basehttp basehttp.py 212 django.server log_message 3748 "GET /static/css/survey.css HTTP/1.1" 404 1902
ERROR 2023-12-14 20:27:49,300 django.request Thread-1 12716 log log.py 241 django.request log_response 14136 Internal Server Error: /survey/
Traceback (most recent call last):
  File "C:\Users\aky\AppData\Local\Programs\Python\Python38\courseu\lib\site-packages\django\core\handlers\exception.py", line 55, in inner
    response = get_response(request)
  File "C:\Users\aky\AppData\Local\Programs\Python\Python38\courseu\lib\site-packages\django\core\handlers\base.py", line 197, in _get_response
    response = wrapped_callback(request, *callback_args, **callback_kwargs)
  File "C:\Users\aky\AppData\Local\Programs\Python\Python38\eng_ver\apps\survey\views.py", line 11, in survey
    form = SurveyForm()
  File "C:\Users\aky\AppData\Local\Programs\Python\Python38\eng_ver\apps\survey\forms.py", line 68, in __init__
    field_choices = self.fields['specialization'].choices
AttributeError: 'CharField' object has no attribute 'choices'
ERROR 2023-12-14 20:27:49,418 django.server Thread-1 12716 basehttp basehttp.py 212 django.server log_message 14136 "GET /survey/ HTTP/1.1" 500 97285
ERROR 2023-12-14 20:30:33,767 django.request Thread-1 7952 log log.py 241 django.request log_response 11748 Internal Server Error: /survey/
Traceback (most recent call last):
  File "C:\Users\aky\AppData\Local\Programs\Python\Python38\courseu\lib\site-packages\django\core\handlers\exception.py", line 55, in inner
    response = get_response(request)
  File "C:\Users\aky\AppData\Local\Programs\Python\Python38\courseu\lib\site-packages\django\core\handlers\base.py", line 197, in _get_response
    response = wrapped_callback(request, *callback_args, **callback_kwargs)
  File "C:\Users\aky\AppData\Local\Programs\Python\Python38\eng_ver\apps\survey\views.py", line 11, in survey
    form = SurveyForm()
  File "C:\Users\aky\AppData\Local\Programs\Python\Python38\eng_ver\apps\survey\forms.py", line 68, in __init__
    field_choices = [(field.id, field.field_name) for field in Field.objects.all()]
  File "C:\Users\aky\AppData\Local\Programs\Python\Python38\eng_ver\apps\survey\forms.py", line 68, in <listcomp>
    field_choices = [(field.id, field.field_name) for field in Field.objects.all()]
AttributeError: 'Field' object has no attribute 'id'
ERROR 2023-12-14 20:30:33,877 django.server Thread-1 7952 basehttp basehttp.py 212 django.server log_message 11748 "GET /survey/ HTTP/1.1" 500 101484
ERROR 2023-12-14 20:30:37,881 django.request Thread-2 7404 log log.py 241 django.request log_response 11748 Internal Server Error: /survey/
Traceback (most recent call last):
  File "C:\Users\aky\AppData\Local\Programs\Python\Python38\courseu\lib\site-packages\django\core\handlers\exception.py", line 55, in inner
    response = get_response(request)
  File "C:\Users\aky\AppData\Local\Programs\Python\Python38\courseu\lib\site-packages\django\core\handlers\base.py", line 197, in _get_response
    response = wrapped_callback(request, *callback_args, **callback_kwargs)
  File "C:\Users\aky\AppData\Local\Programs\Python\Python38\eng_ver\apps\survey\views.py", line 11, in survey
    form = SurveyForm()
  File "C:\Users\aky\AppData\Local\Programs\Python\Python38\eng_ver\apps\survey\forms.py", line 68, in __init__
    field_choices = [(field.id, field.field_name) for field in Field.objects.all()]
  File "C:\Users\aky\AppData\Local\Programs\Python\Python38\eng_ver\apps\survey\forms.py", line 68, in <listcomp>
    field_choices = [(field.id, field.field_name) for field in Field.objects.all()]
AttributeError: 'Field' object has no attribute 'id'
ERROR 2023-12-14 20:30:37,998 django.server Thread-2 7404 basehttp basehttp.py 212 django.server log_message 11748 "GET /survey/ HTTP/1.1" 500 101484
WARNING 2023-12-14 20:31:13,299 django.server Thread-5 16208 basehttp basehttp.py 212 django.server log_message 13688 "GET /static/css/survey.css HTTP/1.1" 404 1902
WARNING 2023-12-14 20:31:15,170 django.server Thread-3 9972 basehttp basehttp.py 212 django.server log_message 13688 "GET /static/css/survey.css HTTP/1.1" 404 1902
WARNING 2023-12-14 20:32:02,666 django.server Thread-1 14600 basehttp basehttp.py 212 django.server log_message 7064 "GET /static/css/survey.css HTTP/1.1" 404 1902
WARNING 2023-12-14 20:41:40,253 django.server Thread-5 8240 basehttp basehttp.py 212 django.server log_message 9256 "GET /static/css/survey.css HTTP/1.1" 404 1902
WARNING 2023-12-14 20:41:43,485 django.server Thread-3 2308 basehttp basehttp.py 212 django.server log_message 9256 "GET /static/css/survey.css HTTP/1.1" 404 1902
WARNING 2023-12-14 20:41:44,733 django.server Thread-2 9596 basehttp basehttp.py 212 django.server log_message 9256 "GET /static/css/survey.css HTTP/1.1" 404 1902
WARNING 2023-12-14 20:41:45,664 django.server Thread-1 14792 basehttp basehttp.py 212 django.server log_message 9256 "GET /static/css/survey.css HTTP/1.1" 404 1902
WARNING 2023-12-14 20:42:39,327 django.server Thread-4 10196 basehttp basehttp.py 212 django.server log_message 2016 "GET /static/css/survey.css HTTP/1.1" 404 1902
ERROR 2023-12-15 00:44:23,820 django.request Thread-1 4668 log log.py 241 django.request log_response 17056 Internal Server Error: /survey/
Traceback (most recent call last):
  File "C:\Users\aky\AppData\Local\Programs\Python\Python38\courseu\lib\site-packages\django\core\handlers\exception.py", line 55, in inner
    response = get_response(request)
  File "C:\Users\aky\AppData\Local\Programs\Python\Python38\courseu\lib\site-packages\django\core\handlers\base.py", line 197, in _get_response
    response = wrapped_callback(request, *callback_args, **callback_kwargs)
  File "C:\Users\aky\AppData\Local\Programs\Python\Python38\eng_ver\apps\survey\views.py", line 11, in survey
    form = SurveyForm()
  File "C:\Users\aky\AppData\Local\Programs\Python\Python38\eng_ver\apps\survey\forms.py", line 80, in __init__
    self.fields['additional_feedback'].required = False
KeyError: 'additional_feedback'
ERROR 2023-12-15 00:44:24,339 django.server Thread-1 4668 basehttp basehttp.py 212 django.server log_message 17056 "GET /survey/ HTTP/1.1" 500 97068
ERROR 2023-12-15 00:46:20,926 django.request Thread-2 2068 log log.py 241 django.request log_response 8600 Internal Server Error: /survey/
Traceback (most recent call last):
  File "C:\Users\aky\AppData\Local\Programs\Python\Python38\courseu\lib\site-packages\django\core\handlers\exception.py", line 55, in inner
    response = get_response(request)
  File "C:\Users\aky\AppData\Local\Programs\Python\Python38\courseu\lib\site-packages\django\core\handlers\base.py", line 197, in _get_response
    response = wrapped_callback(request, *callback_args, **callback_kwargs)
  File "C:\Users\aky\AppData\Local\Programs\Python\Python38\eng_ver\apps\survey\views.py", line 11, in survey
    form = SurveyForm()
  File "C:\Users\aky\AppData\Local\Programs\Python\Python38\eng_ver\apps\survey\forms.py", line 80, in __init__
    self.fields['additional_feedback'].required = False
KeyError: 'additional_feedback'
ERROR 2023-12-15 00:46:21,095 django.server Thread-2 2068 basehttp basehttp.py 212 django.server log_message 8600 "GET /survey/ HTTP/1.1" 500 97068
WARNING 2023-12-15 15:54:32,740 django.request Thread-3 8868 log log.py 241 django.request log_response 7096 Not Found: /favicon.ico
WARNING 2023-12-15 15:54:32,743 django.server Thread-3 8868 basehttp basehttp.py 212 django.server log_message 7096 "GET /favicon.ico HTTP/1.1" 404 26154
WARNING 2023-12-15 15:54:34,247 django.server Thread-3 8868 basehttp basehttp.py 212 django.server log_message 7096 "GET /static/images/favicon.png HTTP/1.1" 404 1914
ERROR 2023-12-15 18:05:49,064 django.request Thread-16 14896 log log.py 241 django.request log_response 15472 Internal Server Error: /create_test/
Traceback (most recent call last):
  File "C:\Users\aky\AppData\Local\Programs\Python\Python38\courseu\lib\site-packages\django\template\base.py", line 505, in parse
    compile_func = self.tags[command]
KeyError: 'static'

During handling of the above exception, another exception occurred:

Traceback (most recent call last):
  File "C:\Users\aky\AppData\Local\Programs\Python\Python38\courseu\lib\site-packages\django\core\handlers\exception.py", line 55, in inner
    response = get_response(request)
  File "C:\Users\aky\AppData\Local\Programs\Python\Python38\courseu\lib\site-packages\django\core\handlers\base.py", line 197, in _get_response
    response = wrapped_callback(request, *callback_args, **callback_kwargs)
  File "C:\Users\aky\AppData\Local\Programs\Python\Python38\eng_ver\apps\assessment\views.py", line 852, in create_test
    return render(request, 'test/create_test.html', context)
  File "C:\Users\aky\AppData\Local\Programs\Python\Python38\courseu\lib\site-packages\django\shortcuts.py", line 24, in render
    content = loader.render_to_string(template_name, context, request, using=using)
  File "C:\Users\aky\AppData\Local\Programs\Python\Python38\courseu\lib\site-packages\django\template\loader.py", line 61, in render_to_string
    template = get_template(template_name, using=using)
  File "C:\Users\aky\AppData\Local\Programs\Python\Python38\courseu\lib\site-packages\django\template\loader.py", line 15, in get_template
    return engine.get_template(template_name)
  File "C:\Users\aky\AppData\Local\Programs\Python\Python38\courseu\lib\site-packages\django\template\backends\django.py", line 33, in get_template
    return Template(self.engine.get_template(template_name), self)
  File "C:\Users\aky\AppData\Local\Programs\Python\Python38\courseu\lib\site-packages\django\template\engine.py", line 175, in get_template
    template, origin = self.find_template(template_name)
  File "C:\Users\aky\AppData\Local\Programs\Python\Python38\courseu\lib\site-packages\django\template\engine.py", line 157, in find_template
    template = loader.get_template(name, skip=skip)
  File "C:\Users\aky\AppData\Local\Programs\Python\Python38\courseu\lib\site-packages\django\template\loaders\cached.py", line 57, in get_template
    template = super().get_template(template_name, skip)
  File "C:\Users\aky\AppData\Local\Programs\Python\Python38\courseu\lib\site-packages\django\template\loaders\base.py", line 28, in get_template
    return Template(
  File "C:\Users\aky\AppData\Local\Programs\Python\Python38\courseu\lib\site-packages\django\template\base.py", line 154, in __init__
    self.nodelist = self.compile_nodelist()
  File "C:\Users\aky\AppData\Local\Programs\Python\Python38\courseu\lib\site-packages\django\template\base.py", line 200, in compile_nodelist
    return parser.parse()
  File "C:\Users\aky\AppData\Local\Programs\Python\Python38\courseu\lib\site-packages\django\template\base.py", line 513, in parse
    raise self.error(token, e)
  File "C:\Users\aky\AppData\Local\Programs\Python\Python38\courseu\lib\site-packages\django\template\base.py", line 511, in parse
    compiled_result = compile_func(self, token)
  File "C:\Users\aky\AppData\Local\Programs\Python\Python38\courseu\lib\site-packages\django\template\loader_tags.py", line 293, in do_extends
    nodelist = parser.parse()
  File "C:\Users\aky\AppData\Local\Programs\Python\Python38\courseu\lib\site-packages\django\template\base.py", line 507, in parse
    self.invalid_block_tag(token, command, parse_until)
  File "C:\Users\aky\AppData\Local\Programs\Python\Python38\courseu\lib\site-packages\django\template\base.py", line 568, in invalid_block_tag
    raise self.error(
django.template.exceptions.TemplateSyntaxError: Invalid block tag on line 5: 'static'. Did you forget to register or load this tag?
ERROR 2023-12-15 18:05:49,152 django.server Thread-16 14896 basehttp basehttp.py 212 django.server log_message 15472 "GET /create_test/ HTTP/1.1" 500 181445
ERROR 2023-12-15 18:36:39,038 django.request Thread-1 13396 log log.py 241 django.request log_response 7544 Internal Server Error: /admin_report/
Traceback (most recent call last):
  File "C:\Users\aky\AppData\Local\Programs\Python\Python38\courseu\lib\site-packages\django\core\handlers\exception.py", line 55, in inner
    response = get_response(request)
  File "C:\Users\aky\AppData\Local\Programs\Python\Python38\courseu\lib\site-packages\django\core\handlers\base.py", line 197, in _get_response
    response = wrapped_callback(request, *callback_args, **callback_kwargs)
  File "C:\Users\aky\AppData\Local\Programs\Python\Python38\eng_ver\apps\website\views.py", line 368, in admin_report
    return render(request, 'admin_report.html', {
  File "C:\Users\aky\AppData\Local\Programs\Python\Python38\courseu\lib\site-packages\django\shortcuts.py", line 24, in render
    content = loader.render_to_string(template_name, context, request, using=using)
  File "C:\Users\aky\AppData\Local\Programs\Python\Python38\courseu\lib\site-packages\django\template\loader.py", line 61, in render_to_string
    template = get_template(template_name, using=using)
  File "C:\Users\aky\AppData\Local\Programs\Python\Python38\courseu\lib\site-packages\django\template\loader.py", line 19, in get_template
    raise TemplateDoesNotExist(template_name, chain=chain)
django.template.exceptions.TemplateDoesNotExist: admin_report.html
ERROR 2023-12-15 18:36:39,293 django.server Thread-1 13396 basehttp basehttp.py 212 django.server log_message 7544 "GET /admin_report/ HTTP/1.1" 500 124294
ERROR 2023-12-15 18:37:24,270 django.request Thread-3 10076 log log.py 241 django.request log_response 8604 Internal Server Error: /admin_home/
Traceback (most recent call last):
  File "C:\Users\aky\AppData\Local\Programs\Python\Python38\courseu\lib\site-packages\django\core\handlers\exception.py", line 55, in inner
    response = get_response(request)
  File "C:\Users\aky\AppData\Local\Programs\Python\Python38\courseu\lib\site-packages\django\core\handlers\base.py", line 197, in _get_response
    response = wrapped_callback(request, *callback_args, **callback_kwargs)
  File "C:\Users\aky\AppData\Local\Programs\Python\Python38\eng_ver\apps\website\views.py", line 173, in admin_home
    return render(request, 'admin_home.html', {
  File "C:\Users\aky\AppData\Local\Programs\Python\Python38\courseu\lib\site-packages\django\shortcuts.py", line 24, in render
    content = loader.render_to_string(template_name, context, request, using=using)
  File "C:\Users\aky\AppData\Local\Programs\Python\Python38\courseu\lib\site-packages\django\template\loader.py", line 61, in render_to_string
    template = get_template(template_name, using=using)
  File "C:\Users\aky\AppData\Local\Programs\Python\Python38\courseu\lib\site-packages\django\template\loader.py", line 19, in get_template
    raise TemplateDoesNotExist(template_name, chain=chain)
django.template.exceptions.TemplateDoesNotExist: admin_home.html
ERROR 2023-12-15 18:37:24,397 django.server Thread-3 10076 basehttp basehttp.py 212 django.server log_message 8604 "GET /admin_home/ HTTP/1.1" 500 113339
ERROR 2023-12-15 18:37:52,104 django.request Thread-4 12444 log log.py 241 django.request log_response 8604 Internal Server Error: /admin_home/
Traceback (most recent call last):
  File "C:\Users\aky\AppData\Local\Programs\Python\Python38\courseu\lib\site-packages\django\core\handlers\exception.py", line 55, in inner
    response = get_response(request)
  File "C:\Users\aky\AppData\Local\Programs\Python\Python38\courseu\lib\site-packages\django\core\handlers\base.py", line 197, in _get_response
    response = wrapped_callback(request, *callback_args, **callback_kwargs)
  File "C:\Users\aky\AppData\Local\Programs\Python\Python38\eng_ver\apps\website\views.py", line 173, in admin_home
    return render(request, 'admin_home.html', {
  File "C:\Users\aky\AppData\Local\Programs\Python\Python38\courseu\lib\site-packages\django\shortcuts.py", line 24, in render
    content = loader.render_to_string(template_name, context, request, using=using)
  File "C:\Users\aky\AppData\Local\Programs\Python\Python38\courseu\lib\site-packages\django\template\loader.py", line 61, in render_to_string
    template = get_template(template_name, using=using)
  File "C:\Users\aky\AppData\Local\Programs\Python\Python38\courseu\lib\site-packages\django\template\loader.py", line 19, in get_template
    raise TemplateDoesNotExist(template_name, chain=chain)
django.template.exceptions.TemplateDoesNotExist: admin_home.html
ERROR 2023-12-15 18:37:52,171 django.server Thread-4 12444 basehttp basehttp.py 212 django.server log_message 8604 "GET /admin_home/ HTTP/1.1" 500 113332
ERROR 2023-12-15 18:38:12,598 django.request Thread-1 8932 log log.py 241 django.request log_response 13932 Internal Server Error: /admin_home/
Traceback (most recent call last):
  File "C:\Users\aky\AppData\Local\Programs\Python\Python38\courseu\lib\site-packages\django\core\handlers\exception.py", line 55, in inner
    response = get_response(request)
  File "C:\Users\aky\AppData\Local\Programs\Python\Python38\courseu\lib\site-packages\django\core\handlers\base.py", line 197, in _get_response
    response = wrapped_callback(request, *callback_args, **callback_kwargs)
  File "C:\Users\aky\AppData\Local\Programs\Python\Python38\eng_ver\apps\website\views.py", line 173, in admin_home
    return render(request, 'dashboard/admin_home.html', {
  File "C:\Users\aky\AppData\Local\Programs\Python\Python38\courseu\lib\site-packages\django\shortcuts.py", line 24, in render
    content = loader.render_to_string(template_name, context, request, using=using)
  File "C:\Users\aky\AppData\Local\Programs\Python\Python38\courseu\lib\site-packages\django\template\loader.py", line 61, in render_to_string
    template = get_template(template_name, using=using)
  File "C:\Users\aky\AppData\Local\Programs\Python\Python38\courseu\lib\site-packages\django\template\loader.py", line 19, in get_template
    raise TemplateDoesNotExist(template_name, chain=chain)
django.template.exceptions.TemplateDoesNotExist: admin_home.html
ERROR 2023-12-15 18:38:12,835 django.server Thread-1 8932 basehttp basehttp.py 212 django.server log_message 13932 "GET /admin_home/ HTTP/1.1" 500 113353
ERROR 2023-12-15 18:38:21,378 django.request Thread-1 11736 log log.py 241 django.request log_response 7576 Internal Server Error: /admin_home/
Traceback (most recent call last):
  File "C:\Users\aky\AppData\Local\Programs\Python\Python38\courseu\lib\site-packages\django\template\backends\django.py", line 61, in render
    return self.template.render(context)
  File "C:\Users\aky\AppData\Local\Programs\Python\Python38\courseu\lib\site-packages\django\template\base.py", line 175, in render
    return self._render(context)
  File "C:\Users\aky\AppData\Local\Programs\Python\Python38\courseu\lib\site-packages\django\test\utils.py", line 112, in instrumented_test_render
    return self.nodelist.render(context)
  File "C:\Users\aky\AppData\Local\Programs\Python\Python38\courseu\lib\site-packages\django\template\base.py", line 1005, in render
    return SafeString("".join([node.render_annotated(context) for node in self]))
  File "C:\Users\aky\AppData\Local\Programs\Python\Python38\courseu\lib\site-packages\django\template\base.py", line 1005, in <listcomp>
    return SafeString("".join([node.render_annotated(context) for node in self]))
  File "C:\Users\aky\AppData\Local\Programs\Python\Python38\courseu\lib\site-packages\django\template\base.py", line 966, in render_annotated
    return self.render(context)
  File "C:\Users\aky\AppData\Local\Programs\Python\Python38\courseu\lib\site-packages\django\template\loader_tags.py", line 157, in render
    return compiled_parent._render(context)
  File "C:\Users\aky\AppData\Local\Programs\Python\Python38\courseu\lib\site-packages\django\test\utils.py", line 112, in instrumented_test_render
    return self.nodelist.render(context)
  File "C:\Users\aky\AppData\Local\Programs\Python\Python38\courseu\lib\site-packages\django\template\base.py", line 1005, in render
    return SafeString("".join([node.render_annotated(context) for node in self]))
  File "C:\Users\aky\AppData\Local\Programs\Python\Python38\courseu\lib\site-packages\django\template\base.py", line 1005, in <listcomp>
    return SafeString("".join([node.render_annotated(context) for node in self]))
  File "C:\Users\aky\AppData\Local\Programs\Python\Python38\courseu\lib\site-packages\django\template\base.py", line 966, in render_annotated
    return self.render(context)
  File "C:\Users\aky\AppData\Local\Programs\Python\Python38\courseu\lib\site-packages\django\template\defaulttags.py", line 321, in render
    return nodelist.render(context)
  File "C:\Users\aky\AppData\Local\Programs\Python\Python38\courseu\lib\site-packages\django\template\base.py", line 1005, in render
    return SafeString("".join([node.render_annotated(context) for node in self]))
  File "C:\Users\aky\AppData\Local\Programs\Python\Python38\courseu\lib\site-packages\django\template\base.py", line 1005, in <listcomp>
    return SafeString("".join([node.render_annotated(context) for node in self]))
  File "C:\Users\aky\AppData\Local\Programs\Python\Python38\courseu\lib\site-packages\django\template\base.py", line 966, in render_annotated
    return self.render(context)
  File "C:\Users\aky\AppData\Local\Programs\Python\Python38\courseu\lib\site-packages\django\template\loader_tags.py", line 63, in render
    result = block.nodelist.render(context)
  File "C:\Users\aky\AppData\Local\Programs\Python\Python38\courseu\lib\site-packages\django\template\base.py", line 1005, in render
    return SafeString("".join([node.render_annotated(context) for node in self]))
  File "C:\Users\aky\AppData\Local\Programs\Python\Python38\courseu\lib\site-packages\django\template\base.py", line 1005, in <listcomp>
    return SafeString("".join([node.render_annotated(context) for node in self]))
  File "C:\Users\aky\AppData\Local\Programs\Python\Python38\courseu\lib\site-packages\django\template\base.py", line 966, in render_annotated
    return self.render(context)
  File "C:\Users\aky\AppData\Local\Programs\Python\Python38\courseu\lib\site-packages\django\template\defaulttags.py", line 321, in render
    return nodelist.render(context)
  File "C:\Users\aky\AppData\Local\Programs\Python\Python38\courseu\lib\site-packages\django\template\base.py", line 1005, in render
    return SafeString("".join([node.render_annotated(context) for node in self]))
  File "C:\Users\aky\AppData\Local\Programs\Python\Python38\courseu\lib\site-packages\django\template\base.py", line 1005, in <listcomp>
    return SafeString("".join([node.render_annotated(context) for node in self]))
  File "C:\Users\aky\AppData\Local\Programs\Python\Python38\courseu\lib\site-packages\django\template\base.py", line 966, in render_annotated
    return self.render(context)
  File "C:\Users\aky\AppData\Local\Programs\Python\Python38\courseu\lib\site-packages\django\template\loader_tags.py", line 197, in render
    template = context.template.engine.select_template(template_name)
  File "C:\Users\aky\AppData\Local\Programs\Python\Python38\courseu\lib\site-packages\django\template\engine.py", line 212, in select_template
    raise TemplateDoesNotExist(", ".join(not_found))
django.template.exceptions.TemplateDoesNotExist: status.html

The above exception was the direct cause of the following exception:

Traceback (most recent call last):
  File "C:\Users\aky\AppData\Local\Programs\Python\Python38\courseu\lib\site-packages\django\core\handlers\exception.py", line 55, in inner
    response = get_response(request)
  File "C:\Users\aky\AppData\Local\Programs\Python\Python38\courseu\lib\site-packages\django\core\handlers\base.py", line 197, in _get_response
    response = wrapped_callback(request, *callback_args, **callback_kwargs)
  File "C:\Users\aky\AppData\Local\Programs\Python\Python38\eng_ver\apps\website\views.py", line 173, in admin_home
    return render(request, 'dashboard/admin_home.html', {
  File "C:\Users\aky\AppData\Local\Programs\Python\Python38\courseu\lib\site-packages\django\shortcuts.py", line 24, in render
    content = loader.render_to_string(template_name, context, request, using=using)
  File "C:\Users\aky\AppData\Local\Programs\Python\Python38\courseu\lib\site-packages\django\template\loader.py", line 62, in render_to_string
    return template.render(context, request)
  File "C:\Users\aky\AppData\Local\Programs\Python\Python38\courseu\lib\site-packages\django\template\backends\django.py", line 63, in render
    reraise(exc, self.backend)
  File "C:\Users\aky\AppData\Local\Programs\Python\Python38\courseu\lib\site-packages\django\template\backends\django.py", line 84, in reraise
    raise new from exc
django.template.exceptions.TemplateDoesNotExist: status.html
ERROR 2023-12-15 18:38:21,657 django.server Thread-1 11736 basehttp basehttp.py 212 django.server log_message 7576 "GET /admin_home/ HTTP/1.1" 500 246975
ERROR 2023-12-15 18:39:42,301 django.request Thread-1 4576 log log.py 241 django.request log_response 14744 Internal Server Error: /create_test/
Traceback (most recent call last):
  File "C:\Users\aky\AppData\Local\Programs\Python\Python38\courseu\lib\site-packages\django\core\handlers\exception.py", line 55, in inner
    response = get_response(request)
  File "C:\Users\aky\AppData\Local\Programs\Python\Python38\courseu\lib\site-packages\django\core\handlers\base.py", line 197, in _get_response
    response = wrapped_callback(request, *callback_args, **callback_kwargs)
  File "C:\Users\aky\AppData\Local\Programs\Python\Python38\eng_ver\apps\assessment\views.py", line 852, in create_test
    return render(request, 'test/create_test.html', context)
  File "C:\Users\aky\AppData\Local\Programs\Python\Python38\courseu\lib\site-packages\django\shortcuts.py", line 24, in render
    content = loader.render_to_string(template_name, context, request, using=using)
  File "C:\Users\aky\AppData\Local\Programs\Python\Python38\courseu\lib\site-packages\django\template\loader.py", line 61, in render_to_string
    template = get_template(template_name, using=using)
  File "C:\Users\aky\AppData\Local\Programs\Python\Python38\courseu\lib\site-packages\django\template\loader.py", line 19, in get_template
    raise TemplateDoesNotExist(template_name, chain=chain)
django.template.exceptions.TemplateDoesNotExist: test/create_test.html
ERROR 2023-12-15 18:39:42,356 django.server Thread-1 4576 basehttp basehttp.py 212 django.server log_message 14744 "GET /create_test/ HTTP/1.1" 500 109104
ERROR 2023-12-15 18:40:45,574 django.request Thread-1 13744 log log.py 241 django.request log_response 1376 Internal Server Error: /create_test/
Traceback (most recent call last):
  File "C:\Users\aky\AppData\Local\Programs\Python\Python38\courseu\lib\site-packages\django\core\handlers\exception.py", line 55, in inner
    response = get_response(request)
  File "C:\Users\aky\AppData\Local\Programs\Python\Python38\courseu\lib\site-packages\django\core\handlers\base.py", line 197, in _get_response
    response = wrapped_callback(request, *callback_args, **callback_kwargs)
  File "C:\Users\aky\AppData\Local\Programs\Python\Python38\eng_ver\apps\assessment\views.py", line 852, in create_test
    return render(request, 'dashboard/create_test.html', context)
  File "C:\Users\aky\AppData\Local\Programs\Python\Python38\courseu\lib\site-packages\django\shortcuts.py", line 24, in render
    content = loader.render_to_string(template_name, context, request, using=using)
  File "C:\Users\aky\AppData\Local\Programs\Python\Python38\courseu\lib\site-packages\django\template\loader.py", line 61, in render_to_string
    template = get_template(template_name, using=using)
  File "C:\Users\aky\AppData\Local\Programs\Python\Python38\courseu\lib\site-packages\django\template\loader.py", line 19, in get_template
    raise TemplateDoesNotExist(template_name, chain=chain)
django.template.exceptions.TemplateDoesNotExist: dahsboard/create_test.html
ERROR 2023-12-15 18:40:45,589 django.request Thread-2 9184 log log.py 241 django.request log_response 1376 Internal Server Error: /create_test/
Traceback (most recent call last):
  File "C:\Users\aky\AppData\Local\Programs\Python\Python38\courseu\lib\site-packages\django\core\handlers\exception.py", line 55, in inner
    response = get_response(request)
  File "C:\Users\aky\AppData\Local\Programs\Python\Python38\courseu\lib\site-packages\django\core\handlers\base.py", line 197, in _get_response
    response = wrapped_callback(request, *callback_args, **callback_kwargs)
  File "C:\Users\aky\AppData\Local\Programs\Python\Python38\eng_ver\apps\assessment\views.py", line 852, in create_test
    return render(request, 'dashboard/create_test.html', context)
  File "C:\Users\aky\AppData\Local\Programs\Python\Python38\courseu\lib\site-packages\django\shortcuts.py", line 24, in render
    content = loader.render_to_string(template_name, context, request, using=using)
  File "C:\Users\aky\AppData\Local\Programs\Python\Python38\courseu\lib\site-packages\django\template\loader.py", line 61, in render_to_string
    template = get_template(template_name, using=using)
  File "C:\Users\aky\AppData\Local\Programs\Python\Python38\courseu\lib\site-packages\django\template\loader.py", line 19, in get_template
    raise TemplateDoesNotExist(template_name, chain=chain)
django.template.exceptions.TemplateDoesNotExist: dahsboard/create_test.html
ERROR 2023-12-15 18:40:45,881 django.server Thread-2 9184 basehttp basehttp.py 212 django.server log_message 1376 "GET /create_test/ HTTP/1.1" 500 109204
ERROR 2023-12-15 18:40:48,559 django.request Thread-2 9184 log log.py 241 django.request log_response 1376 Internal Server Error: /create_test/
Traceback (most recent call last):
  File "C:\Users\aky\AppData\Local\Programs\Python\Python38\courseu\lib\site-packages\django\core\handlers\exception.py", line 55, in inner
    response = get_response(request)
  File "C:\Users\aky\AppData\Local\Programs\Python\Python38\courseu\lib\site-packages\django\core\handlers\base.py", line 197, in _get_response
    response = wrapped_callback(request, *callback_args, **callback_kwargs)
  File "C:\Users\aky\AppData\Local\Programs\Python\Python38\eng_ver\apps\assessment\views.py", line 852, in create_test
    return render(request, 'dashboard/create_test.html', context)
  File "C:\Users\aky\AppData\Local\Programs\Python\Python38\courseu\lib\site-packages\django\shortcuts.py", line 24, in render
    content = loader.render_to_string(template_name, context, request, using=using)
  File "C:\Users\aky\AppData\Local\Programs\Python\Python38\courseu\lib\site-packages\django\template\loader.py", line 61, in render_to_string
    template = get_template(template_name, using=using)
  File "C:\Users\aky\AppData\Local\Programs\Python\Python38\courseu\lib\site-packages\django\template\loader.py", line 19, in get_template
    raise TemplateDoesNotExist(template_name, chain=chain)
django.template.exceptions.TemplateDoesNotExist: dahsboard/create_test.html
ERROR 2023-12-15 18:40:48,650 django.server Thread-2 9184 basehttp basehttp.py 212 django.server log_message 1376 "GET /create_test/ HTTP/1.1" 500 109204
WARNING 2023-12-15 18:45:43,949 django.request Thread-3 8608 log log.py 241 django.request log_response 14416 Not Found: /admin_students class=
WARNING 2023-12-15 18:45:43,951 django.server Thread-3 8608 basehttp basehttp.py 212 django.server log_message 14416 "GET /admin_students%20class= HTTP/1.1" 404 26213
WARNING 2023-12-15 18:45:59,704 django.request Thread-1 10504 log log.py 241 django.request log_response 16076 Not Found: /admin_students class=
WARNING 2023-12-15 18:45:59,706 django.server Thread-1 10504 basehttp basehttp.py 212 django.server log_message 16076 "GET /admin_students%20class= HTTP/1.1" 404 26213
WARNING 2023-12-15 18:46:24,276 django.request Thread-1 10504 log log.py 241 django.request log_response 16076 Not Found: /admin_students class=
WARNING 2023-12-15 18:46:24,278 django.server Thread-1 10504 basehttp basehttp.py 212 django.server log_message 16076 "GET /admin_students%20class= HTTP/1.1" 404 26213
ERROR 2023-12-15 18:46:34,061 django.request Thread-1 10504 log log.py 241 django.request log_response 16076 Internal Server Error: /admin_students
Traceback (most recent call last):
  File "C:\Users\aky\AppData\Local\Programs\Python\Python38\courseu\lib\site-packages\django\core\handlers\exception.py", line 55, in inner
    response = get_response(request)
  File "C:\Users\aky\AppData\Local\Programs\Python\Python38\courseu\lib\site-packages\django\core\handlers\base.py", line 197, in _get_response
    response = wrapped_callback(request, *callback_args, **callback_kwargs)
  File "C:\Users\aky\AppData\Local\Programs\Python\Python38\eng_ver\apps\website\views.py", line 189, in admin_students
    return render(request, 'dashboad/admin_students.html', {'auth_user': auth_user})
  File "C:\Users\aky\AppData\Local\Programs\Python\Python38\courseu\lib\site-packages\django\shortcuts.py", line 24, in render
    content = loader.render_to_string(template_name, context, request, using=using)
  File "C:\Users\aky\AppData\Local\Programs\Python\Python38\courseu\lib\site-packages\django\template\loader.py", line 61, in render_to_string
    template = get_template(template_name, using=using)
  File "C:\Users\aky\AppData\Local\Programs\Python\Python38\courseu\lib\site-packages\django\template\loader.py", line 19, in get_template
    raise TemplateDoesNotExist(template_name, chain=chain)
django.template.exceptions.TemplateDoesNotExist: dashboad/admin_students.html
ERROR 2023-12-15 18:46:34,133 django.server Thread-1 10504 basehttp basehttp.py 212 django.server log_message 16076 "GET /admin_students HTTP/1.1" 500 108776
WARNING 2023-12-15 18:47:06,465 django.request Thread-1 9084 log log.py 241 django.request log_response 14560 Not Found: /admin_students class=
WARNING 2023-12-15 18:47:06,466 django.server Thread-1 9084 basehttp basehttp.py 212 django.server log_message 14560 "GET /admin_students%20class= HTTP/1.1" 404 26213
WARNING 2023-12-15 18:47:44,692 django.request Thread-1 12324 log log.py 241 django.request log_response 14832 Not Found: /admin_students class=
ERROR 2023-12-15 18:48:34,104 django.request Thread-3 1376 log log.py 241 django.request log_response 14832 Internal Server Error: /admin_students
Traceback (most recent call last):
  File "C:\Users\aky\AppData\Local\Programs\Python\Python38\courseu\lib\site-packages\django\template\base.py", line 505, in parse
    compile_func = self.tags[command]
KeyError: 'static'

During handling of the above exception, another exception occurred:

Traceback (most recent call last):
  File "C:\Users\aky\AppData\Local\Programs\Python\Python38\courseu\lib\site-packages\django\core\handlers\exception.py", line 55, in inner
    response = get_response(request)
  File "C:\Users\aky\AppData\Local\Programs\Python\Python38\courseu\lib\site-packages\django\core\handlers\base.py", line 197, in _get_response
    response = wrapped_callback(request, *callback_args, **callback_kwargs)
  File "C:\Users\aky\AppData\Local\Programs\Python\Python38\eng_ver\apps\website\views.py", line 189, in admin_students
    return render(request, 'dashboard/admin_students.html', {'auth_user': auth_user})
  File "C:\Users\aky\AppData\Local\Programs\Python\Python38\courseu\lib\site-packages\django\shortcuts.py", line 24, in render
    content = loader.render_to_string(template_name, context, request, using=using)
  File "C:\Users\aky\AppData\Local\Programs\Python\Python38\courseu\lib\site-packages\django\template\loader.py", line 61, in render_to_string
    template = get_template(template_name, using=using)
  File "C:\Users\aky\AppData\Local\Programs\Python\Python38\courseu\lib\site-packages\django\template\loader.py", line 15, in get_template
    return engine.get_template(template_name)
  File "C:\Users\aky\AppData\Local\Programs\Python\Python38\courseu\lib\site-packages\django\template\backends\django.py", line 33, in get_template
    return Template(self.engine.get_template(template_name), self)
  File "C:\Users\aky\AppData\Local\Programs\Python\Python38\courseu\lib\site-packages\django\template\engine.py", line 175, in get_template
    template, origin = self.find_template(template_name)
  File "C:\Users\aky\AppData\Local\Programs\Python\Python38\courseu\lib\site-packages\django\template\engine.py", line 157, in find_template
    template = loader.get_template(name, skip=skip)
  File "C:\Users\aky\AppData\Local\Programs\Python\Python38\courseu\lib\site-packages\django\template\loaders\cached.py", line 57, in get_template
    template = super().get_template(template_name, skip)
  File "C:\Users\aky\AppData\Local\Programs\Python\Python38\courseu\lib\site-packages\django\template\loaders\base.py", line 28, in get_template
    return Template(
  File "C:\Users\aky\AppData\Local\Programs\Python\Python38\courseu\lib\site-packages\django\template\base.py", line 154, in __init__
    self.nodelist = self.compile_nodelist()
  File "C:\Users\aky\AppData\Local\Programs\Python\Python38\courseu\lib\site-packages\django\template\base.py", line 200, in compile_nodelist
    return parser.parse()
  File "C:\Users\aky\AppData\Local\Programs\Python\Python38\courseu\lib\site-packages\django\template\base.py", line 513, in parse
    raise self.error(token, e)
  File "C:\Users\aky\AppData\Local\Programs\Python\Python38\courseu\lib\site-packages\django\template\base.py", line 511, in parse
    compiled_result = compile_func(self, token)
  File "C:\Users\aky\AppData\Local\Programs\Python\Python38\courseu\lib\site-packages\django\template\loader_tags.py", line 293, in do_extends
    nodelist = parser.parse()
  File "C:\Users\aky\AppData\Local\Programs\Python\Python38\courseu\lib\site-packages\django\template\base.py", line 513, in parse
    raise self.error(token, e)
  File "C:\Users\aky\AppData\Local\Programs\Python\Python38\courseu\lib\site-packages\django\template\base.py", line 511, in parse
    compiled_result = compile_func(self, token)
  File "C:\Users\aky\AppData\Local\Programs\Python\Python38\courseu\lib\site-packages\django\template\loader_tags.py", line 232, in do_block
    nodelist = parser.parse(("endblock",))
  File "C:\Users\aky\AppData\Local\Programs\Python\Python38\courseu\lib\site-packages\django\template\base.py", line 507, in parse
    self.invalid_block_tag(token, command, parse_until)
  File "C:\Users\aky\AppData\Local\Programs\Python\Python38\courseu\lib\site-packages\django\template\base.py", line 558, in invalid_block_tag
    raise self.error(
django.template.exceptions.TemplateSyntaxError: Invalid block tag on line 8: 'static', expected 'endblock'. Did you forget to register or load this tag?
ERROR 2023-12-15 18:48:34,310 django.server Thread-3 1376 basehttp basehttp.py 212 django.server log_message 14832 "GET /admin_students HTTP/1.1" 500 212130
ERROR 2023-12-15 18:48:41,883 django.request Thread-3 1376 log log.py 241 django.request log_response 14832 Internal Server Error: /admin_students
Traceback (most recent call last):
  File "C:\Users\aky\AppData\Local\Programs\Python\Python38\courseu\lib\site-packages\django\template\base.py", line 505, in parse
    compile_func = self.tags[command]
KeyError: 'static'

During handling of the above exception, another exception occurred:

Traceback (most recent call last):
  File "C:\Users\aky\AppData\Local\Programs\Python\Python38\courseu\lib\site-packages\django\core\handlers\exception.py", line 55, in inner
    response = get_response(request)
  File "C:\Users\aky\AppData\Local\Programs\Python\Python38\courseu\lib\site-packages\django\core\handlers\base.py", line 197, in _get_response
    response = wrapped_callback(request, *callback_args, **callback_kwargs)
  File "C:\Users\aky\AppData\Local\Programs\Python\Python38\eng_ver\apps\website\views.py", line 189, in admin_students
    return render(request, 'dashboard/admin_students.html', {'auth_user': auth_user})
  File "C:\Users\aky\AppData\Local\Programs\Python\Python38\courseu\lib\site-packages\django\shortcuts.py", line 24, in render
    content = loader.render_to_string(template_name, context, request, using=using)
  File "C:\Users\aky\AppData\Local\Programs\Python\Python38\courseu\lib\site-packages\django\template\loader.py", line 61, in render_to_string
    template = get_template(template_name, using=using)
  File "C:\Users\aky\AppData\Local\Programs\Python\Python38\courseu\lib\site-packages\django\template\loader.py", line 15, in get_template
    return engine.get_template(template_name)
  File "C:\Users\aky\AppData\Local\Programs\Python\Python38\courseu\lib\site-packages\django\template\backends\django.py", line 33, in get_template
    return Template(self.engine.get_template(template_name), self)
  File "C:\Users\aky\AppData\Local\Programs\Python\Python38\courseu\lib\site-packages\django\template\engine.py", line 175, in get_template
    template, origin = self.find_template(template_name)
  File "C:\Users\aky\AppData\Local\Programs\Python\Python38\courseu\lib\site-packages\django\template\engine.py", line 157, in find_template
    template = loader.get_template(name, skip=skip)
  File "C:\Users\aky\AppData\Local\Programs\Python\Python38\courseu\lib\site-packages\django\template\loaders\cached.py", line 57, in get_template
    template = super().get_template(template_name, skip)
  File "C:\Users\aky\AppData\Local\Programs\Python\Python38\courseu\lib\site-packages\django\template\loaders\base.py", line 28, in get_template
    return Template(
  File "C:\Users\aky\AppData\Local\Programs\Python\Python38\courseu\lib\site-packages\django\template\base.py", line 154, in __init__
    self.nodelist = self.compile_nodelist()
  File "C:\Users\aky\AppData\Local\Programs\Python\Python38\courseu\lib\site-packages\django\template\base.py", line 200, in compile_nodelist
    return parser.parse()
  File "C:\Users\aky\AppData\Local\Programs\Python\Python38\courseu\lib\site-packages\django\template\base.py", line 513, in parse
    raise self.error(token, e)
  File "C:\Users\aky\AppData\Local\Programs\Python\Python38\courseu\lib\site-packages\django\template\base.py", line 511, in parse
    compiled_result = compile_func(self, token)
  File "C:\Users\aky\AppData\Local\Programs\Python\Python38\courseu\lib\site-packages\django\template\loader_tags.py", line 293, in do_extends
    nodelist = parser.parse()
  File "C:\Users\aky\AppData\Local\Programs\Python\Python38\courseu\lib\site-packages\django\template\base.py", line 513, in parse
    raise self.error(token, e)
  File "C:\Users\aky\AppData\Local\Programs\Python\Python38\courseu\lib\site-packages\django\template\base.py", line 511, in parse
    compiled_result = compile_func(self, token)
  File "C:\Users\aky\AppData\Local\Programs\Python\Python38\courseu\lib\site-packages\django\template\loader_tags.py", line 232, in do_block
    nodelist = parser.parse(("endblock",))
  File "C:\Users\aky\AppData\Local\Programs\Python\Python38\courseu\lib\site-packages\django\template\base.py", line 507, in parse
    self.invalid_block_tag(token, command, parse_until)
  File "C:\Users\aky\AppData\Local\Programs\Python\Python38\courseu\lib\site-packages\django\template\base.py", line 558, in invalid_block_tag
    raise self.error(
django.template.exceptions.TemplateSyntaxError: Invalid block tag on line 8: 'static', expected 'endblock'. Did you forget to register or load this tag?
ERROR 2023-12-15 18:48:41,991 django.server Thread-3 1376 basehttp basehttp.py 212 django.server log_message 14832 "GET /admin_students HTTP/1.1" 500 212130
ERROR 2023-12-15 18:48:48,790 django.request Thread-3 1376 log log.py 241 django.request log_response 14832 Internal Server Error: /admin_students
Traceback (most recent call last):
  File "C:\Users\aky\AppData\Local\Programs\Python\Python38\courseu\lib\site-packages\django\template\base.py", line 505, in parse
    compile_func = self.tags[command]
KeyError: 'static'

During handling of the above exception, another exception occurred:

Traceback (most recent call last):
  File "C:\Users\aky\AppData\Local\Programs\Python\Python38\courseu\lib\site-packages\django\core\handlers\exception.py", line 55, in inner
    response = get_response(request)
  File "C:\Users\aky\AppData\Local\Programs\Python\Python38\courseu\lib\site-packages\django\core\handlers\base.py", line 197, in _get_response
    response = wrapped_callback(request, *callback_args, **callback_kwargs)
  File "C:\Users\aky\AppData\Local\Programs\Python\Python38\eng_ver\apps\website\views.py", line 189, in admin_students
    return render(request, 'dashboard/admin_students.html', {'auth_user': auth_user})
  File "C:\Users\aky\AppData\Local\Programs\Python\Python38\courseu\lib\site-packages\django\shortcuts.py", line 24, in render
    content = loader.render_to_string(template_name, context, request, using=using)
  File "C:\Users\aky\AppData\Local\Programs\Python\Python38\courseu\lib\site-packages\django\template\loader.py", line 61, in render_to_string
    template = get_template(template_name, using=using)
  File "C:\Users\aky\AppData\Local\Programs\Python\Python38\courseu\lib\site-packages\django\template\loader.py", line 15, in get_template
    return engine.get_template(template_name)
  File "C:\Users\aky\AppData\Local\Programs\Python\Python38\courseu\lib\site-packages\django\template\backends\django.py", line 33, in get_template
    return Template(self.engine.get_template(template_name), self)
  File "C:\Users\aky\AppData\Local\Programs\Python\Python38\courseu\lib\site-packages\django\template\engine.py", line 175, in get_template
    template, origin = self.find_template(template_name)
  File "C:\Users\aky\AppData\Local\Programs\Python\Python38\courseu\lib\site-packages\django\template\engine.py", line 157, in find_template
    template = loader.get_template(name, skip=skip)
  File "C:\Users\aky\AppData\Local\Programs\Python\Python38\courseu\lib\site-packages\django\template\loaders\cached.py", line 57, in get_template
    template = super().get_template(template_name, skip)
  File "C:\Users\aky\AppData\Local\Programs\Python\Python38\courseu\lib\site-packages\django\template\loaders\base.py", line 28, in get_template
    return Template(
  File "C:\Users\aky\AppData\Local\Programs\Python\Python38\courseu\lib\site-packages\django\template\base.py", line 154, in __init__
    self.nodelist = self.compile_nodelist()
  File "C:\Users\aky\AppData\Local\Programs\Python\Python38\courseu\lib\site-packages\django\template\base.py", line 200, in compile_nodelist
    return parser.parse()
  File "C:\Users\aky\AppData\Local\Programs\Python\Python38\courseu\lib\site-packages\django\template\base.py", line 513, in parse
    raise self.error(token, e)
  File "C:\Users\aky\AppData\Local\Programs\Python\Python38\courseu\lib\site-packages\django\template\base.py", line 511, in parse
    compiled_result = compile_func(self, token)
  File "C:\Users\aky\AppData\Local\Programs\Python\Python38\courseu\lib\site-packages\django\template\loader_tags.py", line 293, in do_extends
    nodelist = parser.parse()
  File "C:\Users\aky\AppData\Local\Programs\Python\Python38\courseu\lib\site-packages\django\template\base.py", line 513, in parse
    raise self.error(token, e)
  File "C:\Users\aky\AppData\Local\Programs\Python\Python38\courseu\lib\site-packages\django\template\base.py", line 511, in parse
    compiled_result = compile_func(self, token)
  File "C:\Users\aky\AppData\Local\Programs\Python\Python38\courseu\lib\site-packages\django\template\loader_tags.py", line 232, in do_block
    nodelist = parser.parse(("endblock",))
  File "C:\Users\aky\AppData\Local\Programs\Python\Python38\courseu\lib\site-packages\django\template\base.py", line 507, in parse
    self.invalid_block_tag(token, command, parse_until)
  File "C:\Users\aky\AppData\Local\Programs\Python\Python38\courseu\lib\site-packages\django\template\base.py", line 558, in invalid_block_tag
    raise self.error(
django.template.exceptions.TemplateSyntaxError: Invalid block tag on line 9: 'static', expected 'endblock'. Did you forget to register or load this tag?
ERROR 2023-12-15 18:48:48,911 django.server Thread-3 1376 basehttp basehttp.py 212 django.server log_message 14832 "GET /admin_students HTTP/1.1" 500 212179
ERROR 2023-12-15 18:48:51,203 django.request Thread-3 1376 log log.py 241 django.request log_response 14832 Internal Server Error: /admin_students
Traceback (most recent call last):
  File "C:\Users\aky\AppData\Local\Programs\Python\Python38\courseu\lib\site-packages\django\template\base.py", line 505, in parse
    compile_func = self.tags[command]
KeyError: 'static'

During handling of the above exception, another exception occurred:

Traceback (most recent call last):
  File "C:\Users\aky\AppData\Local\Programs\Python\Python38\courseu\lib\site-packages\django\core\handlers\exception.py", line 55, in inner
    response = get_response(request)
  File "C:\Users\aky\AppData\Local\Programs\Python\Python38\courseu\lib\site-packages\django\core\handlers\base.py", line 197, in _get_response
    response = wrapped_callback(request, *callback_args, **callback_kwargs)
  File "C:\Users\aky\AppData\Local\Programs\Python\Python38\eng_ver\apps\website\views.py", line 189, in admin_students
    return render(request, 'dashboard/admin_students.html', {'auth_user': auth_user})
  File "C:\Users\aky\AppData\Local\Programs\Python\Python38\courseu\lib\site-packages\django\shortcuts.py", line 24, in render
    content = loader.render_to_string(template_name, context, request, using=using)
  File "C:\Users\aky\AppData\Local\Programs\Python\Python38\courseu\lib\site-packages\django\template\loader.py", line 61, in render_to_string
    template = get_template(template_name, using=using)
  File "C:\Users\aky\AppData\Local\Programs\Python\Python38\courseu\lib\site-packages\django\template\loader.py", line 15, in get_template
    return engine.get_template(template_name)
  File "C:\Users\aky\AppData\Local\Programs\Python\Python38\courseu\lib\site-packages\django\template\backends\django.py", line 33, in get_template
    return Template(self.engine.get_template(template_name), self)
  File "C:\Users\aky\AppData\Local\Programs\Python\Python38\courseu\lib\site-packages\django\template\engine.py", line 175, in get_template
    template, origin = self.find_template(template_name)
  File "C:\Users\aky\AppData\Local\Programs\Python\Python38\courseu\lib\site-packages\django\template\engine.py", line 157, in find_template
    template = loader.get_template(name, skip=skip)
  File "C:\Users\aky\AppData\Local\Programs\Python\Python38\courseu\lib\site-packages\django\template\loaders\cached.py", line 57, in get_template
    template = super().get_template(template_name, skip)
  File "C:\Users\aky\AppData\Local\Programs\Python\Python38\courseu\lib\site-packages\django\template\loaders\base.py", line 28, in get_template
    return Template(
  File "C:\Users\aky\AppData\Local\Programs\Python\Python38\courseu\lib\site-packages\django\template\base.py", line 154, in __init__
    self.nodelist = self.compile_nodelist()
  File "C:\Users\aky\AppData\Local\Programs\Python\Python38\courseu\lib\site-packages\django\template\base.py", line 200, in compile_nodelist
    return parser.parse()
  File "C:\Users\aky\AppData\Local\Programs\Python\Python38\courseu\lib\site-packages\django\template\base.py", line 513, in parse
    raise self.error(token, e)
  File "C:\Users\aky\AppData\Local\Programs\Python\Python38\courseu\lib\site-packages\django\template\base.py", line 511, in parse
    compiled_result = compile_func(self, token)
  File "C:\Users\aky\AppData\Local\Programs\Python\Python38\courseu\lib\site-packages\django\template\loader_tags.py", line 293, in do_extends
    nodelist = parser.parse()
  File "C:\Users\aky\AppData\Local\Programs\Python\Python38\courseu\lib\site-packages\django\template\base.py", line 513, in parse
    raise self.error(token, e)
  File "C:\Users\aky\AppData\Local\Programs\Python\Python38\courseu\lib\site-packages\django\template\base.py", line 511, in parse
    compiled_result = compile_func(self, token)
  File "C:\Users\aky\AppData\Local\Programs\Python\Python38\courseu\lib\site-packages\django\template\loader_tags.py", line 232, in do_block
    nodelist = parser.parse(("endblock",))
  File "C:\Users\aky\AppData\Local\Programs\Python\Python38\courseu\lib\site-packages\django\template\base.py", line 507, in parse
    self.invalid_block_tag(token, command, parse_until)
  File "C:\Users\aky\AppData\Local\Programs\Python\Python38\courseu\lib\site-packages\django\template\base.py", line 558, in invalid_block_tag
    raise self.error(
django.template.exceptions.TemplateSyntaxError: Invalid block tag on line 9: 'static', expected 'endblock'. Did you forget to register or load this tag?
ERROR 2023-12-15 18:48:51,324 django.server Thread-3 1376 basehttp basehttp.py 212 django.server log_message 14832 "GET /admin_students HTTP/1.1" 500 212179
ERROR 2023-12-15 18:48:54,351 django.request Thread-3 1376 log log.py 241 django.request log_response 14832 Internal Server Error: /admin_students
Traceback (most recent call last):
  File "C:\Users\aky\AppData\Local\Programs\Python\Python38\courseu\lib\site-packages\django\template\base.py", line 505, in parse
    compile_func = self.tags[command]
KeyError: 'static'

During handling of the above exception, another exception occurred:

Traceback (most recent call last):
  File "C:\Users\aky\AppData\Local\Programs\Python\Python38\courseu\lib\site-packages\django\core\handlers\exception.py", line 55, in inner
    response = get_response(request)
  File "C:\Users\aky\AppData\Local\Programs\Python\Python38\courseu\lib\site-packages\django\core\handlers\base.py", line 197, in _get_response
    response = wrapped_callback(request, *callback_args, **callback_kwargs)
  File "C:\Users\aky\AppData\Local\Programs\Python\Python38\eng_ver\apps\website\views.py", line 189, in admin_students
    return render(request, 'dashboard/admin_students.html', {'auth_user': auth_user})
  File "C:\Users\aky\AppData\Local\Programs\Python\Python38\courseu\lib\site-packages\django\shortcuts.py", line 24, in render
    content = loader.render_to_string(template_name, context, request, using=using)
  File "C:\Users\aky\AppData\Local\Programs\Python\Python38\courseu\lib\site-packages\django\template\loader.py", line 61, in render_to_string
    template = get_template(template_name, using=using)
  File "C:\Users\aky\AppData\Local\Programs\Python\Python38\courseu\lib\site-packages\django\template\loader.py", line 15, in get_template
    return engine.get_template(template_name)
  File "C:\Users\aky\AppData\Local\Programs\Python\Python38\courseu\lib\site-packages\django\template\backends\django.py", line 33, in get_template
    return Template(self.engine.get_template(template_name), self)
  File "C:\Users\aky\AppData\Local\Programs\Python\Python38\courseu\lib\site-packages\django\template\engine.py", line 175, in get_template
    template, origin = self.find_template(template_name)
  File "C:\Users\aky\AppData\Local\Programs\Python\Python38\courseu\lib\site-packages\django\template\engine.py", line 157, in find_template
    template = loader.get_template(name, skip=skip)
  File "C:\Users\aky\AppData\Local\Programs\Python\Python38\courseu\lib\site-packages\django\template\loaders\cached.py", line 57, in get_template
    template = super().get_template(template_name, skip)
  File "C:\Users\aky\AppData\Local\Programs\Python\Python38\courseu\lib\site-packages\django\template\loaders\base.py", line 28, in get_template
    return Template(
  File "C:\Users\aky\AppData\Local\Programs\Python\Python38\courseu\lib\site-packages\django\template\base.py", line 154, in __init__
    self.nodelist = self.compile_nodelist()
  File "C:\Users\aky\AppData\Local\Programs\Python\Python38\courseu\lib\site-packages\django\template\base.py", line 200, in compile_nodelist
    return parser.parse()
  File "C:\Users\aky\AppData\Local\Programs\Python\Python38\courseu\lib\site-packages\django\template\base.py", line 513, in parse
    raise self.error(token, e)
  File "C:\Users\aky\AppData\Local\Programs\Python\Python38\courseu\lib\site-packages\django\template\base.py", line 511, in parse
    compiled_result = compile_func(self, token)
  File "C:\Users\aky\AppData\Local\Programs\Python\Python38\courseu\lib\site-packages\django\template\loader_tags.py", line 293, in do_extends
    nodelist = parser.parse()
  File "C:\Users\aky\AppData\Local\Programs\Python\Python38\courseu\lib\site-packages\django\template\base.py", line 513, in parse
    raise self.error(token, e)
  File "C:\Users\aky\AppData\Local\Programs\Python\Python38\courseu\lib\site-packages\django\template\base.py", line 511, in parse
    compiled_result = compile_func(self, token)
  File "C:\Users\aky\AppData\Local\Programs\Python\Python38\courseu\lib\site-packages\django\template\loader_tags.py", line 232, in do_block
    nodelist = parser.parse(("endblock",))
  File "C:\Users\aky\AppData\Local\Programs\Python\Python38\courseu\lib\site-packages\django\template\base.py", line 507, in parse
    self.invalid_block_tag(token, command, parse_until)
  File "C:\Users\aky\AppData\Local\Programs\Python\Python38\courseu\lib\site-packages\django\template\base.py", line 558, in invalid_block_tag
    raise self.error(
django.template.exceptions.TemplateSyntaxError: Invalid block tag on line 9: 'static', expected 'endblock'. Did you forget to register or load this tag?
ERROR 2023-12-15 18:48:54,504 django.server Thread-3 1376 basehttp basehttp.py 212 django.server log_message 14832 "GET /admin_students HTTP/1.1" 500 212042
ERROR 2023-12-15 19:11:24,127 django.request Thread-4 1916 log log.py 241 django.request log_response 6156 Internal Server Error: /admin_home/
Traceback (most recent call last):
  File "C:\Users\aky\AppData\Local\Programs\Python\Python38\courseu\lib\site-packages\django\core\handlers\exception.py", line 55, in inner
    response = get_response(request)
  File "C:\Users\aky\AppData\Local\Programs\Python\Python38\courseu\lib\site-packages\django\core\handlers\base.py", line 197, in _get_response
    response = wrapped_callback(request, *callback_args, **callback_kwargs)
  File "C:\Users\aky\AppData\Local\Programs\Python\Python38\eng_ver\apps\website\views.py", line 183, in admin_home
    return render(request, 'dashboard/admin_home.html', {
  File "C:\Users\aky\AppData\Local\Programs\Python\Python38\courseu\lib\site-packages\django\shortcuts.py", line 24, in render
    content = loader.render_to_string(template_name, context, request, using=using)
  File "C:\Users\aky\AppData\Local\Programs\Python\Python38\courseu\lib\site-packages\django\template\loader.py", line 62, in render_to_string
    return template.render(context, request)
  File "C:\Users\aky\AppData\Local\Programs\Python\Python38\courseu\lib\site-packages\django\template\backends\django.py", line 61, in render
    return self.template.render(context)
  File "C:\Users\aky\AppData\Local\Programs\Python\Python38\courseu\lib\site-packages\django\template\base.py", line 175, in render
    return self._render(context)
  File "C:\Users\aky\AppData\Local\Programs\Python\Python38\courseu\lib\site-packages\django\test\utils.py", line 112, in instrumented_test_render
    return self.nodelist.render(context)
  File "C:\Users\aky\AppData\Local\Programs\Python\Python38\courseu\lib\site-packages\django\template\base.py", line 1005, in render
    return SafeString("".join([node.render_annotated(context) for node in self]))
  File "C:\Users\aky\AppData\Local\Programs\Python\Python38\courseu\lib\site-packages\django\template\base.py", line 1005, in <listcomp>
    return SafeString("".join([node.render_annotated(context) for node in self]))
  File "C:\Users\aky\AppData\Local\Programs\Python\Python38\courseu\lib\site-packages\django\template\base.py", line 966, in render_annotated
    return self.render(context)
  File "C:\Users\aky\AppData\Local\Programs\Python\Python38\courseu\lib\site-packages\django\template\loader_tags.py", line 157, in render
    return compiled_parent._render(context)
  File "C:\Users\aky\AppData\Local\Programs\Python\Python38\courseu\lib\site-packages\django\test\utils.py", line 112, in instrumented_test_render
    return self.nodelist.render(context)
  File "C:\Users\aky\AppData\Local\Programs\Python\Python38\courseu\lib\site-packages\django\template\base.py", line 1005, in render
    return SafeString("".join([node.render_annotated(context) for node in self]))
  File "C:\Users\aky\AppData\Local\Programs\Python\Python38\courseu\lib\site-packages\django\template\base.py", line 1005, in <listcomp>
    return SafeString("".join([node.render_annotated(context) for node in self]))
  File "C:\Users\aky\AppData\Local\Programs\Python\Python38\courseu\lib\site-packages\django\template\base.py", line 966, in render_annotated
    return self.render(context)
  File "C:\Users\aky\AppData\Local\Programs\Python\Python38\courseu\lib\site-packages\django\template\defaulttags.py", line 321, in render
    return nodelist.render(context)
  File "C:\Users\aky\AppData\Local\Programs\Python\Python38\courseu\lib\site-packages\django\template\base.py", line 1005, in render
    return SafeString("".join([node.render_annotated(context) for node in self]))
  File "C:\Users\aky\AppData\Local\Programs\Python\Python38\courseu\lib\site-packages\django\template\base.py", line 1005, in <listcomp>
    return SafeString("".join([node.render_annotated(context) for node in self]))
  File "C:\Users\aky\AppData\Local\Programs\Python\Python38\courseu\lib\site-packages\django\template\base.py", line 966, in render_annotated
    return self.render(context)
  File "C:\Users\aky\AppData\Local\Programs\Python\Python38\courseu\lib\site-packages\django\template\loader_tags.py", line 63, in render
    result = block.nodelist.render(context)
  File "C:\Users\aky\AppData\Local\Programs\Python\Python38\courseu\lib\site-packages\django\template\base.py", line 1005, in render
    return SafeString("".join([node.render_annotated(context) for node in self]))
  File "C:\Users\aky\AppData\Local\Programs\Python\Python38\courseu\lib\site-packages\django\template\base.py", line 1005, in <listcomp>
    return SafeString("".join([node.render_annotated(context) for node in self]))
  File "C:\Users\aky\AppData\Local\Programs\Python\Python38\courseu\lib\site-packages\django\template\base.py", line 966, in render_annotated
    return self.render(context)
  File "C:\Users\aky\AppData\Local\Programs\Python\Python38\courseu\lib\site-packages\django\template\defaulttags.py", line 321, in render
    return nodelist.render(context)
  File "C:\Users\aky\AppData\Local\Programs\Python\Python38\courseu\lib\site-packages\django\template\base.py", line 1005, in render
    return SafeString("".join([node.render_annotated(context) for node in self]))
  File "C:\Users\aky\AppData\Local\Programs\Python\Python38\courseu\lib\site-packages\django\template\base.py", line 1005, in <listcomp>
    return SafeString("".join([node.render_annotated(context) for node in self]))
  File "C:\Users\aky\AppData\Local\Programs\Python\Python38\courseu\lib\site-packages\django\template\base.py", line 966, in render_annotated
    return self.render(context)
  File "C:\Users\aky\AppData\Local\Programs\Python\Python38\courseu\lib\site-packages\django\template\defaulttags.py", line 471, in render
    url = reverse(view_name, args=args, kwargs=kwargs, current_app=current_app)
  File "C:\Users\aky\AppData\Local\Programs\Python\Python38\courseu\lib\site-packages\django\urls\base.py", line 88, in reverse
    return resolver._reverse_with_prefix(view, prefix, *args, **kwargs)
  File "C:\Users\aky\AppData\Local\Programs\Python\Python38\courseu\lib\site-packages\django\urls\resolvers.py", line 828, in _reverse_with_prefix
    raise NoReverseMatch(msg)
django.urls.exceptions.NoReverseMatch: Reverse for 'admin_dhome' not found. 'admin_dhome' is not a valid view function or pattern name.
ERROR 2023-12-15 19:11:24,269 django.server Thread-4 1916 basehttp basehttp.py 212 django.server log_message 6156 "GET /admin_home/ HTTP/1.1" 500 244595
ERROR 2023-12-15 20:53:41,640 django.request Thread-1 8772 log log.py 241 django.request log_response 3848 Internal Server Error: /admin_students
Traceback (most recent call last):
  File "C:\Users\aky\AppData\Local\Programs\Python\Python38\courseu\lib\site-packages\django\core\handlers\exception.py", line 55, in inner
    response = get_response(request)
  File "C:\Users\aky\AppData\Local\Programs\Python\Python38\courseu\lib\site-packages\django\core\handlers\base.py", line 197, in _get_response
    response = wrapped_callback(request, *callback_args, **callback_kwargs)
  File "C:\Users\aky\AppData\Local\Programs\Python\Python38\eng_ver\apps\website\views.py", line 208, in admin_students
    field_names = [field.name for field in students._meta.get_fields()]
AttributeError: 'RawQuerySet' object has no attribute '_meta'
ERROR 2023-12-15 20:53:41,885 django.server Thread-1 8772 basehttp basehttp.py 212 django.server log_message 3848 "GET /admin_students HTTP/1.1" 500 94222
ERROR 2023-12-15 21:03:03,354 django.request Thread-1 8732 log log.py 241 django.request log_response 13260 Internal Server Error: /admin_students
Traceback (most recent call last):
  File "C:\Users\aky\AppData\Local\Programs\Python\Python38\courseu\lib\site-packages\django\db\backends\utils.py", line 89, in _execute
    return self.cursor.execute(sql, params)
  File "C:\Users\aky\AppData\Local\Programs\Python\Python38\courseu\lib\site-packages\django\db\backends\mysql\base.py", line 75, in execute
    return self.cursor.execute(query, args)
  File "C:\Users\aky\AppData\Local\Programs\Python\Python38\courseu\lib\site-packages\MySQLdb\cursors.py", line 179, in execute
    res = self._query(mogrified_query)
  File "C:\Users\aky\AppData\Local\Programs\Python\Python38\courseu\lib\site-packages\MySQLdb\cursors.py", line 330, in _query
    db.query(q)
  File "C:\Users\aky\AppData\Local\Programs\Python\Python38\courseu\lib\site-packages\MySQLdb\connections.py", line 255, in query
    _mysql.connection.query(self, query)
MySQLdb.ProgrammingError: (1146, "Table 'courseu_db.course' doesn't exist")

The above exception was the direct cause of the following exception:

Traceback (most recent call last):
  File "C:\Users\aky\AppData\Local\Programs\Python\Python38\courseu\lib\site-packages\django\core\handlers\exception.py", line 55, in inner
    response = get_response(request)
  File "C:\Users\aky\AppData\Local\Programs\Python\Python38\courseu\lib\site-packages\django\core\handlers\base.py", line 197, in _get_response
    response = wrapped_callback(request, *callback_args, **callback_kwargs)
  File "C:\Users\aky\AppData\Local\Programs\Python\Python38\eng_ver\apps\website\views.py", line 215, in admin_students
    return render(request, 'dashboard/admin_students.html', {
  File "C:\Users\aky\AppData\Local\Programs\Python\Python38\courseu\lib\site-packages\django\shortcuts.py", line 24, in render
    content = loader.render_to_string(template_name, context, request, using=using)
  File "C:\Users\aky\AppData\Local\Programs\Python\Python38\courseu\lib\site-packages\django\template\loader.py", line 62, in render_to_string
    return template.render(context, request)
  File "C:\Users\aky\AppData\Local\Programs\Python\Python38\courseu\lib\site-packages\django\template\backends\django.py", line 61, in render
    return self.template.render(context)
  File "C:\Users\aky\AppData\Local\Programs\Python\Python38\courseu\lib\site-packages\django\template\base.py", line 175, in render
    return self._render(context)
  File "C:\Users\aky\AppData\Local\Programs\Python\Python38\courseu\lib\site-packages\django\test\utils.py", line 112, in instrumented_test_render
    return self.nodelist.render(context)
  File "C:\Users\aky\AppData\Local\Programs\Python\Python38\courseu\lib\site-packages\django\template\base.py", line 1005, in render
    return SafeString("".join([node.render_annotated(context) for node in self]))
  File "C:\Users\aky\AppData\Local\Programs\Python\Python38\courseu\lib\site-packages\django\template\base.py", line 1005, in <listcomp>
    return SafeString("".join([node.render_annotated(context) for node in self]))
  File "C:\Users\aky\AppData\Local\Programs\Python\Python38\courseu\lib\site-packages\django\template\base.py", line 966, in render_annotated
    return self.render(context)
  File "C:\Users\aky\AppData\Local\Programs\Python\Python38\courseu\lib\site-packages\django\template\loader_tags.py", line 157, in render
    return compiled_parent._render(context)
  File "C:\Users\aky\AppData\Local\Programs\Python\Python38\courseu\lib\site-packages\django\test\utils.py", line 112, in instrumented_test_render
    return self.nodelist.render(context)
  File "C:\Users\aky\AppData\Local\Programs\Python\Python38\courseu\lib\site-packages\django\template\base.py", line 1005, in render
    return SafeString("".join([node.render_annotated(context) for node in self]))
  File "C:\Users\aky\AppData\Local\Programs\Python\Python38\courseu\lib\site-packages\django\template\base.py", line 1005, in <listcomp>
    return SafeString("".join([node.render_annotated(context) for node in self]))
  File "C:\Users\aky\AppData\Local\Programs\Python\Python38\courseu\lib\site-packages\django\template\base.py", line 966, in render_annotated
    return self.render(context)
  File "C:\Users\aky\AppData\Local\Programs\Python\Python38\courseu\lib\site-packages\django\template\defaulttags.py", line 321, in render
    return nodelist.render(context)
  File "C:\Users\aky\AppData\Local\Programs\Python\Python38\courseu\lib\site-packages\django\template\base.py", line 1005, in render
    return SafeString("".join([node.render_annotated(context) for node in self]))
  File "C:\Users\aky\AppData\Local\Programs\Python\Python38\courseu\lib\site-packages\django\template\base.py", line 1005, in <listcomp>
    return SafeString("".join([node.render_annotated(context) for node in self]))
  File "C:\Users\aky\AppData\Local\Programs\Python\Python38\courseu\lib\site-packages\django\template\base.py", line 966, in render_annotated
    return self.render(context)
  File "C:\Users\aky\AppData\Local\Programs\Python\Python38\courseu\lib\site-packages\django\template\loader_tags.py", line 63, in render
    result = block.nodelist.render(context)
  File "C:\Users\aky\AppData\Local\Programs\Python\Python38\courseu\lib\site-packages\django\template\base.py", line 1005, in render
    return SafeString("".join([node.render_annotated(context) for node in self]))
  File "C:\Users\aky\AppData\Local\Programs\Python\Python38\courseu\lib\site-packages\django\template\base.py", line 1005, in <listcomp>
    return SafeString("".join([node.render_annotated(context) for node in self]))
  File "C:\Users\aky\AppData\Local\Programs\Python\Python38\courseu\lib\site-packages\django\template\base.py", line 966, in render_annotated
    return self.render(context)
  File "C:\Users\aky\AppData\Local\Programs\Python\Python38\courseu\lib\site-packages\django\template\defaulttags.py", line 321, in render
    return nodelist.render(context)
  File "C:\Users\aky\AppData\Local\Programs\Python\Python38\courseu\lib\site-packages\django\template\base.py", line 1005, in render
    return SafeString("".join([node.render_annotated(context) for node in self]))
  File "C:\Users\aky\AppData\Local\Programs\Python\Python38\courseu\lib\site-packages\django\template\base.py", line 1005, in <listcomp>
    return SafeString("".join([node.render_annotated(context) for node in self]))
  File "C:\Users\aky\AppData\Local\Programs\Python\Python38\courseu\lib\site-packages\django\template\base.py", line 966, in render_annotated
    return self.render(context)
  File "C:\Users\aky\AppData\Local\Programs\Python\Python38\courseu\lib\site-packages\django\template\defaulttags.py", line 194, in render
    len_values = len(values)
  File "C:\Users\aky\AppData\Local\Programs\Python\Python38\courseu\lib\site-packages\django\db\models\query.py", line 2072, in __len__
    self._fetch_all()
  File "C:\Users\aky\AppData\Local\Programs\Python\Python38\courseu\lib\site-packages\django\db\models\query.py", line 2067, in _fetch_all
    self._result_cache = list(self.iterator())
  File "C:\Users\aky\AppData\Local\Programs\Python\Python38\courseu\lib\site-packages\django\db\models\query.py", line 2094, in iterator
    yield from RawModelIterable(self)
  File "C:\Users\aky\AppData\Local\Programs\Python\Python38\courseu\lib\site-packages\django\db\models\query.py", line 158, in __iter__
    query_iterator = iter(query)
  File "C:\Users\aky\AppData\Local\Programs\Python\Python38\courseu\lib\site-packages\django\db\models\sql\query.py", line 112, in __iter__
    self._execute_query()
  File "C:\Users\aky\AppData\Local\Programs\Python\Python38\courseu\lib\site-packages\django\db\models\sql\query.py", line 152, in _execute_query
    self.cursor.execute(self.sql, params)
  File "C:\Users\aky\AppData\Local\Programs\Python\Python38\courseu\lib\site-packages\debug_toolbar\panels\sql\tracking.py", line 252, in execute
    return self._record(super().execute, sql, params)
  File "C:\Users\aky\AppData\Local\Programs\Python\Python38\courseu\lib\site-packages\debug_toolbar\panels\sql\tracking.py", line 177, in _record
    return method(sql, params)
  File "C:\Users\aky\AppData\Local\Programs\Python\Python38\courseu\lib\site-packages\django\db\backends\utils.py", line 102, in execute
    return super().execute(sql, params)
  File "C:\Users\aky\AppData\Local\Programs\Python\Python38\courseu\lib\site-packages\django\db\backends\utils.py", line 67, in execute
    return self._execute_with_wrappers(
  File "C:\Users\aky\AppData\Local\Programs\Python\Python38\courseu\lib\site-packages\django\db\backends\utils.py", line 80, in _execute_with_wrappers
    return executor(sql, params, many, context)
  File "C:\Users\aky\AppData\Local\Programs\Python\Python38\courseu\lib\site-packages\django\db\backends\utils.py", line 89, in _execute
    return self.cursor.execute(sql, params)
  File "C:\Users\aky\AppData\Local\Programs\Python\Python38\courseu\lib\site-packages\django\db\utils.py", line 91, in __exit__
    raise dj_exc_value.with_traceback(traceback) from exc_value
  File "C:\Users\aky\AppData\Local\Programs\Python\Python38\courseu\lib\site-packages\django\db\backends\utils.py", line 89, in _execute
    return self.cursor.execute(sql, params)
  File "C:\Users\aky\AppData\Local\Programs\Python\Python38\courseu\lib\site-packages\django\db\backends\mysql\base.py", line 75, in execute
    return self.cursor.execute(query, args)
  File "C:\Users\aky\AppData\Local\Programs\Python\Python38\courseu\lib\site-packages\MySQLdb\cursors.py", line 179, in execute
    res = self._query(mogrified_query)
  File "C:\Users\aky\AppData\Local\Programs\Python\Python38\courseu\lib\site-packages\MySQLdb\cursors.py", line 330, in _query
    db.query(q)
  File "C:\Users\aky\AppData\Local\Programs\Python\Python38\courseu\lib\site-packages\MySQLdb\connections.py", line 255, in query
    _mysql.connection.query(self, query)
django.db.utils.ProgrammingError: (1146, "Table 'courseu_db.course' doesn't exist")
ERROR 2023-12-15 21:03:03,544 django.server Thread-1 8732 basehttp basehttp.py 212 django.server log_message 13260 "GET /admin_students HTTP/1.1" 500 335491
ERROR 2023-12-15 21:13:06,483 django.request Thread-1 16284 log log.py 241 django.request log_response 6012 Internal Server Error: /admin_test
Traceback (most recent call last):
  File "C:\Users\aky\AppData\Local\Programs\Python\Python38\courseu\lib\site-packages\django\db\backends\utils.py", line 89, in _execute
    return self.cursor.execute(sql, params)
  File "C:\Users\aky\AppData\Local\Programs\Python\Python38\courseu\lib\site-packages\django\db\backends\mysql\base.py", line 75, in execute
    return self.cursor.execute(query, args)
  File "C:\Users\aky\AppData\Local\Programs\Python\Python38\courseu\lib\site-packages\MySQLdb\cursors.py", line 179, in execute
    res = self._query(mogrified_query)
  File "C:\Users\aky\AppData\Local\Programs\Python\Python38\courseu\lib\site-packages\MySQLdb\cursors.py", line 330, in _query
    db.query(q)
  File "C:\Users\aky\AppData\Local\Programs\Python\Python38\courseu\lib\site-packages\MySQLdb\connections.py", line 255, in query
    _mysql.connection.query(self, query)
MySQLdb.OperationalError: (1054, "Unknown column 'assessment_test.test_name' in 'field list'")

The above exception was the direct cause of the following exception:

Traceback (most recent call last):
  File "C:\Users\aky\AppData\Local\Programs\Python\Python38\courseu\lib\site-packages\django\core\handlers\exception.py", line 55, in inner
    response = get_response(request)
  File "C:\Users\aky\AppData\Local\Programs\Python\Python38\courseu\lib\site-packages\django\core\handlers\base.py", line 197, in _get_response
    response = wrapped_callback(request, *callback_args, **callback_kwargs)
  File "C:\Users\aky\AppData\Local\Programs\Python\Python38\eng_ver\apps\website\views.py", line 233, in admin_test
    print("questionset: ", questionset[0].__dict__)
  File "C:\Users\aky\AppData\Local\Programs\Python\Python38\courseu\lib\site-packages\django\db\models\query.py", line 2100, in __getitem__
    return list(self)[k]
  File "C:\Users\aky\AppData\Local\Programs\Python\Python38\courseu\lib\site-packages\django\db\models\query.py", line 2072, in __len__
    self._fetch_all()
  File "C:\Users\aky\AppData\Local\Programs\Python\Python38\courseu\lib\site-packages\django\db\models\query.py", line 2067, in _fetch_all
    self._result_cache = list(self.iterator())
  File "C:\Users\aky\AppData\Local\Programs\Python\Python38\courseu\lib\site-packages\django\db\models\query.py", line 2094, in iterator
    yield from RawModelIterable(self)
  File "C:\Users\aky\AppData\Local\Programs\Python\Python38\courseu\lib\site-packages\django\db\models\query.py", line 158, in __iter__
    query_iterator = iter(query)
  File "C:\Users\aky\AppData\Local\Programs\Python\Python38\courseu\lib\site-packages\django\db\models\sql\query.py", line 112, in __iter__
    self._execute_query()
  File "C:\Users\aky\AppData\Local\Programs\Python\Python38\courseu\lib\site-packages\django\db\models\sql\query.py", line 152, in _execute_query
    self.cursor.execute(self.sql, params)
  File "C:\Users\aky\AppData\Local\Programs\Python\Python38\courseu\lib\site-packages\debug_toolbar\panels\sql\tracking.py", line 252, in execute
    return self._record(super().execute, sql, params)
  File "C:\Users\aky\AppData\Local\Programs\Python\Python38\courseu\lib\site-packages\debug_toolbar\panels\sql\tracking.py", line 177, in _record
    return method(sql, params)
  File "C:\Users\aky\AppData\Local\Programs\Python\Python38\courseu\lib\site-packages\django\db\backends\utils.py", line 102, in execute
    return super().execute(sql, params)
  File "C:\Users\aky\AppData\Local\Programs\Python\Python38\courseu\lib\site-packages\django\db\backends\utils.py", line 67, in execute
    return self._execute_with_wrappers(
  File "C:\Users\aky\AppData\Local\Programs\Python\Python38\courseu\lib\site-packages\django\db\backends\utils.py", line 80, in _execute_with_wrappers
    return executor(sql, params, many, context)
  File "C:\Users\aky\AppData\Local\Programs\Python\Python38\courseu\lib\site-packages\django\db\backends\utils.py", line 89, in _execute
    return self.cursor.execute(sql, params)
  File "C:\Users\aky\AppData\Local\Programs\Python\Python38\courseu\lib\site-packages\django\db\utils.py", line 91, in __exit__
    raise dj_exc_value.with_traceback(traceback) from exc_value
  File "C:\Users\aky\AppData\Local\Programs\Python\Python38\courseu\lib\site-packages\django\db\backends\utils.py", line 89, in _execute
    return self.cursor.execute(sql, params)
  File "C:\Users\aky\AppData\Local\Programs\Python\Python38\courseu\lib\site-packages\django\db\backends\mysql\base.py", line 75, in execute
    return self.cursor.execute(query, args)
  File "C:\Users\aky\AppData\Local\Programs\Python\Python38\courseu\lib\site-packages\MySQLdb\cursors.py", line 179, in execute
    res = self._query(mogrified_query)
  File "C:\Users\aky\AppData\Local\Programs\Python\Python38\courseu\lib\site-packages\MySQLdb\cursors.py", line 330, in _query
    db.query(q)
  File "C:\Users\aky\AppData\Local\Programs\Python\Python38\courseu\lib\site-packages\MySQLdb\connections.py", line 255, in query
    _mysql.connection.query(self, query)
django.db.utils.OperationalError: (1054, "Unknown column 'assessment_test.test_name' in 'field list'")
ERROR 2023-12-15 21:13:06,783 django.server Thread-1 16284 basehttp basehttp.py 212 django.server log_message 6012 "GET /admin_test HTTP/1.1" 500 205793
ERROR 2023-12-15 21:14:14,612 django.request Thread-1 7932 log log.py 241 django.request log_response 13728 Internal Server Error: /admin_test
Traceback (most recent call last):
  File "C:\Users\aky\AppData\Local\Programs\Python\Python38\courseu\lib\site-packages\django\db\backends\utils.py", line 89, in _execute
    return self.cursor.execute(sql, params)
  File "C:\Users\aky\AppData\Local\Programs\Python\Python38\courseu\lib\site-packages\django\db\backends\mysql\base.py", line 75, in execute
    return self.cursor.execute(query, args)
  File "C:\Users\aky\AppData\Local\Programs\Python\Python38\courseu\lib\site-packages\MySQLdb\cursors.py", line 179, in execute
    res = self._query(mogrified_query)
  File "C:\Users\aky\AppData\Local\Programs\Python\Python38\courseu\lib\site-packages\MySQLdb\cursors.py", line 330, in _query
    db.query(q)
  File "C:\Users\aky\AppData\Local\Programs\Python\Python38\courseu\lib\site-packages\MySQLdb\connections.py", line 255, in query
    _mysql.connection.query(self, query)
MySQLdb.ProgrammingError: (1064, "You have an error in your SQL syntax; check the manual that corresponds to your MySQL server version for the right syntax to use near 'FROM auth_user\n    INNER JOIN assessment_questionset ON auth_user.id = assessmen' at line 2")

The above exception was the direct cause of the following exception:

Traceback (most recent call last):
  File "C:\Users\aky\AppData\Local\Programs\Python\Python38\courseu\lib\site-packages\django\core\handlers\exception.py", line 55, in inner
    response = get_response(request)
  File "C:\Users\aky\AppData\Local\Programs\Python\Python38\courseu\lib\site-packages\django\core\handlers\base.py", line 197, in _get_response
    response = wrapped_callback(request, *callback_args, **callback_kwargs)
  File "C:\Users\aky\AppData\Local\Programs\Python\Python38\eng_ver\apps\website\views.py", line 232, in admin_test
    print("questionset: ", questionset[0].__dict__)
  File "C:\Users\aky\AppData\Local\Programs\Python\Python38\courseu\lib\site-packages\django\db\models\query.py", line 2100, in __getitem__
    return list(self)[k]
  File "C:\Users\aky\AppData\Local\Programs\Python\Python38\courseu\lib\site-packages\django\db\models\query.py", line 2072, in __len__
    self._fetch_all()
  File "C:\Users\aky\AppData\Local\Programs\Python\Python38\courseu\lib\site-packages\django\db\models\query.py", line 2067, in _fetch_all
    self._result_cache = list(self.iterator())
  File "C:\Users\aky\AppData\Local\Programs\Python\Python38\courseu\lib\site-packages\django\db\models\query.py", line 2094, in iterator
    yield from RawModelIterable(self)
  File "C:\Users\aky\AppData\Local\Programs\Python\Python38\courseu\lib\site-packages\django\db\models\query.py", line 158, in __iter__
    query_iterator = iter(query)
  File "C:\Users\aky\AppData\Local\Programs\Python\Python38\courseu\lib\site-packages\django\db\models\sql\query.py", line 112, in __iter__
    self._execute_query()
  File "C:\Users\aky\AppData\Local\Programs\Python\Python38\courseu\lib\site-packages\django\db\models\sql\query.py", line 152, in _execute_query
    self.cursor.execute(self.sql, params)
  File "C:\Users\aky\AppData\Local\Programs\Python\Python38\courseu\lib\site-packages\debug_toolbar\panels\sql\tracking.py", line 252, in execute
    return self._record(super().execute, sql, params)
  File "C:\Users\aky\AppData\Local\Programs\Python\Python38\courseu\lib\site-packages\debug_toolbar\panels\sql\tracking.py", line 177, in _record
    return method(sql, params)
  File "C:\Users\aky\AppData\Local\Programs\Python\Python38\courseu\lib\site-packages\django\db\backends\utils.py", line 102, in execute
    return super().execute(sql, params)
  File "C:\Users\aky\AppData\Local\Programs\Python\Python38\courseu\lib\site-packages\django\db\backends\utils.py", line 67, in execute
    return self._execute_with_wrappers(
  File "C:\Users\aky\AppData\Local\Programs\Python\Python38\courseu\lib\site-packages\django\db\backends\utils.py", line 80, in _execute_with_wrappers
    return executor(sql, params, many, context)
  File "C:\Users\aky\AppData\Local\Programs\Python\Python38\courseu\lib\site-packages\django\db\backends\utils.py", line 89, in _execute
    return self.cursor.execute(sql, params)
  File "C:\Users\aky\AppData\Local\Programs\Python\Python38\courseu\lib\site-packages\django\db\utils.py", line 91, in __exit__
    raise dj_exc_value.with_traceback(traceback) from exc_value
  File "C:\Users\aky\AppData\Local\Programs\Python\Python38\courseu\lib\site-packages\django\db\backends\utils.py", line 89, in _execute
    return self.cursor.execute(sql, params)
  File "C:\Users\aky\AppData\Local\Programs\Python\Python38\courseu\lib\site-packages\django\db\backends\mysql\base.py", line 75, in execute
    return self.cursor.execute(query, args)
  File "C:\Users\aky\AppData\Local\Programs\Python\Python38\courseu\lib\site-packages\MySQLdb\cursors.py", line 179, in execute
    res = self._query(mogrified_query)
  File "C:\Users\aky\AppData\Local\Programs\Python\Python38\courseu\lib\site-packages\MySQLdb\cursors.py", line 330, in _query
    db.query(q)
  File "C:\Users\aky\AppData\Local\Programs\Python\Python38\courseu\lib\site-packages\MySQLdb\connections.py", line 255, in query
    _mysql.connection.query(self, query)
django.db.utils.ProgrammingError: (1064, "You have an error in your SQL syntax; check the manual that corresponds to your MySQL server version for the right syntax to use near 'FROM auth_user\n    INNER JOIN assessment_questionset ON auth_user.id = assessmen' at line 2")
ERROR 2023-12-15 21:14:15,084 django.server Thread-1 7932 basehttp basehttp.py 212 django.server log_message 13728 "GET /admin_test HTTP/1.1" 500 202965
ERROR 2023-12-15 21:49:53,833 django.request Thread-1 13552 log log.py 241 django.request log_response 10800 Internal Server Error: /admin_jobpostings
Traceback (most recent call last):
  File "C:\Users\aky\AppData\Local\Programs\Python\Python38\courseu\lib\site-packages\django\core\handlers\exception.py", line 55, in inner
    response = get_response(request)
  File "C:\Users\aky\AppData\Local\Programs\Python\Python38\courseu\lib\site-packages\django\core\handlers\base.py", line 197, in _get_response
    response = wrapped_callback(request, *callback_args, **callback_kwargs)
  File "C:\Users\aky\AppData\Local\Programs\Python\Python38\eng_ver\apps\website\views.py", line 256, in admin_jobpostings
    return render(request, 'dashboard/admin_jobopstings.html', {
  File "C:\Users\aky\AppData\Local\Programs\Python\Python38\courseu\lib\site-packages\django\shortcuts.py", line 24, in render
    content = loader.render_to_string(template_name, context, request, using=using)
  File "C:\Users\aky\AppData\Local\Programs\Python\Python38\courseu\lib\site-packages\django\template\loader.py", line 61, in render_to_string
    template = get_template(template_name, using=using)
  File "C:\Users\aky\AppData\Local\Programs\Python\Python38\courseu\lib\site-packages\django\template\loader.py", line 19, in get_template
    raise TemplateDoesNotExist(template_name, chain=chain)
django.template.exceptions.TemplateDoesNotExist: dashboard/admin_jobopstings.html
ERROR 2023-12-15 21:49:54,101 django.server Thread-1 13552 basehttp basehttp.py 212 django.server log_message 10800 "GET /admin_jobpostings HTTP/1.1" 500 112957
ERROR 2023-12-15 23:35:34,800 django.request Thread-2 13756 log log.py 241 django.request log_response 12048 Internal Server Error: /recommender/
Traceback (most recent call last):
  File "C:\Users\aky\AppData\Local\Programs\Python\Python38\courseu\lib\site-packages\pandas\core\indexes\base.py", line 3653, in get_loc
    return self._engine.get_loc(casted_key)
  File "pandas\_libs\index.pyx", line 147, in pandas._libs.index.IndexEngine.get_loc
  File "pandas\_libs\index.pyx", line 176, in pandas._libs.index.IndexEngine.get_loc
  File "pandas\_libs\hashtable_class_helper.pxi", line 7080, in pandas._libs.hashtable.PyObjectHashTable.get_item
  File "pandas\_libs\hashtable_class_helper.pxi", line 7088, in pandas._libs.hashtable.PyObjectHashTable.get_item
KeyError: 'adaptability in development'

The above exception was the direct cause of the following exception:

Traceback (most recent call last):
  File "C:\Users\aky\AppData\Local\Programs\Python\Python38\courseu\lib\site-packages\django\core\handlers\exception.py", line 55, in inner
    response = get_response(request)
  File "C:\Users\aky\AppData\Local\Programs\Python\Python38\courseu\lib\site-packages\django\core\handlers\base.py", line 197, in _get_response
    response = wrapped_callback(request, *callback_args, **callback_kwargs)
  File "C:\Users\aky\AppData\Local\Programs\Python\Python38\eng_ver\apps\recommender\views.py", line 203, in recommender
    field_data.append(pivot_df[field].tolist())
  File "C:\Users\aky\AppData\Local\Programs\Python\Python38\courseu\lib\site-packages\pandas\core\frame.py", line 3761, in __getitem__
    indexer = self.columns.get_loc(key)
  File "C:\Users\aky\AppData\Local\Programs\Python\Python38\courseu\lib\site-packages\pandas\core\indexes\base.py", line 3655, in get_loc
    raise KeyError(key) from err
KeyError: 'adaptability in development'
ERROR 2023-12-15 23:35:36,051 django.server Thread-2 13756 basehttp basehttp.py 212 django.server log_message 12048 "GET /recommender/ HTTP/1.1" 500 226321
ERROR 2023-12-15 23:35:45,348 django.request Thread-4 16468 log log.py 241 django.request log_response 12048 Internal Server Error: /recommender/
Traceback (most recent call last):
  File "C:\Users\aky\AppData\Local\Programs\Python\Python38\courseu\lib\site-packages\pandas\core\indexes\base.py", line 3653, in get_loc
    return self._engine.get_loc(casted_key)
  File "pandas\_libs\index.pyx", line 147, in pandas._libs.index.IndexEngine.get_loc
  File "pandas\_libs\index.pyx", line 176, in pandas._libs.index.IndexEngine.get_loc
  File "pandas\_libs\hashtable_class_helper.pxi", line 7080, in pandas._libs.hashtable.PyObjectHashTable.get_item
  File "pandas\_libs\hashtable_class_helper.pxi", line 7088, in pandas._libs.hashtable.PyObjectHashTable.get_item
KeyError: 'adaptability in development'

The above exception was the direct cause of the following exception:

Traceback (most recent call last):
  File "C:\Users\aky\AppData\Local\Programs\Python\Python38\courseu\lib\site-packages\django\core\handlers\exception.py", line 55, in inner
    response = get_response(request)
  File "C:\Users\aky\AppData\Local\Programs\Python\Python38\courseu\lib\site-packages\django\core\handlers\base.py", line 197, in _get_response
    response = wrapped_callback(request, *callback_args, **callback_kwargs)
  File "C:\Users\aky\AppData\Local\Programs\Python\Python38\eng_ver\apps\recommender\views.py", line 203, in recommender
    field_data.append(pivot_df[field].tolist())
  File "C:\Users\aky\AppData\Local\Programs\Python\Python38\courseu\lib\site-packages\pandas\core\frame.py", line 3761, in __getitem__
    indexer = self.columns.get_loc(key)
  File "C:\Users\aky\AppData\Local\Programs\Python\Python38\courseu\lib\site-packages\pandas\core\indexes\base.py", line 3655, in get_loc
    raise KeyError(key) from err
KeyError: 'adaptability in development'
ERROR 2023-12-15 23:35:46,501 django.server Thread-4 16468 basehttp basehttp.py 212 django.server log_message 12048 "GET /recommender/ HTTP/1.1" 500 226193
ERROR 2023-12-15 23:37:15,534 django.request Thread-1 13968 log log.py 241 django.request log_response 11504 Internal Server Error: /recommender/
Traceback (most recent call last):
  File "C:\Users\aky\AppData\Local\Programs\Python\Python38\courseu\lib\site-packages\pandas\core\indexes\base.py", line 3653, in get_loc
    return self._engine.get_loc(casted_key)
  File "pandas\_libs\index.pyx", line 147, in pandas._libs.index.IndexEngine.get_loc
  File "pandas\_libs\index.pyx", line 176, in pandas._libs.index.IndexEngine.get_loc
  File "pandas\_libs\hashtable_class_helper.pxi", line 7080, in pandas._libs.hashtable.PyObjectHashTable.get_item
  File "pandas\_libs\hashtable_class_helper.pxi", line 7088, in pandas._libs.hashtable.PyObjectHashTable.get_item
KeyError: 63

The above exception was the direct cause of the following exception:

Traceback (most recent call last):
  File "C:\Users\aky\AppData\Local\Programs\Python\Python38\courseu\lib\site-packages\django\core\handlers\exception.py", line 55, in inner
    response = get_response(request)
  File "C:\Users\aky\AppData\Local\Programs\Python\Python38\courseu\lib\site-packages\django\core\handlers\base.py", line 197, in _get_response
    response = wrapped_callback(request, *callback_args, **callback_kwargs)
  File "C:\Users\aky\AppData\Local\Programs\Python\Python38\eng_ver\apps\recommender\views.py", line 203, in recommender
    field_data.append(user_skills_df[field].tolist())
  File "C:\Users\aky\AppData\Local\Programs\Python\Python38\courseu\lib\site-packages\pandas\core\frame.py", line 3761, in __getitem__
    indexer = self.columns.get_loc(key)
  File "C:\Users\aky\AppData\Local\Programs\Python\Python38\courseu\lib\site-packages\pandas\core\indexes\base.py", line 3655, in get_loc
    raise KeyError(key) from err
KeyError: 63
ERROR 2023-12-15 23:37:17,095 django.server Thread-1 13968 basehttp basehttp.py 212 django.server log_message 11504 "GET /recommender/ HTTP/1.1" 500 224491
ERROR 2023-12-15 23:37:22,877 django.request Thread-1 13968 log log.py 241 django.request log_response 11504 Internal Server Error: /recommender/
Traceback (most recent call last):
  File "C:\Users\aky\AppData\Local\Programs\Python\Python38\courseu\lib\site-packages\pandas\core\indexes\base.py", line 3653, in get_loc
    return self._engine.get_loc(casted_key)
  File "pandas\_libs\index.pyx", line 147, in pandas._libs.index.IndexEngine.get_loc
  File "pandas\_libs\index.pyx", line 176, in pandas._libs.index.IndexEngine.get_loc
  File "pandas\_libs\hashtable_class_helper.pxi", line 7080, in pandas._libs.hashtable.PyObjectHashTable.get_item
  File "pandas\_libs\hashtable_class_helper.pxi", line 7088, in pandas._libs.hashtable.PyObjectHashTable.get_item
KeyError: 63

The above exception was the direct cause of the following exception:

Traceback (most recent call last):
  File "C:\Users\aky\AppData\Local\Programs\Python\Python38\courseu\lib\site-packages\django\core\handlers\exception.py", line 55, in inner
    response = get_response(request)
  File "C:\Users\aky\AppData\Local\Programs\Python\Python38\courseu\lib\site-packages\django\core\handlers\base.py", line 197, in _get_response
    response = wrapped_callback(request, *callback_args, **callback_kwargs)
  File "C:\Users\aky\AppData\Local\Programs\Python\Python38\eng_ver\apps\recommender\views.py", line 203, in recommender
    field_data.append(user_skills_df[field].tolist())
  File "C:\Users\aky\AppData\Local\Programs\Python\Python38\courseu\lib\site-packages\pandas\core\frame.py", line 3761, in __getitem__
    indexer = self.columns.get_loc(key)
  File "C:\Users\aky\AppData\Local\Programs\Python\Python38\courseu\lib\site-packages\pandas\core\indexes\base.py", line 3655, in get_loc
    raise KeyError(key) from err
KeyError: 63
ERROR 2023-12-15 23:37:23,768 django.server Thread-1 13968 basehttp basehttp.py 212 django.server log_message 11504 "GET /recommender/ HTTP/1.1" 500 224491
ERROR 2023-12-16 00:52:05,750 django.request Thread-2 364 log log.py 241 django.request log_response 11504 Internal Server Error: /recommender/
Traceback (most recent call last):
  File "C:\Users\aky\AppData\Local\Programs\Python\Python38\courseu\lib\site-packages\pandas\core\indexes\base.py", line 3653, in get_loc
    return self._engine.get_loc(casted_key)
  File "pandas\_libs\index.pyx", line 147, in pandas._libs.index.IndexEngine.get_loc
  File "pandas\_libs\index.pyx", line 176, in pandas._libs.index.IndexEngine.get_loc
  File "pandas\_libs\hashtable_class_helper.pxi", line 7080, in pandas._libs.hashtable.PyObjectHashTable.get_item
  File "pandas\_libs\hashtable_class_helper.pxi", line 7088, in pandas._libs.hashtable.PyObjectHashTable.get_item
KeyError: 63

The above exception was the direct cause of the following exception:

Traceback (most recent call last):
  File "C:\Users\aky\AppData\Local\Programs\Python\Python38\courseu\lib\site-packages\django\core\handlers\exception.py", line 55, in inner
    response = get_response(request)
  File "C:\Users\aky\AppData\Local\Programs\Python\Python38\courseu\lib\site-packages\django\core\handlers\base.py", line 197, in _get_response
    response = wrapped_callback(request, *callback_args, **callback_kwargs)
  File "C:\Users\aky\AppData\Local\Programs\Python\Python38\eng_ver\apps\recommender\views.py", line 203, in recommender
    field_data.append(user_skills_df[field].tolist())
  File "C:\Users\aky\AppData\Local\Programs\Python\Python38\courseu\lib\site-packages\pandas\core\frame.py", line 3761, in __getitem__
    indexer = self.columns.get_loc(key)
  File "C:\Users\aky\AppData\Local\Programs\Python\Python38\courseu\lib\site-packages\pandas\core\indexes\base.py", line 3655, in get_loc
    raise KeyError(key) from err
KeyError: 63
ERROR 2023-12-16 00:52:07,131 django.server Thread-2 364 basehttp basehttp.py 212 django.server log_message 11504 "GET /recommender/ HTTP/1.1" 500 224491
ERROR 2023-12-16 00:54:01,123 django.request Thread-1 6976 log log.py 241 django.request log_response 9308 Internal Server Error: /recommender/
Traceback (most recent call last):
  File "C:\Users\aky\AppData\Local\Programs\Python\Python38\courseu\lib\site-packages\django\core\handlers\exception.py", line 55, in inner
    response = get_response(request)
  File "C:\Users\aky\AppData\Local\Programs\Python\Python38\courseu\lib\site-packages\django\core\handlers\base.py", line 197, in _get_response
    response = wrapped_callback(request, *callback_args, **callback_kwargs)
  File "C:\Users\aky\AppData\Local\Programs\Python\Python38\eng_ver\apps\recommender\views.py", line 206, in recommender
    fig = px.bar(
  File "C:\Users\aky\AppData\Local\Programs\Python\Python38\courseu\lib\site-packages\plotly\express\_chart_types.py", line 373, in bar
    return make_figure(
  File "C:\Users\aky\AppData\Local\Programs\Python\Python38\courseu\lib\site-packages\plotly\express\_core.py", line 2076, in make_figure
    args = build_dataframe(args, constructor)
  File "C:\Users\aky\AppData\Local\Programs\Python\Python38\courseu\lib\site-packages\plotly\express\_core.py", line 1485, in build_dataframe
    df_output, wide_id_vars = process_args_into_dataframe(
  File "C:\Users\aky\AppData\Local\Programs\Python\Python38\courseu\lib\site-packages\plotly\express\_core.py", line 1250, in process_args_into_dataframe
    raise ValueError(
ValueError: All arguments should have the same length. The length of argument `wide_variable_0` is 4, whereas the length of  previously-processed arguments ['y'] is 101
ERROR 2023-12-16 00:54:02,129 django.server Thread-1 6976 basehttp basehttp.py 212 django.server log_message 9308 "GET /recommender/ HTTP/1.1" 500 203344
ERROR 2023-12-16 00:57:08,434 django.request Thread-1 4240 log log.py 241 django.request log_response 16644 Internal Server Error: /recommender/
Traceback (most recent call last):
  File "C:\Users\aky\AppData\Local\Programs\Python\Python38\courseu\lib\site-packages\django\core\handlers\exception.py", line 55, in inner
    response = get_response(request)
  File "C:\Users\aky\AppData\Local\Programs\Python\Python38\courseu\lib\site-packages\django\core\handlers\base.py", line 197, in _get_response
    response = wrapped_callback(request, *callback_args, **callback_kwargs)
  File "C:\Users\aky\AppData\Local\Programs\Python\Python38\eng_ver\apps\recommender\views.py", line 206, in recommender
    fig = px.bar(
  File "C:\Users\aky\AppData\Local\Programs\Python\Python38\courseu\lib\site-packages\plotly\express\_chart_types.py", line 373, in bar
    return make_figure(
  File "C:\Users\aky\AppData\Local\Programs\Python\Python38\courseu\lib\site-packages\plotly\express\_core.py", line 2076, in make_figure
    args = build_dataframe(args, constructor)
  File "C:\Users\aky\AppData\Local\Programs\Python\Python38\courseu\lib\site-packages\plotly\express\_core.py", line 1485, in build_dataframe
    df_output, wide_id_vars = process_args_into_dataframe(
  File "C:\Users\aky\AppData\Local\Programs\Python\Python38\courseu\lib\site-packages\plotly\express\_core.py", line 1250, in process_args_into_dataframe
    raise ValueError(
ValueError: All arguments should have the same length. The length of argument `wide_variable_0` is 4, whereas the length of  previously-processed arguments ['y'] is 101
ERROR 2023-12-16 00:57:09,450 django.server Thread-1 4240 basehttp basehttp.py 212 django.server log_message 16644 "GET /recommender/ HTTP/1.1" 500 203364
ERROR 2023-12-16 01:04:21,642 django.request Thread-1 9184 log log.py 241 django.request log_response 1392 Internal Server Error: /recommender/
Traceback (most recent call last):
  File "C:\Users\aky\AppData\Local\Programs\Python\Python38\courseu\lib\site-packages\django\core\handlers\exception.py", line 55, in inner
    response = get_response(request)
  File "C:\Users\aky\AppData\Local\Programs\Python\Python38\courseu\lib\site-packages\django\core\handlers\base.py", line 197, in _get_response
    response = wrapped_callback(request, *callback_args, **callback_kwargs)
  File "C:\Users\aky\AppData\Local\Programs\Python\Python38\eng_ver\apps\recommender\views.py", line 210, in recommender
    fig = px.bar(
TypeError: bar() got an unexpected keyword argument 'bardmode'
ERROR 2023-12-16 01:04:23,505 django.server Thread-1 9184 basehttp basehttp.py 212 django.server log_message 1392 "GET /recommender/ HTTP/1.1" 500 128129
ERROR 2023-12-16 01:04:50,770 django.request Thread-1 6156 log log.py 241 django.request log_response 12972 Internal Server Error: /recommender/
Traceback (most recent call last):
  File "C:\Users\aky\AppData\Local\Programs\Python\Python38\courseu\lib\site-packages\django\core\handlers\exception.py", line 55, in inner
    response = get_response(request)
  File "C:\Users\aky\AppData\Local\Programs\Python\Python38\courseu\lib\site-packages\django\core\handlers\base.py", line 197, in _get_response
    response = wrapped_callback(request, *callback_args, **callback_kwargs)
  File "C:\Users\aky\AppData\Local\Programs\Python\Python38\eng_ver\apps\recommender\views.py", line 210, in recommender
    fig = px.bar(
  File "C:\Users\aky\AppData\Local\Programs\Python\Python38\courseu\lib\site-packages\plotly\express\_chart_types.py", line 373, in bar
    return make_figure(
  File "C:\Users\aky\AppData\Local\Programs\Python\Python38\courseu\lib\site-packages\plotly\express\_core.py", line 2165, in make_figure
    m.updater(trace, m.val_map[val])  # covers most cases
  File "C:\Users\aky\AppData\Local\Programs\Python\Python38\courseu\lib\site-packages\plotly\express\_core.py", line 240, in <lambda>
    updater=lambda trace, v: trace.update(
  File "C:\Users\aky\AppData\Local\Programs\Python\Python38\courseu\lib\site-packages\plotly\basedatatypes.py", line 5141, in update
    BaseFigure._perform_update(self, dict1, overwrite=overwrite)
  File "C:\Users\aky\AppData\Local\Programs\Python\Python38\courseu\lib\site-packages\plotly\basedatatypes.py", line 3921, in _perform_update
    BaseFigure._perform_update(plotly_obj[key], val)
  File "C:\Users\aky\AppData\Local\Programs\Python\Python38\courseu\lib\site-packages\plotly\basedatatypes.py", line 3942, in _perform_update
    plotly_obj[key] = val
  File "C:\Users\aky\AppData\Local\Programs\Python\Python38\courseu\lib\site-packages\plotly\basedatatypes.py", line 4876, in __setitem__
    self._set_prop(prop, value)
  File "C:\Users\aky\AppData\Local\Programs\Python\Python38\courseu\lib\site-packages\plotly\basedatatypes.py", line 5220, in _set_prop
    raise err
  File "C:\Users\aky\AppData\Local\Programs\Python\Python38\courseu\lib\site-packages\plotly\basedatatypes.py", line 5215, in _set_prop
    val = validator.validate_coerce(val)
  File "C:\Users\aky\AppData\Local\Programs\Python\Python38\courseu\lib\site-packages\_plotly_utils\basevalidators.py", line 1374, in validate_coerce
    self.raise_invalid_val(v)
  File "C:\Users\aky\AppData\Local\Programs\Python\Python38\courseu\lib\site-packages\_plotly_utils\basevalidators.py", line 287, in raise_invalid_val
    raise ValueError(
ValueError: 
    Invalid value of type 'builtins.str' received for the 'color' property of bar.marker
        Received value: 'Software Development'

    The 'color' property is a color and may be specified as:
      - A hex string (e.g. '#ff0000')
      - An rgb/rgba string (e.g. 'rgb(255,0,0)')
      - An hsl/hsla string (e.g. 'hsl(0,100%,50%)')
      - An hsv/hsva string (e.g. 'hsv(0,100%,100%)')
      - A named CSS color:
            aliceblue, antiquewhite, aqua, aquamarine, azure,
            beige, bisque, black, blanchedalmond, blue,
            blueviolet, brown, burlywood, cadetblue,
            chartreuse, chocolate, coral, cornflowerblue,
            cornsilk, crimson, cyan, darkblue, darkcyan,
            darkgoldenrod, darkgray, darkgrey, darkgreen,
            darkkhaki, darkmagenta, darkolivegreen, darkorange,
            darkorchid, darkred, darksalmon, darkseagreen,
            darkslateblue, darkslategray, darkslategrey,
            darkturquoise, darkviolet, deeppink, deepskyblue,
            dimgray, dimgrey, dodgerblue, firebrick,
            floralwhite, forestgreen, fuchsia, gainsboro,
            ghostwhite, gold, goldenrod, gray, grey, green,
            greenyellow, honeydew, hotpink, indianred, indigo,
            ivory, khaki, lavender, lavenderblush, lawngreen,
            lemonchiffon, lightblue, lightcoral, lightcyan,
            lightgoldenrodyellow, lightgray, lightgrey,
            lightgreen, lightpink, lightsalmon, lightseagreen,
            lightskyblue, lightslategray, lightslategrey,
            lightsteelblue, lightyellow, lime, limegreen,
            linen, magenta, maroon, mediumaquamarine,
            mediumblue, mediumorchid, mediumpurple,
            mediumseagreen, mediumslateblue, mediumspringgreen,
            mediumturquoise, mediumvioletred, midnightblue,
            mintcream, mistyrose, moccasin, navajowhite, navy,
            oldlace, olive, olivedrab, orange, orangered,
            orchid, palegoldenrod, palegreen, paleturquoise,
            palevioletred, papayawhip, peachpuff, peru, pink,
            plum, powderblue, purple, red, rosybrown,
            royalblue, rebeccapurple, saddlebrown, salmon,
            sandybrown, seagreen, seashell, sienna, silver,
            skyblue, slateblue, slategray, slategrey, snow,
            springgreen, steelblue, tan, teal, thistle, tomato,
            turquoise, violet, wheat, white, whitesmoke,
            yellow, yellowgreen
      - A number that will be interpreted as a color
        according to bar.marker.colorscale
      - A list or array of any of the above
ERROR 2023-12-16 01:04:52,029 django.server Thread-1 6156 basehttp basehttp.py 212 django.server log_message 12972 "GET /recommender/ HTTP/1.1" 500 210542
WARNING 2023-12-16 12:14:30,193 django.request Thread-3 17276 log log.py 241 django.request log_response 14920 Not Found: /favicon.ico
WARNING 2023-12-16 12:14:30,193 django.server Thread-3 17276 basehttp basehttp.py 212 django.server log_message 14920 "GET /favicon.ico HTTP/1.1" 404 26884
WARNING 2023-12-16 12:14:36,911 django.server Thread-3 17276 basehttp basehttp.py 212 django.server log_message 14920 "GET /static/images/favicon.png HTTP/1.1" 404 1914
ERROR 2023-12-16 16:00:04,385 django.request Thread-1 3116 log log.py 241 django.request log_response 6048 Internal Server Error: /admin_tracer
Traceback (most recent call last):
  File "C:\Users\aky\AppData\Local\Programs\Python\Python38\courseu\lib\site-packages\django\core\handlers\exception.py", line 55, in inner
    response = get_response(request)
  File "C:\Users\aky\AppData\Local\Programs\Python\Python38\courseu\lib\site-packages\django\core\handlers\base.py", line 197, in _get_response
    response = wrapped_callback(request, *callback_args, **callback_kwargs)
  File "C:\Users\aky\AppData\Local\Programs\Python\Python38\eng_ver\apps\website\views.py", line 251, in admin_tracer
    return render(request, 'dashboard/admin_tracer.html', {
  File "C:\Users\aky\AppData\Local\Programs\Python\Python38\courseu\lib\site-packages\django\shortcuts.py", line 24, in render
    content = loader.render_to_string(template_name, context, request, using=using)
  File "C:\Users\aky\AppData\Local\Programs\Python\Python38\courseu\lib\site-packages\django\template\loader.py", line 62, in render_to_string
    return template.render(context, request)
  File "C:\Users\aky\AppData\Local\Programs\Python\Python38\courseu\lib\site-packages\django\template\backends\django.py", line 61, in render
    return self.template.render(context)
  File "C:\Users\aky\AppData\Local\Programs\Python\Python38\courseu\lib\site-packages\django\template\base.py", line 175, in render
    return self._render(context)
  File "C:\Users\aky\AppData\Local\Programs\Python\Python38\courseu\lib\site-packages\django\test\utils.py", line 112, in instrumented_test_render
    return self.nodelist.render(context)
  File "C:\Users\aky\AppData\Local\Programs\Python\Python38\courseu\lib\site-packages\django\template\base.py", line 1005, in render
    return SafeString("".join([node.render_annotated(context) for node in self]))
  File "C:\Users\aky\AppData\Local\Programs\Python\Python38\courseu\lib\site-packages\django\template\base.py", line 1005, in <listcomp>
    return SafeString("".join([node.render_annotated(context) for node in self]))
  File "C:\Users\aky\AppData\Local\Programs\Python\Python38\courseu\lib\site-packages\django\template\base.py", line 966, in render_annotated
    return self.render(context)
  File "C:\Users\aky\AppData\Local\Programs\Python\Python38\courseu\lib\site-packages\django\template\loader_tags.py", line 157, in render
    return compiled_parent._render(context)
  File "C:\Users\aky\AppData\Local\Programs\Python\Python38\courseu\lib\site-packages\django\test\utils.py", line 112, in instrumented_test_render
    return self.nodelist.render(context)
  File "C:\Users\aky\AppData\Local\Programs\Python\Python38\courseu\lib\site-packages\django\template\base.py", line 1005, in render
    return SafeString("".join([node.render_annotated(context) for node in self]))
  File "C:\Users\aky\AppData\Local\Programs\Python\Python38\courseu\lib\site-packages\django\template\base.py", line 1005, in <listcomp>
    return SafeString("".join([node.render_annotated(context) for node in self]))
  File "C:\Users\aky\AppData\Local\Programs\Python\Python38\courseu\lib\site-packages\django\template\base.py", line 966, in render_annotated
    return self.render(context)
  File "C:\Users\aky\AppData\Local\Programs\Python\Python38\courseu\lib\site-packages\django\template\defaulttags.py", line 321, in render
    return nodelist.render(context)
  File "C:\Users\aky\AppData\Local\Programs\Python\Python38\courseu\lib\site-packages\django\template\base.py", line 1005, in render
    return SafeString("".join([node.render_annotated(context) for node in self]))
  File "C:\Users\aky\AppData\Local\Programs\Python\Python38\courseu\lib\site-packages\django\template\base.py", line 1005, in <listcomp>
    return SafeString("".join([node.render_annotated(context) for node in self]))
  File "C:\Users\aky\AppData\Local\Programs\Python\Python38\courseu\lib\site-packages\django\template\base.py", line 966, in render_annotated
    return self.render(context)
  File "C:\Users\aky\AppData\Local\Programs\Python\Python38\courseu\lib\site-packages\django\template\loader_tags.py", line 63, in render
    result = block.nodelist.render(context)
  File "C:\Users\aky\AppData\Local\Programs\Python\Python38\courseu\lib\site-packages\django\template\base.py", line 1005, in render
    return SafeString("".join([node.render_annotated(context) for node in self]))
  File "C:\Users\aky\AppData\Local\Programs\Python\Python38\courseu\lib\site-packages\django\template\base.py", line 1005, in <listcomp>
    return SafeString("".join([node.render_annotated(context) for node in self]))
  File "C:\Users\aky\AppData\Local\Programs\Python\Python38\courseu\lib\site-packages\django\template\base.py", line 966, in render_annotated
    return self.render(context)
  File "C:\Users\aky\AppData\Local\Programs\Python\Python38\courseu\lib\site-packages\django\template\defaulttags.py", line 471, in render
    url = reverse(view_name, args=args, kwargs=kwargs, current_app=current_app)
  File "C:\Users\aky\AppData\Local\Programs\Python\Python38\courseu\lib\site-packages\django\urls\base.py", line 88, in reverse
    return resolver._reverse_with_prefix(view, prefix, *args, **kwargs)
  File "C:\Users\aky\AppData\Local\Programs\Python\Python38\courseu\lib\site-packages\django\urls\resolvers.py", line 828, in _reverse_with_prefix
    raise NoReverseMatch(msg)
django.urls.exceptions.NoReverseMatch: Reverse for 'admin_view' not found. 'admin_view' is not a valid view function or pattern name.
ERROR 2023-12-16 16:00:04,573 django.server Thread-1 3116 basehttp basehttp.py 212 django.server log_message 6048 "GET /admin_tracer HTTP/1.1" 500 218275
ERROR 2023-12-16 16:00:33,172 django.request Thread-1 3116 log log.py 241 django.request log_response 6048 Internal Server Error: /admin_report_view/
Traceback (most recent call last):
  File "C:\Users\aky\AppData\Local\Programs\Python\Python38\courseu\lib\site-packages\django\db\models\sql\query.py", line 2161, in add_fields
    join_info = self.setup_joins(
  File "C:\Users\aky\AppData\Local\Programs\Python\Python38\courseu\lib\site-packages\django\db\models\sql\query.py", line 1823, in setup_joins
    path, final_field, targets, rest = self.names_to_path(
  File "C:\Users\aky\AppData\Local\Programs\Python\Python38\courseu\lib\site-packages\django\db\models\sql\query.py", line 1724, in names_to_path
    raise FieldError(
django.core.exceptions.FieldError: Cannot resolve keyword 'q2' into field. Choices are: academic_course, academic_course_id, accessed_job_postings, additional_feedback, confidence_rating, current_job_title, employed, explored_learning_materials, id, job_alignment, job_misalignment_reason, job_satisfaction, material_satisfaction, material_skill_gain, more_specialized_postings, posting_career_influence, posting_job_understanding, received_recommendation, recommendation_influence, recommendation_influence_reason, recommendation_system_improvements, specialization, study_preparation, system_information_helpfulness, timestamp, user, user_id

During handling of the above exception, another exception occurred:

Traceback (most recent call last):
  File "C:\Users\aky\AppData\Local\Programs\Python\Python38\courseu\lib\site-packages\django\core\handlers\exception.py", line 55, in inner
    response = get_response(request)
  File "C:\Users\aky\AppData\Local\Programs\Python\Python38\courseu\lib\site-packages\django\core\handlers\base.py", line 197, in _get_response
    response = wrapped_callback(request, *callback_args, **callback_kwargs)
  File "C:\Users\aky\AppData\Local\Programs\Python\Python38\eng_ver\apps\survey\views.py", line 86, in admin_report_view
    alignment_and_satisfaction = plotly_alignment_and_satisfaction()
  File "C:\Users\aky\AppData\Local\Programs\Python\Python38\eng_ver\apps\survey\report_generator.py", line 10, in plotly_alignment_and_satisfaction
    alignment_data = Survey.objects.values('q2', 'q6').annotate(count=Count('q2'))
  File "C:\Users\aky\AppData\Local\Programs\Python\Python38\courseu\lib\site-packages\django\db\models\manager.py", line 87, in manager_method
    return getattr(self.get_queryset(), name)(*args, **kwargs)
  File "C:\Users\aky\AppData\Local\Programs\Python\Python38\courseu\lib\site-packages\django\db\models\query.py", line 1313, in values
    clone = self._values(*fields, **expressions)
  File "C:\Users\aky\AppData\Local\Programs\Python\Python38\courseu\lib\site-packages\django\db\models\query.py", line 1308, in _values
    clone.query.set_values(fields)
  File "C:\Users\aky\AppData\Local\Programs\Python\Python38\courseu\lib\site-packages\django\db\models\sql\query.py", line 2460, in set_values
    self.add_fields(field_names, True)
  File "C:\Users\aky\AppData\Local\Programs\Python\Python38\courseu\lib\site-packages\django\db\models\sql\query.py", line 2194, in add_fields
    raise FieldError(
django.core.exceptions.FieldError: Cannot resolve keyword 'q2' into field. Choices are: academic_course, academic_course_id, accessed_job_postings, additional_feedback, confidence_rating, current_job_title, employed, explored_learning_materials, id, job_alignment, job_misalignment_reason, job_satisfaction, material_satisfaction, material_skill_gain, more_specialized_postings, posting_career_influence, posting_job_understanding, received_recommendation, recommendation_influence, recommendation_influence_reason, recommendation_system_improvements, specialization, study_preparation, system_information_helpfulness, timestamp, user, user_id
ERROR 2023-12-16 16:00:33,326 django.server Thread-1 3116 basehttp basehttp.py 212 django.server log_message 6048 "GET /admin_report_view/ HTTP/1.1" 500 142509
ERROR 2023-12-16 16:00:37,228 django.request Thread-1 3116 log log.py 241 django.request log_response 6048 Internal Server Error: /admin_report_pdf/
Traceback (most recent call last):
  File "C:\Users\aky\AppData\Local\Programs\Python\Python38\courseu\lib\site-packages\django\core\handlers\exception.py", line 55, in inner
    response = get_response(request)
  File "C:\Users\aky\AppData\Local\Programs\Python\Python38\courseu\lib\site-packages\django\core\handlers\base.py", line 197, in _get_response
    response = wrapped_callback(request, *callback_args, **callback_kwargs)
  File "C:\Users\aky\AppData\Local\Programs\Python\Python38\eng_ver\apps\survey\views.py", line 126, in admin_report_pdf
    template = get_template('admin_report.html')
  File "C:\Users\aky\AppData\Local\Programs\Python\Python38\courseu\lib\site-packages\django\template\loader.py", line 19, in get_template
    raise TemplateDoesNotExist(template_name, chain=chain)
django.template.exceptions.TemplateDoesNotExist: admin_report.html
ERROR 2023-12-16 16:00:37,303 django.server Thread-1 3116 basehttp basehttp.py 212 django.server log_message 6048 "GET /admin_report_pdf/ HTTP/1.1" 500 107496
ERROR 2023-12-16 16:02:09,130 django.request Thread-1 10936 log log.py 241 django.request log_response 9896 Internal Server Error: /admin_report_view/
Traceback (most recent call last):
  File "C:\Users\aky\AppData\Local\Programs\Python\Python38\courseu\lib\site-packages\django\db\models\sql\query.py", line 2161, in add_fields
    join_info = self.setup_joins(
  File "C:\Users\aky\AppData\Local\Programs\Python\Python38\courseu\lib\site-packages\django\db\models\sql\query.py", line 1823, in setup_joins
    path, final_field, targets, rest = self.names_to_path(
  File "C:\Users\aky\AppData\Local\Programs\Python\Python38\courseu\lib\site-packages\django\db\models\sql\query.py", line 1724, in names_to_path
    raise FieldError(
django.core.exceptions.FieldError: Cannot resolve keyword 'q2' into field. Choices are: academic_course, academic_course_id, accessed_job_postings, additional_feedback, confidence_rating, current_job_title, employed, explored_learning_materials, id, job_alignment, job_misalignment_reason, job_satisfaction, material_satisfaction, material_skill_gain, more_specialized_postings, posting_career_influence, posting_job_understanding, received_recommendation, recommendation_influence, recommendation_influence_reason, recommendation_system_improvements, specialization, study_preparation, system_information_helpfulness, timestamp, user, user_id

During handling of the above exception, another exception occurred:

Traceback (most recent call last):
  File "C:\Users\aky\AppData\Local\Programs\Python\Python38\courseu\lib\site-packages\django\core\handlers\exception.py", line 55, in inner
    response = get_response(request)
  File "C:\Users\aky\AppData\Local\Programs\Python\Python38\courseu\lib\site-packages\django\core\handlers\base.py", line 197, in _get_response
    response = wrapped_callback(request, *callback_args, **callback_kwargs)
  File "C:\Users\aky\AppData\Local\Programs\Python\Python38\eng_ver\apps\survey\views.py", line 86, in admin_report_view
    alignment_and_satisfaction = plotly_alignment_and_satisfaction()
  File "C:\Users\aky\AppData\Local\Programs\Python\Python38\eng_ver\apps\survey\report_generator.py", line 10, in plotly_alignment_and_satisfaction
    alignment_data = Survey.objects.values('q2', 'q6').annotate(count=Count('q2'))
  File "C:\Users\aky\AppData\Local\Programs\Python\Python38\courseu\lib\site-packages\django\db\models\manager.py", line 87, in manager_method
    return getattr(self.get_queryset(), name)(*args, **kwargs)
  File "C:\Users\aky\AppData\Local\Programs\Python\Python38\courseu\lib\site-packages\django\db\models\query.py", line 1313, in values
    clone = self._values(*fields, **expressions)
  File "C:\Users\aky\AppData\Local\Programs\Python\Python38\courseu\lib\site-packages\django\db\models\query.py", line 1308, in _values
    clone.query.set_values(fields)
  File "C:\Users\aky\AppData\Local\Programs\Python\Python38\courseu\lib\site-packages\django\db\models\sql\query.py", line 2460, in set_values
    self.add_fields(field_names, True)
  File "C:\Users\aky\AppData\Local\Programs\Python\Python38\courseu\lib\site-packages\django\db\models\sql\query.py", line 2194, in add_fields
    raise FieldError(
django.core.exceptions.FieldError: Cannot resolve keyword 'q2' into field. Choices are: academic_course, academic_course_id, accessed_job_postings, additional_feedback, confidence_rating, current_job_title, employed, explored_learning_materials, id, job_alignment, job_misalignment_reason, job_satisfaction, material_satisfaction, material_skill_gain, more_specialized_postings, posting_career_influence, posting_job_understanding, received_recommendation, recommendation_influence, recommendation_influence_reason, recommendation_system_improvements, specialization, study_preparation, system_information_helpfulness, timestamp, user, user_id
ERROR 2023-12-16 16:02:09,300 django.server Thread-1 10936 basehttp basehttp.py 212 django.server log_message 9896 "GET /admin_report_view/ HTTP/1.1" 500 142519
ERROR 2023-12-16 16:02:23,216 django.request Thread-1 10936 log log.py 241 django.request log_response 9896 Internal Server Error: /admin_report_view/
Traceback (most recent call last):
  File "C:\Users\aky\AppData\Local\Programs\Python\Python38\courseu\lib\site-packages\django\db\models\sql\query.py", line 2161, in add_fields
    join_info = self.setup_joins(
  File "C:\Users\aky\AppData\Local\Programs\Python\Python38\courseu\lib\site-packages\django\db\models\sql\query.py", line 1823, in setup_joins
    path, final_field, targets, rest = self.names_to_path(
  File "C:\Users\aky\AppData\Local\Programs\Python\Python38\courseu\lib\site-packages\django\db\models\sql\query.py", line 1724, in names_to_path
    raise FieldError(
django.core.exceptions.FieldError: Cannot resolve keyword 'q2' into field. Choices are: academic_course, academic_course_id, accessed_job_postings, additional_feedback, confidence_rating, current_job_title, employed, explored_learning_materials, id, job_alignment, job_misalignment_reason, job_satisfaction, material_satisfaction, material_skill_gain, more_specialized_postings, posting_career_influence, posting_job_understanding, received_recommendation, recommendation_influence, recommendation_influence_reason, recommendation_system_improvements, specialization, study_preparation, system_information_helpfulness, timestamp, user, user_id

During handling of the above exception, another exception occurred:

Traceback (most recent call last):
  File "C:\Users\aky\AppData\Local\Programs\Python\Python38\courseu\lib\site-packages\django\core\handlers\exception.py", line 55, in inner
    response = get_response(request)
  File "C:\Users\aky\AppData\Local\Programs\Python\Python38\courseu\lib\site-packages\django\core\handlers\base.py", line 197, in _get_response
    response = wrapped_callback(request, *callback_args, **callback_kwargs)
  File "C:\Users\aky\AppData\Local\Programs\Python\Python38\eng_ver\apps\survey\views.py", line 86, in admin_report_view
    alignment_and_satisfaction = plotly_alignment_and_satisfaction()
  File "C:\Users\aky\AppData\Local\Programs\Python\Python38\eng_ver\apps\survey\report_generator.py", line 10, in plotly_alignment_and_satisfaction
    alignment_data = Survey.objects.values('q2', 'q6').annotate(count=Count('q2'))
  File "C:\Users\aky\AppData\Local\Programs\Python\Python38\courseu\lib\site-packages\django\db\models\manager.py", line 87, in manager_method
    return getattr(self.get_queryset(), name)(*args, **kwargs)
  File "C:\Users\aky\AppData\Local\Programs\Python\Python38\courseu\lib\site-packages\django\db\models\query.py", line 1313, in values
    clone = self._values(*fields, **expressions)
  File "C:\Users\aky\AppData\Local\Programs\Python\Python38\courseu\lib\site-packages\django\db\models\query.py", line 1308, in _values
    clone.query.set_values(fields)
  File "C:\Users\aky\AppData\Local\Programs\Python\Python38\courseu\lib\site-packages\django\db\models\sql\query.py", line 2460, in set_values
    self.add_fields(field_names, True)
  File "C:\Users\aky\AppData\Local\Programs\Python\Python38\courseu\lib\site-packages\django\db\models\sql\query.py", line 2194, in add_fields
    raise FieldError(
django.core.exceptions.FieldError: Cannot resolve keyword 'q2' into field. Choices are: academic_course, academic_course_id, accessed_job_postings, additional_feedback, confidence_rating, current_job_title, employed, explored_learning_materials, id, job_alignment, job_misalignment_reason, job_satisfaction, material_satisfaction, material_skill_gain, more_specialized_postings, posting_career_influence, posting_job_understanding, received_recommendation, recommendation_influence, recommendation_influence_reason, recommendation_system_improvements, specialization, study_preparation, system_information_helpfulness, timestamp, user, user_id
ERROR 2023-12-16 16:02:23,289 django.server Thread-1 10936 basehttp basehttp.py 212 django.server log_message 9896 "GET /admin_report_view/ HTTP/1.1" 500 142519
