WARNING 2023-11-25 16:10:46,112 django.request Thread-4 4420 log log.py 241 django.request log_response 1396 Not Found: /Specialization
WARNING 2023-11-25 16:10:46,114 django.server Thread-4 4420 basehttp basehttp.py 212 django.server log_message 1396 "GET /Specialization HTTP/1.1" 404 26102
WARNING 2023-11-25 16:10:53,299 django.request Thread-4 4420 log log.py 241 django.request log_response 1396 Not Found: /job_list/
WARNING 2023-11-25 16:10:53,301 django.server Thread-4 4420 basehttp basehttp.py 212 django.server log_message 1396 "GET /job_list/ HTTP/1.1" 404 15693
WARNING 2023-11-25 16:12:46,801 django.request Thread-1 13764 log log.py 241 django.request log_response 16640 Not Found: /images/profile_pics/IMG_3477_YVMV930.jpg
WARNING 2023-11-25 16:12:46,804 django.server Thread-1 13764 basehttp basehttp.py 212 django.server log_message 16640 "GET /images/profile_pics/IMG_3477_YVMV930.jpg HTTP/1.1" 404 26319
WARNING 2023-11-25 16:12:46,825 django.request Thread-2 13780 log log.py 241 django.request log_response 16640 Not Found: /images/profile_pics/WIN_20230530_14_55_43_Pro.jpg
WARNING 2023-11-25 16:12:46,829 django.server Thread-2 13780 basehttp basehttp.py 212 django.server log_message 16640 "GET /images/profile_pics/WIN_20230530_14_55_43_Pro.jpg HTTP/1.1" 404 26364
WARNING 2023-11-25 17:14:51,269 django.request Thread-17 8296 log log.py 241 django.request log_response 16640 Not Found: /images/profile_pics/IMG_3477_YVMV930.jpg
WARNING 2023-11-25 17:14:51,275 django.server Thread-17 8296 basehttp basehttp.py 212 django.server log_message 16640 "GET /images/profile_pics/IMG_3477_YVMV930.jpg HTTP/1.1" 404 26319
WARNING 2023-11-25 17:14:51,299 django.request Thread-16 12484 log log.py 241 django.request log_response 16640 Not Found: /images/profile_pics/WIN_20230530_14_55_43_Pro.jpg
WARNING 2023-11-25 17:14:51,305 django.server Thread-16 12484 basehttp basehttp.py 212 django.server log_message 16640 "GET /images/profile_pics/WIN_20230530_14_55_43_Pro.jpg HTTP/1.1" 404 26364
ERROR 2023-11-25 17:14:59,032 django.request Thread-17 8296 log log.py 241 django.request log_response 16640 Internal Server Error: /reports/12/
Traceback (most recent call last):
  File "C:\Users\aky\AppData\Local\Programs\Python\Python38\courseu\lib\site-packages\django\template\base.py", line 505, in parse
    compile_func = self.tags[command]
KeyError: 'endif'

During handling of the above exception, another exception occurred:

Traceback (most recent call last):
  File "C:\Users\aky\AppData\Local\Programs\Python\Python38\courseu\lib\site-packages\django\core\handlers\exception.py", line 55, in inner
    response = get_response(request)
  File "C:\Users\aky\AppData\Local\Programs\Python\Python38\courseu\lib\site-packages\django\core\handlers\base.py", line 197, in _get_response
    response = wrapped_callback(request, *callback_args, **callback_kwargs)
  File "C:\Users\aky\AppData\Local\Programs\Python\Python38\eng_ver\apps\website\views.py", line 385, in reports
    return render(request, 'reports.html', context)
  File "C:\Users\aky\AppData\Local\Programs\Python\Python38\courseu\lib\site-packages\django\shortcuts.py", line 24, in render
    content = loader.render_to_string(template_name, context, request, using=using)
  File "C:\Users\aky\AppData\Local\Programs\Python\Python38\courseu\lib\site-packages\django\template\loader.py", line 61, in render_to_string
    template = get_template(template_name, using=using)
  File "C:\Users\aky\AppData\Local\Programs\Python\Python38\courseu\lib\site-packages\django\template\loader.py", line 15, in get_template
    return engine.get_template(template_name)
  File "C:\Users\aky\AppData\Local\Programs\Python\Python38\courseu\lib\site-packages\django\template\backends\django.py", line 33, in get_template
    return Template(self.engine.get_template(template_name), self)
  File "C:\Users\aky\AppData\Local\Programs\Python\Python38\courseu\lib\site-packages\django\template\engine.py", line 175, in get_template
    template, origin = self.find_template(template_name)
  File "C:\Users\aky\AppData\Local\Programs\Python\Python38\courseu\lib\site-packages\django\template\engine.py", line 157, in find_template
    template = loader.get_template(name, skip=skip)
  File "C:\Users\aky\AppData\Local\Programs\Python\Python38\courseu\lib\site-packages\django\template\loaders\cached.py", line 57, in get_template
    template = super().get_template(template_name, skip)
  File "C:\Users\aky\AppData\Local\Programs\Python\Python38\courseu\lib\site-packages\django\template\loaders\base.py", line 28, in get_template
    return Template(
  File "C:\Users\aky\AppData\Local\Programs\Python\Python38\courseu\lib\site-packages\django\template\base.py", line 154, in __init__
    self.nodelist = self.compile_nodelist()
  File "C:\Users\aky\AppData\Local\Programs\Python\Python38\courseu\lib\site-packages\django\template\base.py", line 200, in compile_nodelist
    return parser.parse()
  File "C:\Users\aky\AppData\Local\Programs\Python\Python38\courseu\lib\site-packages\django\template\base.py", line 513, in parse
    raise self.error(token, e)
  File "C:\Users\aky\AppData\Local\Programs\Python\Python38\courseu\lib\site-packages\django\template\base.py", line 511, in parse
    compiled_result = compile_func(self, token)
  File "C:\Users\aky\AppData\Local\Programs\Python\Python38\courseu\lib\site-packages\django\template\loader_tags.py", line 293, in do_extends
    nodelist = parser.parse()
  File "C:\Users\aky\AppData\Local\Programs\Python\Python38\courseu\lib\site-packages\django\template\base.py", line 513, in parse
    raise self.error(token, e)
  File "C:\Users\aky\AppData\Local\Programs\Python\Python38\courseu\lib\site-packages\django\template\base.py", line 511, in parse
    compiled_result = compile_func(self, token)
  File "C:\Users\aky\AppData\Local\Programs\Python\Python38\courseu\lib\site-packages\django\template\loader_tags.py", line 232, in do_block
    nodelist = parser.parse(("endblock",))
  File "C:\Users\aky\AppData\Local\Programs\Python\Python38\courseu\lib\site-packages\django\template\base.py", line 507, in parse
    self.invalid_block_tag(token, command, parse_until)
  File "C:\Users\aky\AppData\Local\Programs\Python\Python38\courseu\lib\site-packages\django\template\base.py", line 558, in invalid_block_tag
    raise self.error(
django.template.exceptions.TemplateSyntaxError: Invalid block tag on line 109: 'endif', expected 'endblock'. Did you forget to register or load this tag?
ERROR 2023-11-25 17:14:59,226 django.request Thread-16 12484 log log.py 241 django.request log_response 16640 Internal Server Error: /reports/12/
Traceback (most recent call last):
  File "C:\Users\aky\AppData\Local\Programs\Python\Python38\courseu\lib\site-packages\django\template\base.py", line 505, in parse
    compile_func = self.tags[command]
KeyError: 'endif'

During handling of the above exception, another exception occurred:

Traceback (most recent call last):
  File "C:\Users\aky\AppData\Local\Programs\Python\Python38\courseu\lib\site-packages\django\core\handlers\exception.py", line 55, in inner
    response = get_response(request)
  File "C:\Users\aky\AppData\Local\Programs\Python\Python38\courseu\lib\site-packages\django\core\handlers\base.py", line 197, in _get_response
    response = wrapped_callback(request, *callback_args, **callback_kwargs)
  File "C:\Users\aky\AppData\Local\Programs\Python\Python38\eng_ver\apps\website\views.py", line 385, in reports
    return render(request, 'reports.html', context)
  File "C:\Users\aky\AppData\Local\Programs\Python\Python38\courseu\lib\site-packages\django\shortcuts.py", line 24, in render
    content = loader.render_to_string(template_name, context, request, using=using)
  File "C:\Users\aky\AppData\Local\Programs\Python\Python38\courseu\lib\site-packages\django\template\loader.py", line 61, in render_to_string
    template = get_template(template_name, using=using)
  File "C:\Users\aky\AppData\Local\Programs\Python\Python38\courseu\lib\site-packages\django\template\loader.py", line 15, in get_template
    return engine.get_template(template_name)
  File "C:\Users\aky\AppData\Local\Programs\Python\Python38\courseu\lib\site-packages\django\template\backends\django.py", line 33, in get_template
    return Template(self.engine.get_template(template_name), self)
  File "C:\Users\aky\AppData\Local\Programs\Python\Python38\courseu\lib\site-packages\django\template\engine.py", line 175, in get_template
    template, origin = self.find_template(template_name)
  File "C:\Users\aky\AppData\Local\Programs\Python\Python38\courseu\lib\site-packages\django\template\engine.py", line 157, in find_template
    template = loader.get_template(name, skip=skip)
  File "C:\Users\aky\AppData\Local\Programs\Python\Python38\courseu\lib\site-packages\django\template\loaders\cached.py", line 57, in get_template
    template = super().get_template(template_name, skip)
  File "C:\Users\aky\AppData\Local\Programs\Python\Python38\courseu\lib\site-packages\django\template\loaders\base.py", line 28, in get_template
    return Template(
  File "C:\Users\aky\AppData\Local\Programs\Python\Python38\courseu\lib\site-packages\django\template\base.py", line 154, in __init__
    self.nodelist = self.compile_nodelist()
  File "C:\Users\aky\AppData\Local\Programs\Python\Python38\courseu\lib\site-packages\django\template\base.py", line 200, in compile_nodelist
    return parser.parse()
  File "C:\Users\aky\AppData\Local\Programs\Python\Python38\courseu\lib\site-packages\django\template\base.py", line 513, in parse
    raise self.error(token, e)
  File "C:\Users\aky\AppData\Local\Programs\Python\Python38\courseu\lib\site-packages\django\template\base.py", line 511, in parse
    compiled_result = compile_func(self, token)
  File "C:\Users\aky\AppData\Local\Programs\Python\Python38\courseu\lib\site-packages\django\template\loader_tags.py", line 293, in do_extends
    nodelist = parser.parse()
  File "C:\Users\aky\AppData\Local\Programs\Python\Python38\courseu\lib\site-packages\django\template\base.py", line 513, in parse
    raise self.error(token, e)
  File "C:\Users\aky\AppData\Local\Programs\Python\Python38\courseu\lib\site-packages\django\template\base.py", line 511, in parse
    compiled_result = compile_func(self, token)
  File "C:\Users\aky\AppData\Local\Programs\Python\Python38\courseu\lib\site-packages\django\template\loader_tags.py", line 232, in do_block
    nodelist = parser.parse(("endblock",))
  File "C:\Users\aky\AppData\Local\Programs\Python\Python38\courseu\lib\site-packages\django\template\base.py", line 507, in parse
    self.invalid_block_tag(token, command, parse_until)
  File "C:\Users\aky\AppData\Local\Programs\Python\Python38\courseu\lib\site-packages\django\template\base.py", line 558, in invalid_block_tag
    raise self.error(
django.template.exceptions.TemplateSyntaxError: Invalid block tag on line 109: 'endif', expected 'endblock'. Did you forget to register or load this tag?
ERROR 2023-11-25 17:14:59,351 django.server Thread-17 8296 basehttp basehttp.py 212 django.server log_message 16640 "GET /reports/12/ HTTP/1.1" 500 206153
ERROR 2023-11-25 17:16:03,998 django.request Thread-20 8612 log log.py 241 django.request log_response 16640 Internal Server Error: /reports/12/
Traceback (most recent call last):
  File "C:\Users\aky\AppData\Local\Programs\Python\Python38\courseu\lib\site-packages\django\template\base.py", line 505, in parse
    compile_func = self.tags[command]
KeyError: 'endif'

During handling of the above exception, another exception occurred:

Traceback (most recent call last):
  File "C:\Users\aky\AppData\Local\Programs\Python\Python38\courseu\lib\site-packages\django\core\handlers\exception.py", line 55, in inner
    response = get_response(request)
  File "C:\Users\aky\AppData\Local\Programs\Python\Python38\courseu\lib\site-packages\django\core\handlers\base.py", line 197, in _get_response
    response = wrapped_callback(request, *callback_args, **callback_kwargs)
  File "C:\Users\aky\AppData\Local\Programs\Python\Python38\eng_ver\apps\website\views.py", line 385, in reports
    return render(request, 'reports.html', context)
  File "C:\Users\aky\AppData\Local\Programs\Python\Python38\courseu\lib\site-packages\django\shortcuts.py", line 24, in render
    content = loader.render_to_string(template_name, context, request, using=using)
  File "C:\Users\aky\AppData\Local\Programs\Python\Python38\courseu\lib\site-packages\django\template\loader.py", line 61, in render_to_string
    template = get_template(template_name, using=using)
  File "C:\Users\aky\AppData\Local\Programs\Python\Python38\courseu\lib\site-packages\django\template\loader.py", line 15, in get_template
    return engine.get_template(template_name)
  File "C:\Users\aky\AppData\Local\Programs\Python\Python38\courseu\lib\site-packages\django\template\backends\django.py", line 33, in get_template
    return Template(self.engine.get_template(template_name), self)
  File "C:\Users\aky\AppData\Local\Programs\Python\Python38\courseu\lib\site-packages\django\template\engine.py", line 175, in get_template
    template, origin = self.find_template(template_name)
  File "C:\Users\aky\AppData\Local\Programs\Python\Python38\courseu\lib\site-packages\django\template\engine.py", line 157, in find_template
    template = loader.get_template(name, skip=skip)
  File "C:\Users\aky\AppData\Local\Programs\Python\Python38\courseu\lib\site-packages\django\template\loaders\cached.py", line 57, in get_template
    template = super().get_template(template_name, skip)
  File "C:\Users\aky\AppData\Local\Programs\Python\Python38\courseu\lib\site-packages\django\template\loaders\base.py", line 28, in get_template
    return Template(
  File "C:\Users\aky\AppData\Local\Programs\Python\Python38\courseu\lib\site-packages\django\template\base.py", line 154, in __init__
    self.nodelist = self.compile_nodelist()
  File "C:\Users\aky\AppData\Local\Programs\Python\Python38\courseu\lib\site-packages\django\template\base.py", line 200, in compile_nodelist
    return parser.parse()
  File "C:\Users\aky\AppData\Local\Programs\Python\Python38\courseu\lib\site-packages\django\template\base.py", line 513, in parse
    raise self.error(token, e)
  File "C:\Users\aky\AppData\Local\Programs\Python\Python38\courseu\lib\site-packages\django\template\base.py", line 511, in parse
    compiled_result = compile_func(self, token)
  File "C:\Users\aky\AppData\Local\Programs\Python\Python38\courseu\lib\site-packages\django\template\loader_tags.py", line 293, in do_extends
    nodelist = parser.parse()
  File "C:\Users\aky\AppData\Local\Programs\Python\Python38\courseu\lib\site-packages\django\template\base.py", line 513, in parse
    raise self.error(token, e)
  File "C:\Users\aky\AppData\Local\Programs\Python\Python38\courseu\lib\site-packages\django\template\base.py", line 511, in parse
    compiled_result = compile_func(self, token)
  File "C:\Users\aky\AppData\Local\Programs\Python\Python38\courseu\lib\site-packages\django\template\loader_tags.py", line 232, in do_block
    nodelist = parser.parse(("endblock",))
  File "C:\Users\aky\AppData\Local\Programs\Python\Python38\courseu\lib\site-packages\django\template\base.py", line 507, in parse
    self.invalid_block_tag(token, command, parse_until)
  File "C:\Users\aky\AppData\Local\Programs\Python\Python38\courseu\lib\site-packages\django\template\base.py", line 558, in invalid_block_tag
    raise self.error(
django.template.exceptions.TemplateSyntaxError: Invalid block tag on line 111: 'endif', expected 'endblock'. Did you forget to register or load this tag?
ERROR 2023-11-25 17:16:04,101 django.server Thread-20 8612 basehttp basehttp.py 212 django.server log_message 16640 "GET /reports/12/ HTTP/1.1" 500 205952
WARNING 2023-11-25 17:16:45,567 django.request Thread-22 11080 log log.py 241 django.request log_response 16640 Not Found: /images/profile_pics/IMG_3477_YVMV930.jpg
WARNING 2023-11-25 17:16:45,568 django.server Thread-22 11080 basehttp basehttp.py 212 django.server log_message 16640 "GET /images/profile_pics/IMG_3477_YVMV930.jpg HTTP/1.1" 404 26319
WARNING 2023-11-25 17:16:45,622 django.request Thread-23 17272 log log.py 241 django.request log_response 16640 Not Found: /images/profile_pics/WIN_20230530_14_55_43_Pro.jpg
WARNING 2023-11-25 17:16:45,624 django.server Thread-23 17272 basehttp basehttp.py 212 django.server log_message 16640 "GET /images/profile_pics/WIN_20230530_14_55_43_Pro.jpg HTTP/1.1" 404 26364
WARNING 2023-11-25 17:17:51,556 django.request Thread-23 17272 log log.py 241 django.request log_response 16640 Not Found: /images/profile_pics/WIN_20230530_14_55_43_Pro.jpg
WARNING 2023-11-25 17:17:51,558 django.server Thread-23 17272 basehttp basehttp.py 212 django.server log_message 16640 "GET /images/profile_pics/WIN_20230530_14_55_43_Pro.jpg HTTP/1.1" 404 26364
WARNING 2023-11-25 17:18:39,146 django.server Thread-26 2628 basehttp basehttp.py 212 django.server log_message 16640 "GET /static/images/favicon.png HTTP/1.1" 404 1914
WARNING 2023-11-25 17:28:34,137 django.request Thread-2 8332 log log.py 241 django.request log_response 19016 Not Found: /favicon.ico
WARNING 2023-11-25 17:28:34,137 django.server Thread-2 8332 basehttp basehttp.py 212 django.server log_message 19016 "GET /favicon.ico HTTP/1.1" 404 26090
ERROR 2023-11-25 17:45:27,327 django.request Thread-6 18200 log log.py 241 django.request log_response 19016 Internal Server Error: /admin/website/field/
Traceback (most recent call last):
  File "C:\Users\aky\AppData\Local\Programs\Python\Python38\courseu\lib\site-packages\django\core\handlers\exception.py", line 55, in inner
    response = get_response(request)
  File "C:\Users\aky\AppData\Local\Programs\Python\Python38\courseu\lib\site-packages\django\core\handlers\base.py", line 220, in _get_response
    response = response.render()
  File "C:\Users\aky\AppData\Local\Programs\Python\Python38\courseu\lib\site-packages\django\template\response.py", line 114, in render
    self.content = self.rendered_content
  File "C:\Users\aky\AppData\Local\Programs\Python\Python38\courseu\lib\site-packages\django\template\response.py", line 90, in rendered_content
    template = self.resolve_template(self.template_name)
  File "C:\Users\aky\AppData\Local\Programs\Python\Python38\courseu\lib\site-packages\django\template\response.py", line 72, in resolve_template
    return select_template(template, using=self.using)
  File "C:\Users\aky\AppData\Local\Programs\Python\Python38\courseu\lib\site-packages\django\template\loader.py", line 42, in select_template
    return engine.get_template(template_name)
  File "C:\Users\aky\AppData\Local\Programs\Python\Python38\courseu\lib\site-packages\django\template\backends\django.py", line 33, in get_template
    return Template(self.engine.get_template(template_name), self)
  File "C:\Users\aky\AppData\Local\Programs\Python\Python38\courseu\lib\site-packages\django\template\engine.py", line 175, in get_template
    template, origin = self.find_template(template_name)
  File "C:\Users\aky\AppData\Local\Programs\Python\Python38\courseu\lib\site-packages\django\template\engine.py", line 157, in find_template
    template = loader.get_template(name, skip=skip)
  File "C:\Users\aky\AppData\Local\Programs\Python\Python38\courseu\lib\site-packages\django\template\loaders\cached.py", line 57, in get_template
    template = super().get_template(template_name, skip)
  File "C:\Users\aky\AppData\Local\Programs\Python\Python38\courseu\lib\site-packages\django\template\loaders\base.py", line 28, in get_template
    return Template(
  File "C:\Users\aky\AppData\Local\Programs\Python\Python38\courseu\lib\site-packages\django\template\base.py", line 154, in __init__
    self.nodelist = self.compile_nodelist()
  File "C:\Users\aky\AppData\Local\Programs\Python\Python38\courseu\lib\site-packages\django\template\base.py", line 200, in compile_nodelist
    return parser.parse()
  File "C:\Users\aky\AppData\Local\Programs\Python\Python38\courseu\lib\site-packages\django\template\base.py", line 513, in parse
    raise self.error(token, e)
  File "C:\Users\aky\AppData\Local\Programs\Python\Python38\courseu\lib\site-packages\django\template\base.py", line 511, in parse
    compiled_result = compile_func(self, token)
  File "C:\Users\aky\AppData\Local\Programs\Python\Python38\courseu\lib\site-packages\django\template\loader_tags.py", line 293, in do_extends
    nodelist = parser.parse()
  File "C:\Users\aky\AppData\Local\Programs\Python\Python38\courseu\lib\site-packages\django\template\base.py", line 513, in parse
    raise self.error(token, e)
  File "C:\Users\aky\AppData\Local\Programs\Python\Python38\courseu\lib\site-packages\django\template\base.py", line 511, in parse
    compiled_result = compile_func(self, token)
  File "C:\Users\aky\AppData\Local\Programs\Python\Python38\courseu\lib\site-packages\django\template\loader_tags.py", line 232, in do_block
    nodelist = parser.parse(("endblock",))
  File "C:\Users\aky\AppData\Local\Programs\Python\Python38\courseu\lib\site-packages\django\template\base.py", line 513, in parse
    raise self.error(token, e)
  File "C:\Users\aky\AppData\Local\Programs\Python\Python38\courseu\lib\site-packages\django\template\base.py", line 511, in parse
    compiled_result = compile_func(self, token)
  File "C:\Users\aky\AppData\Local\Programs\Python\Python38\courseu\lib\site-packages\django\template\defaulttags.py", line 953, in do_if
    nodelist = parser.parse(("elif", "else", "endif"))
  File "C:\Users\aky\AppData\Local\Programs\Python\Python38\courseu\lib\site-packages\django\template\base.py", line 518, in parse
    self.unclosed_block_tag(parse_until)
  File "C:\Users\aky\AppData\Local\Programs\Python\Python38\courseu\lib\site-packages\django\template\base.py", line 581, in unclosed_block_tag
    raise self.error(token, msg)
django.template.exceptions.TemplateSyntaxError: Unclosed tag on line 6: 'if'. Looking for one of: elif, else, endif.
ERROR 2023-11-25 17:45:27,437 django.server Thread-6 18200 basehttp basehttp.py 212 django.server log_message 19016 "GET /admin/website/field/ HTTP/1.1" 500 196722
WARNING 2023-11-25 17:54:46,218 django.request Thread-8 17500 log log.py 241 django.request log_response 10768 Not Found: /images/profile_pics/IMG_3477_YVMV930.jpg
WARNING 2023-11-25 17:54:46,222 django.server Thread-8 17500 basehttp basehttp.py 212 django.server log_message 10768 "GET /images/profile_pics/IMG_3477_YVMV930.jpg HTTP/1.1" 404 26319
WARNING 2023-11-25 17:54:46,243 django.request Thread-9 17676 log log.py 241 django.request log_response 10768 Not Found: /images/profile_pics/WIN_20230530_14_55_43_Pro.jpg
WARNING 2023-11-25 17:54:46,245 django.server Thread-9 17676 basehttp basehttp.py 212 django.server log_message 10768 "GET /images/profile_pics/WIN_20230530_14_55_43_Pro.jpg HTTP/1.1" 404 26364
WARNING 2023-11-25 17:55:57,739 django.request Thread-13 8640 log log.py 241 django.request log_response 10768 Not Found: /images/profile_pics/IMG_3477_YVMV930.jpg
WARNING 2023-11-25 17:55:57,740 django.server Thread-13 8640 basehttp basehttp.py 212 django.server log_message 10768 "GET /images/profile_pics/IMG_3477_YVMV930.jpg HTTP/1.1" 404 26319
WARNING 2023-11-25 18:09:14,249 django.request Thread-5 16288 log log.py 241 django.request log_response 6804 Not Found: /favicon.ico
WARNING 2023-11-25 18:09:14,252 django.server Thread-5 16288 basehttp basehttp.py 212 django.server log_message 6804 "GET /favicon.ico HTTP/1.1" 404 26090
WARNING 2023-11-25 18:09:20,864 django.server Thread-5 16288 basehttp basehttp.py 212 django.server log_message 6804 "GET /static/images/favicon.png HTTP/1.1" 404 1914
WARNING 2023-11-25 18:12:43,738 django.request Thread-1 3024 log log.py 241 django.request log_response 12380 Not Found: /admin/website/field/
WARNING 2023-11-25 18:12:43,739 django.server Thread-1 3024 basehttp basehttp.py 212 django.server log_message 12380 "GET /admin/website/field/ HTTP/1.1" 404 17199
ERROR 2023-11-25 18:15:40,108 django.request Thread-5 10716 log log.py 241 django.request log_response 2404 Internal Server Error: /admin/website/field/upload-csv/
Traceback (most recent call last):
  File "C:\Users\aky\AppData\Local\Programs\Python\Python38\courseu\lib\site-packages\django\core\handlers\exception.py", line 55, in inner
    response = get_response(request)
  File "C:\Users\aky\AppData\Local\Programs\Python\Python38\courseu\lib\site-packages\django\core\handlers\base.py", line 197, in _get_response
    response = wrapped_callback(request, *callback_args, **callback_kwargs)
  File "C:\Users\aky\AppData\Local\Programs\Python\Python38\eng_ver\apps\website\admin.py", line 64, in upload_csv
    return render (request, "admin/csv_upload.html")
  File "C:\Users\aky\AppData\Local\Programs\Python\Python38\courseu\lib\site-packages\django\shortcuts.py", line 24, in render
    content = loader.render_to_string(template_name, context, request, using=using)
  File "C:\Users\aky\AppData\Local\Programs\Python\Python38\courseu\lib\site-packages\django\template\loader.py", line 61, in render_to_string
    template = get_template(template_name, using=using)
  File "C:\Users\aky\AppData\Local\Programs\Python\Python38\courseu\lib\site-packages\django\template\loader.py", line 19, in get_template
    raise TemplateDoesNotExist(template_name, chain=chain)
django.template.exceptions.TemplateDoesNotExist: admin/csv_upload.html
ERROR 2023-11-25 18:15:40,151 django.server Thread-5 10716 basehttp basehttp.py 212 django.server log_message 2404 "GET /admin/website/field/upload-csv/ HTTP/1.1" 500 108088
ERROR 2023-11-25 18:16:11,790 django.request Thread-7 12800 log log.py 241 django.request log_response 2404 Internal Server Error: /admin/website/field/upload-csv/
Traceback (most recent call last):
  File "C:\Users\aky\AppData\Local\Programs\Python\Python38\courseu\lib\site-packages\django\core\handlers\exception.py", line 55, in inner
    response = get_response(request)
  File "C:\Users\aky\AppData\Local\Programs\Python\Python38\courseu\lib\site-packages\django\core\handlers\base.py", line 197, in _get_response
    response = wrapped_callback(request, *callback_args, **callback_kwargs)
  File "C:\Users\aky\AppData\Local\Programs\Python\Python38\eng_ver\apps\website\admin.py", line 64, in upload_csv
    return render (request, "admin/csv_upload.html")
  File "C:\Users\aky\AppData\Local\Programs\Python\Python38\courseu\lib\site-packages\django\shortcuts.py", line 24, in render
    content = loader.render_to_string(template_name, context, request, using=using)
  File "C:\Users\aky\AppData\Local\Programs\Python\Python38\courseu\lib\site-packages\django\template\loader.py", line 61, in render_to_string
    template = get_template(template_name, using=using)
  File "C:\Users\aky\AppData\Local\Programs\Python\Python38\courseu\lib\site-packages\django\template\loader.py", line 19, in get_template
    raise TemplateDoesNotExist(template_name, chain=chain)
django.template.exceptions.TemplateDoesNotExist: admin/csv_upload.html
ERROR 2023-11-25 18:16:11,852 django.server Thread-7 12800 basehttp basehttp.py 212 django.server log_message 2404 "GET /admin/website/field/upload-csv/ HTTP/1.1" 500 108225
ERROR 2023-11-25 18:16:41,201 django.request Thread-2 648 log log.py 241 django.request log_response 16736 Internal Server Error: /admin/website/field/upload-csv/
Traceback (most recent call last):
  File "C:\Users\aky\AppData\Local\Programs\Python\Python38\courseu\lib\site-packages\django\core\handlers\exception.py", line 55, in inner
    response = get_response(request)
  File "C:\Users\aky\AppData\Local\Programs\Python\Python38\courseu\lib\site-packages\django\core\handlers\base.py", line 197, in _get_response
    response = wrapped_callback(request, *callback_args, **callback_kwargs)
  File "C:\Users\aky\AppData\Local\Programs\Python\Python38\eng_ver\apps\website\admin.py", line 64, in upload_csv
    return render (request, "admin/upload_csv.html")
  File "C:\Users\aky\AppData\Local\Programs\Python\Python38\courseu\lib\site-packages\django\shortcuts.py", line 24, in render
    content = loader.render_to_string(template_name, context, request, using=using)
  File "C:\Users\aky\AppData\Local\Programs\Python\Python38\courseu\lib\site-packages\django\template\loader.py", line 61, in render_to_string
    template = get_template(template_name, using=using)
  File "C:\Users\aky\AppData\Local\Programs\Python\Python38\courseu\lib\site-packages\django\template\loader.py", line 15, in get_template
    return engine.get_template(template_name)
  File "C:\Users\aky\AppData\Local\Programs\Python\Python38\courseu\lib\site-packages\django\template\backends\django.py", line 33, in get_template
    return Template(self.engine.get_template(template_name), self)
  File "C:\Users\aky\AppData\Local\Programs\Python\Python38\courseu\lib\site-packages\django\template\engine.py", line 175, in get_template
    template, origin = self.find_template(template_name)
  File "C:\Users\aky\AppData\Local\Programs\Python\Python38\courseu\lib\site-packages\django\template\engine.py", line 157, in find_template
    template = loader.get_template(name, skip=skip)
  File "C:\Users\aky\AppData\Local\Programs\Python\Python38\courseu\lib\site-packages\django\template\loaders\cached.py", line 57, in get_template
    template = super().get_template(template_name, skip)
  File "C:\Users\aky\AppData\Local\Programs\Python\Python38\courseu\lib\site-packages\django\template\loaders\base.py", line 28, in get_template
    return Template(
  File "C:\Users\aky\AppData\Local\Programs\Python\Python38\courseu\lib\site-packages\django\template\base.py", line 154, in __init__
    self.nodelist = self.compile_nodelist()
  File "C:\Users\aky\AppData\Local\Programs\Python\Python38\courseu\lib\site-packages\django\template\base.py", line 200, in compile_nodelist
    return parser.parse()
  File "C:\Users\aky\AppData\Local\Programs\Python\Python38\courseu\lib\site-packages\django\template\base.py", line 513, in parse
    raise self.error(token, e)
  File "C:\Users\aky\AppData\Local\Programs\Python\Python38\courseu\lib\site-packages\django\template\base.py", line 511, in parse
    compiled_result = compile_func(self, token)
  File "C:\Users\aky\AppData\Local\Programs\Python\Python38\courseu\lib\site-packages\django\template\loader_tags.py", line 293, in do_extends
    nodelist = parser.parse()
  File "C:\Users\aky\AppData\Local\Programs\Python\Python38\courseu\lib\site-packages\django\template\base.py", line 513, in parse
    raise self.error(token, e)
  File "C:\Users\aky\AppData\Local\Programs\Python\Python38\courseu\lib\site-packages\django\template\base.py", line 511, in parse
    compiled_result = compile_func(self, token)
  File "C:\Users\aky\AppData\Local\Programs\Python\Python38\courseu\lib\site-packages\django\template\loader_tags.py", line 232, in do_block
    nodelist = parser.parse(("endblock",))
  File "C:\Users\aky\AppData\Local\Programs\Python\Python38\courseu\lib\site-packages\django\template\base.py", line 513, in parse
    raise self.error(token, e)
  File "C:\Users\aky\AppData\Local\Programs\Python\Python38\courseu\lib\site-packages\django\template\base.py", line 511, in parse
    compiled_result = compile_func(self, token)
  File "C:\Users\aky\AppData\Local\Programs\Python\Python38\courseu\lib\site-packages\django\template\loader_tags.py", line 232, in do_block
    nodelist = parser.parse(("endblock",))
  File "C:\Users\aky\AppData\Local\Programs\Python\Python38\courseu\lib\site-packages\django\template\base.py", line 513, in parse
    raise self.error(token, e)
  File "C:\Users\aky\AppData\Local\Programs\Python\Python38\courseu\lib\site-packages\django\template\base.py", line 511, in parse
    compiled_result = compile_func(self, token)
  File "C:\Users\aky\AppData\Local\Programs\Python\Python38\courseu\lib\site-packages\django\template\defaulttags.py", line 953, in do_if
    nodelist = parser.parse(("elif", "else", "endif"))
  File "C:\Users\aky\AppData\Local\Programs\Python\Python38\courseu\lib\site-packages\django\template\base.py", line 518, in parse
    self.unclosed_block_tag(parse_until)
  File "C:\Users\aky\AppData\Local\Programs\Python\Python38\courseu\lib\site-packages\django\template\base.py", line 581, in unclosed_block_tag
    raise self.error(token, msg)
django.template.exceptions.TemplateSyntaxError: Unclosed tag on line 12: 'if'. Looking for one of: elif, else, endif.
ERROR 2023-11-25 18:16:41,349 django.server Thread-2 648 basehttp basehttp.py 212 django.server log_message 16736 "GET /admin/website/field/upload-csv/ HTTP/1.1" 500 209870
ERROR 2023-11-25 18:47:41,033 django.request Thread-4 9220 log log.py 241 django.request log_response 12188 Internal Server Error: /admin/website/field/upload-csv/
Traceback (most recent call last):
  File "C:\Users\aky\AppData\Local\Programs\Python\Python38\courseu\lib\site-packages\django\db\models\query.py", line 916, in get_or_create
    return self.get(**kwargs), False
  File "C:\Users\aky\AppData\Local\Programs\Python\Python38\courseu\lib\site-packages\django\db\models\query.py", line 637, in get
    raise self.model.DoesNotExist(
apps.website.models.Field.DoesNotExist: Field matching query does not exist.

During handling of the above exception, another exception occurred:

Traceback (most recent call last):
  File "C:\Users\aky\AppData\Local\Programs\Python\Python38\courseu\lib\site-packages\django\db\backends\utils.py", line 89, in _execute
    return self.cursor.execute(sql, params)
  File "C:\Users\aky\AppData\Local\Programs\Python\Python38\courseu\lib\site-packages\psycopg\cursor.py", line 737, in execute
    raise ex.with_traceback(None)
psycopg.errors.UniqueViolation: duplicate key value violates unique constraint "website_field_pkey"
DETAIL:  Key (field)=(1) already exists.

The above exception was the direct cause of the following exception:

Traceback (most recent call last):
  File "C:\Users\aky\AppData\Local\Programs\Python\Python38\courseu\lib\site-packages\django\core\handlers\exception.py", line 55, in inner
    response = get_response(request)
  File "C:\Users\aky\AppData\Local\Programs\Python\Python38\courseu\lib\site-packages\django\core\handlers\base.py", line 197, in _get_response
    response = wrapped_callback(request, *callback_args, **callback_kwargs)
  File "C:\Users\aky\AppData\Local\Programs\Python\Python38\eng_ver\apps\website\admin.py", line 88, in upload_csv
    created = Field.objects.update_or_create(
  File "C:\Users\aky\AppData\Local\Programs\Python\Python38\courseu\lib\site-packages\django\db\models\manager.py", line 87, in manager_method
    return getattr(self.get_queryset(), name)(*args, **kwargs)
  File "C:\Users\aky\AppData\Local\Programs\Python\Python38\courseu\lib\site-packages\django\db\models\query.py", line 949, in update_or_create
    obj, created = self.select_for_update().get_or_create(defaults, **kwargs)
  File "C:\Users\aky\AppData\Local\Programs\Python\Python38\courseu\lib\site-packages\django\db\models\query.py", line 923, in get_or_create
    return self.create(**params), True
  File "C:\Users\aky\AppData\Local\Programs\Python\Python38\courseu\lib\site-packages\django\db\models\query.py", line 658, in create
    obj.save(force_insert=True, using=self.db)
  File "C:\Users\aky\AppData\Local\Programs\Python\Python38\courseu\lib\site-packages\django\db\models\base.py", line 814, in save
    self.save_base(
  File "C:\Users\aky\AppData\Local\Programs\Python\Python38\courseu\lib\site-packages\django\db\models\base.py", line 877, in save_base
    updated = self._save_table(
  File "C:\Users\aky\AppData\Local\Programs\Python\Python38\courseu\lib\site-packages\django\db\models\base.py", line 1020, in _save_table
    results = self._do_insert(
  File "C:\Users\aky\AppData\Local\Programs\Python\Python38\courseu\lib\site-packages\django\db\models\base.py", line 1061, in _do_insert
    return manager._insert(
  File "C:\Users\aky\AppData\Local\Programs\Python\Python38\courseu\lib\site-packages\django\db\models\manager.py", line 87, in manager_method
    return getattr(self.get_queryset(), name)(*args, **kwargs)
  File "C:\Users\aky\AppData\Local\Programs\Python\Python38\courseu\lib\site-packages\django\db\models\query.py", line 1805, in _insert
    return query.get_compiler(using=using).execute_sql(returning_fields)
  File "C:\Users\aky\AppData\Local\Programs\Python\Python38\courseu\lib\site-packages\django\db\models\sql\compiler.py", line 1822, in execute_sql
    cursor.execute(sql, params)
  File "C:\Users\aky\AppData\Local\Programs\Python\Python38\courseu\lib\site-packages\debug_toolbar\panels\sql\tracking.py", line 252, in execute
    return self._record(super().execute, sql, params)
  File "C:\Users\aky\AppData\Local\Programs\Python\Python38\courseu\lib\site-packages\debug_toolbar\panels\sql\tracking.py", line 177, in _record
    return method(sql, params)
  File "C:\Users\aky\AppData\Local\Programs\Python\Python38\courseu\lib\site-packages\django\db\backends\utils.py", line 102, in execute
    return super().execute(sql, params)
  File "C:\Users\aky\AppData\Local\Programs\Python\Python38\courseu\lib\site-packages\django\db\backends\utils.py", line 67, in execute
    return self._execute_with_wrappers(
  File "C:\Users\aky\AppData\Local\Programs\Python\Python38\courseu\lib\site-packages\django\db\backends\utils.py", line 80, in _execute_with_wrappers
    return executor(sql, params, many, context)
  File "C:\Users\aky\AppData\Local\Programs\Python\Python38\courseu\lib\site-packages\django\db\backends\utils.py", line 89, in _execute
    return self.cursor.execute(sql, params)
  File "C:\Users\aky\AppData\Local\Programs\Python\Python38\courseu\lib\site-packages\django\db\utils.py", line 91, in __exit__
    raise dj_exc_value.with_traceback(traceback) from exc_value
  File "C:\Users\aky\AppData\Local\Programs\Python\Python38\courseu\lib\site-packages\django\db\backends\utils.py", line 89, in _execute
    return self.cursor.execute(sql, params)
  File "C:\Users\aky\AppData\Local\Programs\Python\Python38\courseu\lib\site-packages\psycopg\cursor.py", line 737, in execute
    raise ex.with_traceback(None)
django.db.utils.IntegrityError: duplicate key value violates unique constraint "website_field_pkey"
DETAIL:  Key (field)=(1) already exists.
ERROR 2023-11-25 18:47:41,222 django.server Thread-4 9220 basehttp basehttp.py 212 django.server log_message 12188 "POST /admin/website/field/upload-csv/ HTTP/1.1" 500 215846
WARNING 2023-11-25 19:09:08,041 django.request Thread-9 19384 log log.py 241 django.request log_response 15208 Forbidden (Permission denied): /admin/website/field/
Traceback (most recent call last):
  File "C:\Users\aky\AppData\Local\Programs\Python\Python38\courseu\lib\site-packages\django\core\handlers\exception.py", line 55, in inner
    response = get_response(request)
  File "C:\Users\aky\AppData\Local\Programs\Python\Python38\courseu\lib\site-packages\django\core\handlers\base.py", line 197, in _get_response
    response = wrapped_callback(request, *callback_args, **callback_kwargs)
  File "C:\Users\aky\AppData\Local\Programs\Python\Python38\courseu\lib\site-packages\django\contrib\admin\options.py", line 688, in wrapper
    return self.admin_site.admin_view(view)(*args, **kwargs)
  File "C:\Users\aky\AppData\Local\Programs\Python\Python38\courseu\lib\site-packages\django\utils\decorators.py", line 134, in _wrapper_view
    response = view_func(request, *args, **kwargs)
  File "C:\Users\aky\AppData\Local\Programs\Python\Python38\courseu\lib\site-packages\django\views\decorators\cache.py", line 62, in _wrapper_view_func
    response = view_func(request, *args, **kwargs)
  File "C:\Users\aky\AppData\Local\Programs\Python\Python38\courseu\lib\site-packages\django\contrib\admin\sites.py", line 242, in inner
    return view(request, *args, **kwargs)
  File "C:\Users\aky\AppData\Local\Programs\Python\Python38\courseu\lib\site-packages\django\utils\decorators.py", line 46, in _wrapper
    return bound_method(*args, **kwargs)
  File "C:\Users\aky\AppData\Local\Programs\Python\Python38\courseu\lib\site-packages\django\utils\decorators.py", line 134, in _wrapper_view
    response = view_func(request, *args, **kwargs)
  File "C:\Users\aky\AppData\Local\Programs\Python\Python38\courseu\lib\site-packages\django\contrib\admin\options.py", line 1923, in changelist_view
    raise PermissionDenied
django.core.exceptions.PermissionDenied
WARNING 2023-11-25 19:09:08,125 django.server Thread-9 19384 basehttp basehttp.py 212 django.server log_message 15208 "GET /admin/website/field/ HTTP/1.1" 403 9109
ERROR 2023-11-25 19:41:07,359 django.request Thread-5 17256 log log.py 241 django.request log_response 17252 Internal Server Error: /admin/website/specialization/upload-csv/
Traceback (most recent call last):
  File "C:\Users\aky\AppData\Local\Programs\Python\Python38\courseu\lib\site-packages\django\db\models\fields\__init__.py", line 2053, in get_prep_value
    return int(value)
ValueError: invalid literal for int() with base 10: 'Front-End Developers are responsible for creating the user interface and user experience on websites and web applications. They focus on designing and building the visible components that users inter

The above exception was the direct cause of the following exception:

Traceback (most recent call last):
  File "C:\Users\aky\AppData\Local\Programs\Python\Python38\courseu\lib\site-packages\django\core\handlers\exception.py", line 55, in inner
    response = get_response(request)
  File "C:\Users\aky\AppData\Local\Programs\Python\Python38\courseu\lib\site-packages\django\core\handlers\base.py", line 197, in _get_response
    response = wrapped_callback(request, *callback_args, **callback_kwargs)
  File "C:\Users\aky\AppData\Local\Programs\Python\Python38\eng_ver\apps\website\admin.py", line 144, in upload_csv
    created = Specialization.objects.update_or_create(
  File "C:\Users\aky\AppData\Local\Programs\Python\Python38\courseu\lib\site-packages\django\db\models\manager.py", line 87, in manager_method
    return getattr(self.get_queryset(), name)(*args, **kwargs)
  File "C:\Users\aky\AppData\Local\Programs\Python\Python38\courseu\lib\site-packages\django\db\models\query.py", line 949, in update_or_create
    obj, created = self.select_for_update().get_or_create(defaults, **kwargs)
  File "C:\Users\aky\AppData\Local\Programs\Python\Python38\courseu\lib\site-packages\django\db\models\query.py", line 916, in get_or_create
    return self.get(**kwargs), False
  File "C:\Users\aky\AppData\Local\Programs\Python\Python38\courseu\lib\site-packages\django\db\models\query.py", line 623, in get
    clone = self._chain() if self.query.combinator else self.filter(*args, **kwargs)
  File "C:\Users\aky\AppData\Local\Programs\Python\Python38\courseu\lib\site-packages\django\db\models\query.py", line 1436, in filter
    return self._filter_or_exclude(False, args, kwargs)
  File "C:\Users\aky\AppData\Local\Programs\Python\Python38\courseu\lib\site-packages\django\db\models\query.py", line 1454, in _filter_or_exclude
    clone._filter_or_exclude_inplace(negate, args, kwargs)
  File "C:\Users\aky\AppData\Local\Programs\Python\Python38\courseu\lib\site-packages\django\db\models\query.py", line 1461, in _filter_or_exclude_inplace
    self._query.add_q(Q(*args, **kwargs))
  File "C:\Users\aky\AppData\Local\Programs\Python\Python38\courseu\lib\site-packages\django\db\models\sql\query.py", line 1545, in add_q
    clause, _ = self._add_q(q_object, self.used_aliases)
  File "C:\Users\aky\AppData\Local\Programs\Python\Python38\courseu\lib\site-packages\django\db\models\sql\query.py", line 1576, in _add_q
    child_clause, needed_inner = self.build_filter(
  File "C:\Users\aky\AppData\Local\Programs\Python\Python38\courseu\lib\site-packages\django\db\models\sql\query.py", line 1491, in build_filter
    condition = self.build_lookup(lookups, col, value)
  File "C:\Users\aky\AppData\Local\Programs\Python\Python38\courseu\lib\site-packages\django\db\models\sql\query.py", line 1318, in build_lookup
    lookup = lookup_class(lhs, rhs)
  File "C:\Users\aky\AppData\Local\Programs\Python\Python38\courseu\lib\site-packages\django\db\models\lookups.py", line 27, in __init__
    self.rhs = self.get_prep_lookup()
  File "C:\Users\aky\AppData\Local\Programs\Python\Python38\courseu\lib\site-packages\django\db\models\lookups.py", line 341, in get_prep_lookup
    return super().get_prep_lookup()
  File "C:\Users\aky\AppData\Local\Programs\Python\Python38\courseu\lib\site-packages\django\db\models\lookups.py", line 85, in get_prep_lookup
    return self.lhs.output_field.get_prep_value(self.rhs)
  File "C:\Users\aky\AppData\Local\Programs\Python\Python38\courseu\lib\site-packages\django\db\models\fields\__init__.py", line 2055, in get_prep_value
    raise e.__class__(
ValueError: Field 'roadmap_id' expected a number but got 'Front-End Developers are responsible for creating the user interface and user experience on websites and web applications. They focus on designing and building the visible components that users interact with.'.
ERROR 2023-11-25 19:41:07,455 django.server Thread-5 17256 basehttp basehttp.py 212 django.server log_message 17252 "POST /admin/website/specialization/upload-csv/ HTTP/1.1" 500 187237
ERROR 2023-11-25 19:44:20,734 django.request Thread-3 19044 log log.py 241 django.request log_response 12932 Internal Server Error: /admin/website/specialization/upload-csv/
Traceback (most recent call last):
  File "C:\Users\aky\AppData\Local\Programs\Python\Python38\courseu\lib\site-packages\django\db\models\fields\__init__.py", line 2053, in get_prep_value
    return int(value)
ValueError: invalid literal for int() with base 10: 'Front-End Developers are responsible for creating the user interface and user experience on websites and web applications. They focus on designing and building the visible components that users inter

The above exception was the direct cause of the following exception:

Traceback (most recent call last):
  File "C:\Users\aky\AppData\Local\Programs\Python\Python38\courseu\lib\site-packages\django\core\handlers\exception.py", line 55, in inner
    response = get_response(request)
  File "C:\Users\aky\AppData\Local\Programs\Python\Python38\courseu\lib\site-packages\django\core\handlers\base.py", line 197, in _get_response
    response = wrapped_callback(request, *callback_args, **callback_kwargs)
  File "C:\Users\aky\AppData\Local\Programs\Python\Python38\eng_ver\apps\website\admin.py", line 145, in upload_csv
    created = Specialization.objects.update_or_create(
  File "C:\Users\aky\AppData\Local\Programs\Python\Python38\courseu\lib\site-packages\django\db\models\manager.py", line 87, in manager_method
    return getattr(self.get_queryset(), name)(*args, **kwargs)
  File "C:\Users\aky\AppData\Local\Programs\Python\Python38\courseu\lib\site-packages\django\db\models\query.py", line 949, in update_or_create
    obj, created = self.select_for_update().get_or_create(defaults, **kwargs)
  File "C:\Users\aky\AppData\Local\Programs\Python\Python38\courseu\lib\site-packages\django\db\models\query.py", line 916, in get_or_create
    return self.get(**kwargs), False
  File "C:\Users\aky\AppData\Local\Programs\Python\Python38\courseu\lib\site-packages\django\db\models\query.py", line 623, in get
    clone = self._chain() if self.query.combinator else self.filter(*args, **kwargs)
  File "C:\Users\aky\AppData\Local\Programs\Python\Python38\courseu\lib\site-packages\django\db\models\query.py", line 1436, in filter
    return self._filter_or_exclude(False, args, kwargs)
  File "C:\Users\aky\AppData\Local\Programs\Python\Python38\courseu\lib\site-packages\django\db\models\query.py", line 1454, in _filter_or_exclude
    clone._filter_or_exclude_inplace(negate, args, kwargs)
  File "C:\Users\aky\AppData\Local\Programs\Python\Python38\courseu\lib\site-packages\django\db\models\query.py", line 1461, in _filter_or_exclude_inplace
    self._query.add_q(Q(*args, **kwargs))
  File "C:\Users\aky\AppData\Local\Programs\Python\Python38\courseu\lib\site-packages\django\db\models\sql\query.py", line 1545, in add_q
    clause, _ = self._add_q(q_object, self.used_aliases)
  File "C:\Users\aky\AppData\Local\Programs\Python\Python38\courseu\lib\site-packages\django\db\models\sql\query.py", line 1576, in _add_q
    child_clause, needed_inner = self.build_filter(
  File "C:\Users\aky\AppData\Local\Programs\Python\Python38\courseu\lib\site-packages\django\db\models\sql\query.py", line 1491, in build_filter
    condition = self.build_lookup(lookups, col, value)
  File "C:\Users\aky\AppData\Local\Programs\Python\Python38\courseu\lib\site-packages\django\db\models\sql\query.py", line 1318, in build_lookup
    lookup = lookup_class(lhs, rhs)
  File "C:\Users\aky\AppData\Local\Programs\Python\Python38\courseu\lib\site-packages\django\db\models\lookups.py", line 27, in __init__
    self.rhs = self.get_prep_lookup()
  File "C:\Users\aky\AppData\Local\Programs\Python\Python38\courseu\lib\site-packages\django\db\models\lookups.py", line 341, in get_prep_lookup
    return super().get_prep_lookup()
  File "C:\Users\aky\AppData\Local\Programs\Python\Python38\courseu\lib\site-packages\django\db\models\lookups.py", line 85, in get_prep_lookup
    return self.lhs.output_field.get_prep_value(self.rhs)
  File "C:\Users\aky\AppData\Local\Programs\Python\Python38\courseu\lib\site-packages\django\db\models\fields\__init__.py", line 2055, in get_prep_value
    raise e.__class__(
ValueError: Field 'roadmap_id' expected a number but got 'Front-End Developers are responsible for creating the user interface and user experience on websites and web applications. They focus on designing and building the visible components that users interact with.'.
ERROR 2023-11-25 19:44:20,905 django.server Thread-3 19044 basehttp basehttp.py 212 django.server log_message 12932 "POST /admin/website/specialization/upload-csv/ HTTP/1.1" 500 187276
ERROR 2023-11-25 19:48:47,852 django.request Thread-7 19492 log log.py 241 django.request log_response 12932 Internal Server Error: /admin/website/specialization/upload-csv/
Traceback (most recent call last):
  File "C:\Users\aky\AppData\Local\Programs\Python\Python38\courseu\lib\site-packages\django\db\models\fields\__init__.py", line 2053, in get_prep_value
    return int(value)
ValueError: invalid literal for int() with base 10: 'Front-End Developers are responsible for creating the user interface and user experience on websites and web applications. They focus on designing and building the visible components that users inter

The above exception was the direct cause of the following exception:

Traceback (most recent call last):
  File "C:\Users\aky\AppData\Local\Programs\Python\Python38\courseu\lib\site-packages\django\core\handlers\exception.py", line 55, in inner
    response = get_response(request)
  File "C:\Users\aky\AppData\Local\Programs\Python\Python38\courseu\lib\site-packages\django\core\handlers\base.py", line 197, in _get_response
    response = wrapped_callback(request, *callback_args, **callback_kwargs)
  File "C:\Users\aky\AppData\Local\Programs\Python\Python38\eng_ver\apps\website\admin.py", line 145, in upload_csv
    created = Specialization.objects.update_or_create(
  File "C:\Users\aky\AppData\Local\Programs\Python\Python38\courseu\lib\site-packages\django\db\models\manager.py", line 87, in manager_method
    return getattr(self.get_queryset(), name)(*args, **kwargs)
  File "C:\Users\aky\AppData\Local\Programs\Python\Python38\courseu\lib\site-packages\django\db\models\query.py", line 949, in update_or_create
    obj, created = self.select_for_update().get_or_create(defaults, **kwargs)
  File "C:\Users\aky\AppData\Local\Programs\Python\Python38\courseu\lib\site-packages\django\db\models\query.py", line 916, in get_or_create
    return self.get(**kwargs), False
  File "C:\Users\aky\AppData\Local\Programs\Python\Python38\courseu\lib\site-packages\django\db\models\query.py", line 623, in get
    clone = self._chain() if self.query.combinator else self.filter(*args, **kwargs)
  File "C:\Users\aky\AppData\Local\Programs\Python\Python38\courseu\lib\site-packages\django\db\models\query.py", line 1436, in filter
    return self._filter_or_exclude(False, args, kwargs)
  File "C:\Users\aky\AppData\Local\Programs\Python\Python38\courseu\lib\site-packages\django\db\models\query.py", line 1454, in _filter_or_exclude
    clone._filter_or_exclude_inplace(negate, args, kwargs)
  File "C:\Users\aky\AppData\Local\Programs\Python\Python38\courseu\lib\site-packages\django\db\models\query.py", line 1461, in _filter_or_exclude_inplace
    self._query.add_q(Q(*args, **kwargs))
  File "C:\Users\aky\AppData\Local\Programs\Python\Python38\courseu\lib\site-packages\django\db\models\sql\query.py", line 1545, in add_q
    clause, _ = self._add_q(q_object, self.used_aliases)
  File "C:\Users\aky\AppData\Local\Programs\Python\Python38\courseu\lib\site-packages\django\db\models\sql\query.py", line 1576, in _add_q
    child_clause, needed_inner = self.build_filter(
  File "C:\Users\aky\AppData\Local\Programs\Python\Python38\courseu\lib\site-packages\django\db\models\sql\query.py", line 1491, in build_filter
    condition = self.build_lookup(lookups, col, value)
  File "C:\Users\aky\AppData\Local\Programs\Python\Python38\courseu\lib\site-packages\django\db\models\sql\query.py", line 1318, in build_lookup
    lookup = lookup_class(lhs, rhs)
  File "C:\Users\aky\AppData\Local\Programs\Python\Python38\courseu\lib\site-packages\django\db\models\lookups.py", line 27, in __init__
    self.rhs = self.get_prep_lookup()
  File "C:\Users\aky\AppData\Local\Programs\Python\Python38\courseu\lib\site-packages\django\db\models\lookups.py", line 341, in get_prep_lookup
    return super().get_prep_lookup()
  File "C:\Users\aky\AppData\Local\Programs\Python\Python38\courseu\lib\site-packages\django\db\models\lookups.py", line 85, in get_prep_lookup
    return self.lhs.output_field.get_prep_value(self.rhs)
  File "C:\Users\aky\AppData\Local\Programs\Python\Python38\courseu\lib\site-packages\django\db\models\fields\__init__.py", line 2055, in get_prep_value
    raise e.__class__(
ValueError: Field 'roadmap_id' expected a number but got 'Front-End Developers are responsible for creating the user interface and user experience on websites and web applications. They focus on designing and building the visible components that users interact with.'.
ERROR 2023-11-25 19:48:47,931 django.server Thread-7 19492 basehttp basehttp.py 212 django.server log_message 12932 "POST /admin/website/specialization/upload-csv/ HTTP/1.1" 500 187293
ERROR 2023-11-25 19:49:25,058 django.request Thread-3 17928 log log.py 241 django.request log_response 14092 Internal Server Error: /admin/website/specialization/upload-csv/
Traceback (most recent call last):
  File "C:\Users\aky\AppData\Local\Programs\Python\Python38\courseu\lib\site-packages\django\db\models\fields\__init__.py", line 2053, in get_prep_value
    return int(value)
ValueError: invalid literal for int() with base 10: 'Front-End Developers are responsible for creating the user interface and user experience on websites and web applications. They focus on designing and building the visible components that users inter

The above exception was the direct cause of the following exception:

Traceback (most recent call last):
  File "C:\Users\aky\AppData\Local\Programs\Python\Python38\courseu\lib\site-packages\django\core\handlers\exception.py", line 55, in inner
    response = get_response(request)
  File "C:\Users\aky\AppData\Local\Programs\Python\Python38\courseu\lib\site-packages\django\core\handlers\base.py", line 197, in _get_response
    response = wrapped_callback(request, *callback_args, **callback_kwargs)
  File "C:\Users\aky\AppData\Local\Programs\Python\Python38\eng_ver\apps\website\admin.py", line 146, in upload_csv
    created = Specialization.objects.update_or_create(
  File "C:\Users\aky\AppData\Local\Programs\Python\Python38\courseu\lib\site-packages\django\db\models\manager.py", line 87, in manager_method
    return getattr(self.get_queryset(), name)(*args, **kwargs)
  File "C:\Users\aky\AppData\Local\Programs\Python\Python38\courseu\lib\site-packages\django\db\models\query.py", line 949, in update_or_create
    obj, created = self.select_for_update().get_or_create(defaults, **kwargs)
  File "C:\Users\aky\AppData\Local\Programs\Python\Python38\courseu\lib\site-packages\django\db\models\query.py", line 916, in get_or_create
    return self.get(**kwargs), False
  File "C:\Users\aky\AppData\Local\Programs\Python\Python38\courseu\lib\site-packages\django\db\models\query.py", line 623, in get
    clone = self._chain() if self.query.combinator else self.filter(*args, **kwargs)
  File "C:\Users\aky\AppData\Local\Programs\Python\Python38\courseu\lib\site-packages\django\db\models\query.py", line 1436, in filter
    return self._filter_or_exclude(False, args, kwargs)
  File "C:\Users\aky\AppData\Local\Programs\Python\Python38\courseu\lib\site-packages\django\db\models\query.py", line 1454, in _filter_or_exclude
    clone._filter_or_exclude_inplace(negate, args, kwargs)
  File "C:\Users\aky\AppData\Local\Programs\Python\Python38\courseu\lib\site-packages\django\db\models\query.py", line 1461, in _filter_or_exclude_inplace
    self._query.add_q(Q(*args, **kwargs))
  File "C:\Users\aky\AppData\Local\Programs\Python\Python38\courseu\lib\site-packages\django\db\models\sql\query.py", line 1545, in add_q
    clause, _ = self._add_q(q_object, self.used_aliases)
  File "C:\Users\aky\AppData\Local\Programs\Python\Python38\courseu\lib\site-packages\django\db\models\sql\query.py", line 1576, in _add_q
    child_clause, needed_inner = self.build_filter(
  File "C:\Users\aky\AppData\Local\Programs\Python\Python38\courseu\lib\site-packages\django\db\models\sql\query.py", line 1491, in build_filter
    condition = self.build_lookup(lookups, col, value)
  File "C:\Users\aky\AppData\Local\Programs\Python\Python38\courseu\lib\site-packages\django\db\models\sql\query.py", line 1318, in build_lookup
    lookup = lookup_class(lhs, rhs)
  File "C:\Users\aky\AppData\Local\Programs\Python\Python38\courseu\lib\site-packages\django\db\models\lookups.py", line 27, in __init__
    self.rhs = self.get_prep_lookup()
  File "C:\Users\aky\AppData\Local\Programs\Python\Python38\courseu\lib\site-packages\django\db\models\lookups.py", line 341, in get_prep_lookup
    return super().get_prep_lookup()
  File "C:\Users\aky\AppData\Local\Programs\Python\Python38\courseu\lib\site-packages\django\db\models\lookups.py", line 85, in get_prep_lookup
    return self.lhs.output_field.get_prep_value(self.rhs)
  File "C:\Users\aky\AppData\Local\Programs\Python\Python38\courseu\lib\site-packages\django\db\models\fields\__init__.py", line 2055, in get_prep_value
    raise e.__class__(
ValueError: Field 'roadmap_id' expected a number but got 'Front-End Developers are responsible for creating the user interface and user experience on websites and web applications. They focus on designing and building the visible components that users interact with.'.
ERROR 2023-11-25 19:49:25,280 django.server Thread-3 17928 basehttp basehttp.py 212 django.server log_message 14092 "POST /admin/website/specialization/upload-csv/ HTTP/1.1" 500 187242
ERROR 2023-11-25 19:50:19,252 django.request Thread-1 2960 log log.py 241 django.request log_response 19280 Internal Server Error: /admin/website/specialization/upload-csv/
Traceback (most recent call last):
  File "C:\Users\aky\AppData\Local\Programs\Python\Python38\courseu\lib\site-packages\django\core\handlers\exception.py", line 55, in inner
    response = get_response(request)
  File "C:\Users\aky\AppData\Local\Programs\Python\Python38\courseu\lib\site-packages\django\core\handlers\base.py", line 197, in _get_response
    response = wrapped_callback(request, *callback_args, **callback_kwargs)
  File "C:\Users\aky\AppData\Local\Programs\Python\Python38\eng_ver\apps\website\admin.py", line 141, in upload_csv
    print("Specializatin Object fields:", Specialization._meta.get_fields().values_list('name', flat=True))
AttributeError: 'ImmutableList' object has no attribute 'values_list'
ERROR 2023-11-25 19:50:19,338 django.server Thread-1 2960 basehttp basehttp.py 212 django.server log_message 19280 "POST /admin/website/specialization/upload-csv/ HTTP/1.1" 500 104706
ERROR 2023-11-25 19:50:48,320 django.request Thread-6 9632 log log.py 241 django.request log_response 19280 Internal Server Error: /admin/website/specialization/upload-csv/
Traceback (most recent call last):
  File "C:\Users\aky\AppData\Local\Programs\Python\Python38\courseu\lib\site-packages\django\core\handlers\exception.py", line 55, in inner
    response = get_response(request)
  File "C:\Users\aky\AppData\Local\Programs\Python\Python38\courseu\lib\site-packages\django\core\handlers\base.py", line 197, in _get_response
    response = wrapped_callback(request, *callback_args, **callback_kwargs)
  File "C:\Users\aky\AppData\Local\Programs\Python\Python38\eng_ver\apps\website\admin.py", line 141, in upload_csv
    print("Specializatin Object fields:", Specialization._meta.get_fields().values_list('name', flat=True))
AttributeError: 'ImmutableList' object has no attribute 'values_list'
ERROR 2023-11-25 19:50:48,379 django.server Thread-6 9632 basehttp basehttp.py 212 django.server log_message 19280 "POST /admin/website/specialization/upload-csv/ HTTP/1.1" 500 104706
ERROR 2023-11-25 19:51:50,465 django.request Thread-1 14316 log log.py 241 django.request log_response 9768 Internal Server Error: /admin/website/specialization/upload-csv/
Traceback (most recent call last):
  File "C:\Users\aky\AppData\Local\Programs\Python\Python38\courseu\lib\site-packages\django\db\models\fields\__init__.py", line 2053, in get_prep_value
    return int(value)
ValueError: invalid literal for int() with base 10: 'Front-End Developers are responsible for creating the user interface and user experience on websites and web applications. They focus on designing and building the visible components that users inter

The above exception was the direct cause of the following exception:

Traceback (most recent call last):
  File "C:\Users\aky\AppData\Local\Programs\Python\Python38\courseu\lib\site-packages\django\core\handlers\exception.py", line 55, in inner
    response = get_response(request)
  File "C:\Users\aky\AppData\Local\Programs\Python\Python38\courseu\lib\site-packages\django\core\handlers\base.py", line 197, in _get_response
    response = wrapped_callback(request, *callback_args, **callback_kwargs)
  File "C:\Users\aky\AppData\Local\Programs\Python\Python38\eng_ver\apps\website\admin.py", line 146, in upload_csv
    created = Specialization.objects.update_or_create(
  File "C:\Users\aky\AppData\Local\Programs\Python\Python38\courseu\lib\site-packages\django\db\models\manager.py", line 87, in manager_method
    return getattr(self.get_queryset(), name)(*args, **kwargs)
  File "C:\Users\aky\AppData\Local\Programs\Python\Python38\courseu\lib\site-packages\django\db\models\query.py", line 949, in update_or_create
    obj, created = self.select_for_update().get_or_create(defaults, **kwargs)
  File "C:\Users\aky\AppData\Local\Programs\Python\Python38\courseu\lib\site-packages\django\db\models\query.py", line 916, in get_or_create
    return self.get(**kwargs), False
  File "C:\Users\aky\AppData\Local\Programs\Python\Python38\courseu\lib\site-packages\django\db\models\query.py", line 623, in get
    clone = self._chain() if self.query.combinator else self.filter(*args, **kwargs)
  File "C:\Users\aky\AppData\Local\Programs\Python\Python38\courseu\lib\site-packages\django\db\models\query.py", line 1436, in filter
    return self._filter_or_exclude(False, args, kwargs)
  File "C:\Users\aky\AppData\Local\Programs\Python\Python38\courseu\lib\site-packages\django\db\models\query.py", line 1454, in _filter_or_exclude
    clone._filter_or_exclude_inplace(negate, args, kwargs)
  File "C:\Users\aky\AppData\Local\Programs\Python\Python38\courseu\lib\site-packages\django\db\models\query.py", line 1461, in _filter_or_exclude_inplace
    self._query.add_q(Q(*args, **kwargs))
  File "C:\Users\aky\AppData\Local\Programs\Python\Python38\courseu\lib\site-packages\django\db\models\sql\query.py", line 1545, in add_q
    clause, _ = self._add_q(q_object, self.used_aliases)
  File "C:\Users\aky\AppData\Local\Programs\Python\Python38\courseu\lib\site-packages\django\db\models\sql\query.py", line 1576, in _add_q
    child_clause, needed_inner = self.build_filter(
  File "C:\Users\aky\AppData\Local\Programs\Python\Python38\courseu\lib\site-packages\django\db\models\sql\query.py", line 1491, in build_filter
    condition = self.build_lookup(lookups, col, value)
  File "C:\Users\aky\AppData\Local\Programs\Python\Python38\courseu\lib\site-packages\django\db\models\sql\query.py", line 1318, in build_lookup
    lookup = lookup_class(lhs, rhs)
  File "C:\Users\aky\AppData\Local\Programs\Python\Python38\courseu\lib\site-packages\django\db\models\lookups.py", line 27, in __init__
    self.rhs = self.get_prep_lookup()
  File "C:\Users\aky\AppData\Local\Programs\Python\Python38\courseu\lib\site-packages\django\db\models\lookups.py", line 341, in get_prep_lookup
    return super().get_prep_lookup()
  File "C:\Users\aky\AppData\Local\Programs\Python\Python38\courseu\lib\site-packages\django\db\models\lookups.py", line 85, in get_prep_lookup
    return self.lhs.output_field.get_prep_value(self.rhs)
  File "C:\Users\aky\AppData\Local\Programs\Python\Python38\courseu\lib\site-packages\django\db\models\fields\__init__.py", line 2055, in get_prep_value
    raise e.__class__(
ValueError: Field 'roadmap_id' expected a number but got 'Front-End Developers are responsible for creating the user interface and user experience on websites and web applications. They focus on designing and building the visible components that users interact with.'.
ERROR 2023-11-25 19:51:50,630 django.server Thread-1 14316 basehttp basehttp.py 212 django.server log_message 9768 "POST /admin/website/specialization/upload-csv/ HTTP/1.1" 500 187242
ERROR 2023-11-25 19:53:22,217 django.request Thread-7 1040 log log.py 241 django.request log_response 14788 Internal Server Error: /admin/website/specialization/upload-csv/
Traceback (most recent call last):
  File "C:\Users\aky\AppData\Local\Programs\Python\Python38\courseu\lib\site-packages\django\db\models\fields\__init__.py", line 2053, in get_prep_value
    return int(value)
ValueError: invalid literal for int() with base 10: 'Front-End Developers are responsible for creating the user interface and user experience on websites and web applications. They focus on designing and building the visible components that users inter

The above exception was the direct cause of the following exception:

Traceback (most recent call last):
  File "C:\Users\aky\AppData\Local\Programs\Python\Python38\courseu\lib\site-packages\django\core\handlers\exception.py", line 55, in inner
    response = get_response(request)
  File "C:\Users\aky\AppData\Local\Programs\Python\Python38\courseu\lib\site-packages\django\core\handlers\base.py", line 197, in _get_response
    response = wrapped_callback(request, *callback_args, **callback_kwargs)
  File "C:\Users\aky\AppData\Local\Programs\Python\Python38\eng_ver\apps\website\admin.py", line 146, in upload_csv
    created = Specialization.objects.update_or_create(
  File "C:\Users\aky\AppData\Local\Programs\Python\Python38\courseu\lib\site-packages\django\db\models\manager.py", line 87, in manager_method
    return getattr(self.get_queryset(), name)(*args, **kwargs)
  File "C:\Users\aky\AppData\Local\Programs\Python\Python38\courseu\lib\site-packages\django\db\models\query.py", line 949, in update_or_create
    obj, created = self.select_for_update().get_or_create(defaults, **kwargs)
  File "C:\Users\aky\AppData\Local\Programs\Python\Python38\courseu\lib\site-packages\django\db\models\query.py", line 916, in get_or_create
    return self.get(**kwargs), False
  File "C:\Users\aky\AppData\Local\Programs\Python\Python38\courseu\lib\site-packages\django\db\models\query.py", line 623, in get
    clone = self._chain() if self.query.combinator else self.filter(*args, **kwargs)
  File "C:\Users\aky\AppData\Local\Programs\Python\Python38\courseu\lib\site-packages\django\db\models\query.py", line 1436, in filter
    return self._filter_or_exclude(False, args, kwargs)
  File "C:\Users\aky\AppData\Local\Programs\Python\Python38\courseu\lib\site-packages\django\db\models\query.py", line 1454, in _filter_or_exclude
    clone._filter_or_exclude_inplace(negate, args, kwargs)
  File "C:\Users\aky\AppData\Local\Programs\Python\Python38\courseu\lib\site-packages\django\db\models\query.py", line 1461, in _filter_or_exclude_inplace
    self._query.add_q(Q(*args, **kwargs))
  File "C:\Users\aky\AppData\Local\Programs\Python\Python38\courseu\lib\site-packages\django\db\models\sql\query.py", line 1545, in add_q
    clause, _ = self._add_q(q_object, self.used_aliases)
  File "C:\Users\aky\AppData\Local\Programs\Python\Python38\courseu\lib\site-packages\django\db\models\sql\query.py", line 1576, in _add_q
    child_clause, needed_inner = self.build_filter(
  File "C:\Users\aky\AppData\Local\Programs\Python\Python38\courseu\lib\site-packages\django\db\models\sql\query.py", line 1491, in build_filter
    condition = self.build_lookup(lookups, col, value)
  File "C:\Users\aky\AppData\Local\Programs\Python\Python38\courseu\lib\site-packages\django\db\models\sql\query.py", line 1318, in build_lookup
    lookup = lookup_class(lhs, rhs)
  File "C:\Users\aky\AppData\Local\Programs\Python\Python38\courseu\lib\site-packages\django\db\models\lookups.py", line 27, in __init__
    self.rhs = self.get_prep_lookup()
  File "C:\Users\aky\AppData\Local\Programs\Python\Python38\courseu\lib\site-packages\django\db\models\lookups.py", line 341, in get_prep_lookup
    return super().get_prep_lookup()
  File "C:\Users\aky\AppData\Local\Programs\Python\Python38\courseu\lib\site-packages\django\db\models\lookups.py", line 85, in get_prep_lookup
    return self.lhs.output_field.get_prep_value(self.rhs)
  File "C:\Users\aky\AppData\Local\Programs\Python\Python38\courseu\lib\site-packages\django\db\models\fields\__init__.py", line 2055, in get_prep_value
    raise e.__class__(
ValueError: Field 'roadmap_id' expected a number but got 'Front-End Developers are responsible for creating the user interface and user experience on websites and web applications. They focus on designing and building the visible components that users interact with.'.
ERROR 2023-11-25 19:53:22,275 django.server Thread-7 1040 basehttp basehttp.py 212 django.server log_message 14788 "POST /admin/website/specialization/upload-csv/ HTTP/1.1" 500 187605
ERROR 2023-11-25 19:59:06,573 django.request Thread-4 14876 log log.py 241 django.request log_response 5440 Internal Server Error: /admin/website/specialization/upload-csv/
Traceback (most recent call last):
  File "C:\Users\aky\AppData\Local\Programs\Python\Python38\courseu\lib\site-packages\django\core\handlers\exception.py", line 55, in inner
    response = get_response(request)
  File "C:\Users\aky\AppData\Local\Programs\Python\Python38\courseu\lib\site-packages\django\core\handlers\base.py", line 197, in _get_response
    response = wrapped_callback(request, *callback_args, **callback_kwargs)
  File "C:\Users\aky\AppData\Local\Programs\Python\Python38\eng_ver\apps\website\admin.py", line 141, in upload_csv
    specicalization_id=row['specicalization_id'],
KeyError: 'specicalization_id'
ERROR 2023-11-25 19:59:06,636 django.server Thread-4 14876 basehttp basehttp.py 212 django.server log_message 5440 "POST /admin/website/specialization/upload-csv/ HTTP/1.1" 500 95454
ERROR 2023-11-25 20:00:23,774 django.request Thread-1 19316 log log.py 241 django.request log_response 16172 Internal Server Error: /admin/website/specialization/upload-csv/
Traceback (most recent call last):
  File "C:\Users\aky\AppData\Local\Programs\Python\Python38\courseu\lib\site-packages\django\core\handlers\exception.py", line 55, in inner
    response = get_response(request)
  File "C:\Users\aky\AppData\Local\Programs\Python\Python38\courseu\lib\site-packages\django\core\handlers\base.py", line 197, in _get_response
    response = wrapped_callback(request, *callback_args, **callback_kwargs)
  File "C:\Users\aky\AppData\Local\Programs\Python\Python38\eng_ver\apps\website\admin.py", line 140, in upload_csv
    created = Specialization.objects.update_or_create(
  File "C:\Users\aky\AppData\Local\Programs\Python\Python38\courseu\lib\site-packages\django\db\models\manager.py", line 87, in manager_method
    return getattr(self.get_queryset(), name)(*args, **kwargs)
  File "C:\Users\aky\AppData\Local\Programs\Python\Python38\courseu\lib\site-packages\django\db\models\query.py", line 949, in update_or_create
    obj, created = self.select_for_update().get_or_create(defaults, **kwargs)
  File "C:\Users\aky\AppData\Local\Programs\Python\Python38\courseu\lib\site-packages\django\db\models\query.py", line 916, in get_or_create
    return self.get(**kwargs), False
  File "C:\Users\aky\AppData\Local\Programs\Python\Python38\courseu\lib\site-packages\django\db\models\query.py", line 623, in get
    clone = self._chain() if self.query.combinator else self.filter(*args, **kwargs)
  File "C:\Users\aky\AppData\Local\Programs\Python\Python38\courseu\lib\site-packages\django\db\models\query.py", line 1436, in filter
    return self._filter_or_exclude(False, args, kwargs)
  File "C:\Users\aky\AppData\Local\Programs\Python\Python38\courseu\lib\site-packages\django\db\models\query.py", line 1454, in _filter_or_exclude
    clone._filter_or_exclude_inplace(negate, args, kwargs)
  File "C:\Users\aky\AppData\Local\Programs\Python\Python38\courseu\lib\site-packages\django\db\models\query.py", line 1461, in _filter_or_exclude_inplace
    self._query.add_q(Q(*args, **kwargs))
  File "C:\Users\aky\AppData\Local\Programs\Python\Python38\courseu\lib\site-packages\django\db\models\sql\query.py", line 1545, in add_q
    clause, _ = self._add_q(q_object, self.used_aliases)
  File "C:\Users\aky\AppData\Local\Programs\Python\Python38\courseu\lib\site-packages\django\db\models\sql\query.py", line 1576, in _add_q
    child_clause, needed_inner = self.build_filter(
  File "C:\Users\aky\AppData\Local\Programs\Python\Python38\courseu\lib\site-packages\django\db\models\sql\query.py", line 1426, in build_filter
    lookups, parts, reffed_expression = self.solve_lookup_type(arg, summarize)
  File "C:\Users\aky\AppData\Local\Programs\Python\Python38\courseu\lib\site-packages\django\db\models\sql\query.py", line 1236, in solve_lookup_type
    _, field, _, lookup_parts = self.names_to_path(lookup_splitted, self.get_meta())
  File "C:\Users\aky\AppData\Local\Programs\Python\Python38\courseu\lib\site-packages\django\db\models\sql\query.py", line 1724, in names_to_path
    raise FieldError(
django.core.exceptions.FieldError: Cannot resolve keyword 'specicalization_id' into field. Choices are: description, field, field_id, roadmap_id, specialization_id, specializationskills, title
ERROR 2023-11-25 20:00:23,956 django.server Thread-1 19316 basehttp basehttp.py 212 django.server log_message 16172 "POST /admin/website/specialization/upload-csv/ HTTP/1.1" 500 157156
ERROR 2023-11-25 20:03:04,293 django.request Thread-1 3260 log log.py 241 django.request log_response 12200 Internal Server Error: /admin/website/specialization/upload-csv/
Traceback (most recent call last):
  File "C:\Users\aky\AppData\Local\Programs\Python\Python38\courseu\lib\site-packages\django\db\backends\base\base.py", line 313, in _commit
    return self.connection.commit()
  File "C:\Users\aky\AppData\Local\Programs\Python\Python38\courseu\lib\site-packages\psycopg\connection.py", line 908, in commit
    self.wait(self._commit_gen())
  File "C:\Users\aky\AppData\Local\Programs\Python\Python38\courseu\lib\site-packages\psycopg\connection.py", line 981, in wait
    return waiting.wait(gen, self.pgconn.socket, timeout=timeout)
  File "C:\Users\aky\AppData\Local\Programs\Python\Python38\courseu\lib\site-packages\psycopg\waiting.py", line 244, in wait_select
    s = gen.send(ready)  # type: ignore
  File "C:\Users\aky\AppData\Local\Programs\Python\Python38\courseu\lib\site-packages\psycopg\connection.py", line 545, in _commit_gen
    yield from self._exec_command(b"COMMIT")
  File "C:\Users\aky\AppData\Local\Programs\Python\Python38\courseu\lib\site-packages\psycopg\connection.py", line 479, in _exec_command
    raise e.error_from_result(result, encoding=pgconn_encoding(self.pgconn))
psycopg.errors.ForeignKeyViolation: insert or update on table "website_specialization" violates foreign key constraint "website_specialization_field_id_1d177bf3_fk_website_field_field"
DETAIL:  Key (field_id)=(3) is not present in table "website_field".

The above exception was the direct cause of the following exception:

Traceback (most recent call last):
  File "C:\Users\aky\AppData\Local\Programs\Python\Python38\courseu\lib\site-packages\django\core\handlers\exception.py", line 55, in inner
    response = get_response(request)
  File "C:\Users\aky\AppData\Local\Programs\Python\Python38\courseu\lib\site-packages\django\core\handlers\base.py", line 197, in _get_response
    response = wrapped_callback(request, *callback_args, **callback_kwargs)
  File "C:\Users\aky\AppData\Local\Programs\Python\Python38\eng_ver\apps\website\admin.py", line 140, in upload_csv
    created = Specialization.objects.update_or_create(
  File "C:\Users\aky\AppData\Local\Programs\Python\Python38\courseu\lib\site-packages\django\db\models\manager.py", line 87, in manager_method
    return getattr(self.get_queryset(), name)(*args, **kwargs)
  File "C:\Users\aky\AppData\Local\Programs\Python\Python38\courseu\lib\site-packages\django\db\models\query.py", line 951, in update_or_create
    return obj, created
  File "C:\Users\aky\AppData\Local\Programs\Python\Python38\courseu\lib\site-packages\django\db\transaction.py", line 263, in __exit__
    connection.commit()
  File "C:\Users\aky\AppData\Local\Programs\Python\Python38\courseu\lib\site-packages\django\utils\asyncio.py", line 26, in inner
    return func(*args, **kwargs)
  File "C:\Users\aky\AppData\Local\Programs\Python\Python38\courseu\lib\site-packages\django\db\backends\base\base.py", line 337, in commit
    self._commit()
  File "C:\Users\aky\AppData\Local\Programs\Python\Python38\courseu\lib\site-packages\django\db\backends\base\base.py", line 313, in _commit
    return self.connection.commit()
  File "C:\Users\aky\AppData\Local\Programs\Python\Python38\courseu\lib\site-packages\django\db\utils.py", line 91, in __exit__
    raise dj_exc_value.with_traceback(traceback) from exc_value
  File "C:\Users\aky\AppData\Local\Programs\Python\Python38\courseu\lib\site-packages\django\db\backends\base\base.py", line 313, in _commit
    return self.connection.commit()
  File "C:\Users\aky\AppData\Local\Programs\Python\Python38\courseu\lib\site-packages\psycopg\connection.py", line 908, in commit
    self.wait(self._commit_gen())
  File "C:\Users\aky\AppData\Local\Programs\Python\Python38\courseu\lib\site-packages\psycopg\connection.py", line 981, in wait
    return waiting.wait(gen, self.pgconn.socket, timeout=timeout)
  File "C:\Users\aky\AppData\Local\Programs\Python\Python38\courseu\lib\site-packages\psycopg\waiting.py", line 244, in wait_select
    s = gen.send(ready)  # type: ignore
  File "C:\Users\aky\AppData\Local\Programs\Python\Python38\courseu\lib\site-packages\psycopg\connection.py", line 545, in _commit_gen
    yield from self._exec_command(b"COMMIT")
  File "C:\Users\aky\AppData\Local\Programs\Python\Python38\courseu\lib\site-packages\psycopg\connection.py", line 479, in _exec_command
    raise e.error_from_result(result, encoding=pgconn_encoding(self.pgconn))
django.db.utils.IntegrityError: insert or update on table "website_specialization" violates foreign key constraint "website_specialization_field_id_1d177bf3_fk_website_field_field"
DETAIL:  Key (field_id)=(3) is not present in table "website_field".
ERROR 2023-11-25 20:03:04,659 django.server Thread-1 3260 basehttp basehttp.py 212 django.server log_message 12200 "POST /admin/website/specialization/upload-csv/ HTTP/1.1" 500 178725
WARNING 2023-11-25 20:20:59,494 django.request Thread-10 4508 log log.py 241 django.request log_response 19444 Not Found: /home/
WARNING 2023-11-25 20:20:59,497 django.server Thread-10 4508 basehttp basehttp.py 212 django.server log_message 19444 "GET /home/ HTTP/1.1" 404 26066
ERROR 2023-11-25 20:34:07,768 django.request Thread-1 17568 log log.py 241 django.request log_response 5124 Internal Server Error: /admin/assessment/test/upload-csv/
Traceback (most recent call last):
  File "C:\Users\aky\AppData\Local\Programs\Python\Python38\courseu\lib\site-packages\django\core\handlers\exception.py", line 55, in inner
    response = get_response(request)
  File "C:\Users\aky\AppData\Local\Programs\Python\Python38\courseu\lib\site-packages\django\core\handlers\base.py", line 197, in _get_response
    response = wrapped_callback(request, *callback_args, **callback_kwargs)
  File "C:\Users\aky\AppData\Local\Programs\Python\Python38\eng_ver\apps\assessment\admin.py", line 46, in upload_csv
    created = Field.objects.update_or_create(
NameError: name 'Field' is not defined
ERROR 2023-11-25 20:34:07,807 django.server Thread-1 17568 basehttp basehttp.py 212 django.server log_message 5124 "POST /admin/assessment/test/upload-csv/ HTTP/1.1" 500 95091
ERROR 2023-11-25 20:37:28,056 django.request Thread-1 9456 log log.py 241 django.request log_response 8952 Internal Server Error: /select_year/1/
Traceback (most recent call last):
  File "C:\Users\aky\AppData\Local\Programs\Python\Python38\courseu\lib\site-packages\django\core\handlers\exception.py", line 55, in inner
    response = get_response(request)
  File "C:\Users\aky\AppData\Local\Programs\Python\Python38\courseu\lib\site-packages\django\core\handlers\base.py", line 197, in _get_response
    response = wrapped_callback(request, *callback_args, **callback_kwargs)
  File "C:\Users\aky\AppData\Local\Programs\Python\Python38\eng_ver\apps\acad\views.py", line 18, in select_year
    course = Course.objects.get(pk=course_id)
  File "C:\Users\aky\AppData\Local\Programs\Python\Python38\courseu\lib\site-packages\django\db\models\manager.py", line 87, in manager_method
    return getattr(self.get_queryset(), name)(*args, **kwargs)
  File "C:\Users\aky\AppData\Local\Programs\Python\Python38\courseu\lib\site-packages\django\db\models\query.py", line 637, in get
    raise self.model.DoesNotExist(
apps.acad.models.Course.DoesNotExist: Course matching query does not exist.
ERROR 2023-11-25 20:37:28,109 django.server Thread-1 9456 basehttp basehttp.py 212 django.server log_message 8952 "GET /select_year/1/ HTTP/1.1" 500 100687
ERROR 2023-11-25 21:57:51,990 django.request Thread-1 1624 log log.py 241 django.request log_response 18068 Internal Server Error: /admin/acad/subject/upload-csv/
Traceback (most recent call last):
  File "C:\Users\aky\AppData\Local\Programs\Python\Python38\courseu\lib\site-packages\django\core\handlers\exception.py", line 55, in inner
    response = get_response(request)
  File "C:\Users\aky\AppData\Local\Programs\Python\Python38\courseu\lib\site-packages\django\core\handlers\base.py", line 197, in _get_response
    response = wrapped_callback(request, *callback_args, **callback_kwargs)
  File "C:\Users\aky\AppData\Local\Programs\Python\Python38\eng_ver\apps\acad\admin.py", line 50, in upload_csv
    form = CsvImportForm()
NameError: name 'CsvImportForm' is not defined
ERROR 2023-11-25 21:57:52,161 django.request Thread-2 12840 log log.py 241 django.request log_response 18068 Internal Server Error: /admin/acad/subject/upload-csv/
Traceback (most recent call last):
  File "C:\Users\aky\AppData\Local\Programs\Python\Python38\courseu\lib\site-packages\django\core\handlers\exception.py", line 55, in inner
    response = get_response(request)
  File "C:\Users\aky\AppData\Local\Programs\Python\Python38\courseu\lib\site-packages\django\core\handlers\base.py", line 197, in _get_response
    response = wrapped_callback(request, *callback_args, **callback_kwargs)
  File "C:\Users\aky\AppData\Local\Programs\Python\Python38\eng_ver\apps\acad\admin.py", line 50, in upload_csv
    form = CsvImportForm()
NameError: name 'CsvImportForm' is not defined
ERROR 2023-11-25 21:57:52,199 django.server Thread-2 12840 basehttp basehttp.py 212 django.server log_message 18068 "GET /admin/acad/subject/upload-csv/ HTTP/1.1" 500 92565
ERROR 2023-11-25 22:07:52,557 django.request Thread-1 2316 log log.py 241 django.request log_response 1084 Internal Server Error: /admin/jobs/jobposting/
Traceback (most recent call last):
  File "C:\Users\aky\AppData\Local\Programs\Python\Python38\courseu\lib\site-packages\django\db\backends\utils.py", line 89, in _execute
    return self.cursor.execute(sql, params)
  File "C:\Users\aky\AppData\Local\Programs\Python\Python38\courseu\lib\site-packages\psycopg\cursor.py", line 737, in execute
    raise ex.with_traceback(None)
psycopg.errors.UndefinedColumn: column jobs_jobposting.field_id does not exist
LINE 1: ..._jobposting"."link", "jobs_jobposting"."keyword", "jobs_jobp...
                                                             ^

The above exception was the direct cause of the following exception:

Traceback (most recent call last):
  File "C:\Users\aky\AppData\Local\Programs\Python\Python38\courseu\lib\site-packages\django\core\handlers\exception.py", line 55, in inner
    response = get_response(request)
  File "C:\Users\aky\AppData\Local\Programs\Python\Python38\courseu\lib\site-packages\django\core\handlers\base.py", line 197, in _get_response
    response = wrapped_callback(request, *callback_args, **callback_kwargs)
  File "C:\Users\aky\AppData\Local\Programs\Python\Python38\courseu\lib\site-packages\django\contrib\admin\options.py", line 688, in wrapper
    return self.admin_site.admin_view(view)(*args, **kwargs)
  File "C:\Users\aky\AppData\Local\Programs\Python\Python38\courseu\lib\site-packages\django\utils\decorators.py", line 134, in _wrapper_view
    response = view_func(request, *args, **kwargs)
  File "C:\Users\aky\AppData\Local\Programs\Python\Python38\courseu\lib\site-packages\django\views\decorators\cache.py", line 62, in _wrapper_view_func
    response = view_func(request, *args, **kwargs)
  File "C:\Users\aky\AppData\Local\Programs\Python\Python38\courseu\lib\site-packages\django\contrib\admin\sites.py", line 242, in inner
    return view(request, *args, **kwargs)
  File "C:\Users\aky\AppData\Local\Programs\Python\Python38\courseu\lib\site-packages\django\utils\decorators.py", line 46, in _wrapper
    return bound_method(*args, **kwargs)
  File "C:\Users\aky\AppData\Local\Programs\Python\Python38\courseu\lib\site-packages\django\utils\decorators.py", line 134, in _wrapper_view
    response = view_func(request, *args, **kwargs)
  File "C:\Users\aky\AppData\Local\Programs\Python\Python38\courseu\lib\site-packages\django\contrib\admin\options.py", line 2065, in changelist_view
    "selection_note": _("0 of %(cnt)s selected") % {"cnt": len(cl.result_list)},
  File "C:\Users\aky\AppData\Local\Programs\Python\Python38\courseu\lib\site-packages\django\db\models\query.py", line 380, in __len__
    self._fetch_all()
  File "C:\Users\aky\AppData\Local\Programs\Python\Python38\courseu\lib\site-packages\django\db\models\query.py", line 1881, in _fetch_all
    self._result_cache = list(self._iterable_class(self))
  File "C:\Users\aky\AppData\Local\Programs\Python\Python38\courseu\lib\site-packages\django\db\models\query.py", line 91, in __iter__
    results = compiler.execute_sql(
  File "C:\Users\aky\AppData\Local\Programs\Python\Python38\courseu\lib\site-packages\django\db\models\sql\compiler.py", line 1562, in execute_sql
    cursor.execute(sql, params)
  File "C:\Users\aky\AppData\Local\Programs\Python\Python38\courseu\lib\site-packages\debug_toolbar\panels\sql\tracking.py", line 252, in execute
    return self._record(super().execute, sql, params)
  File "C:\Users\aky\AppData\Local\Programs\Python\Python38\courseu\lib\site-packages\debug_toolbar\panels\sql\tracking.py", line 177, in _record
    return method(sql, params)
  File "C:\Users\aky\AppData\Local\Programs\Python\Python38\courseu\lib\site-packages\django\db\backends\utils.py", line 102, in execute
    return super().execute(sql, params)
  File "C:\Users\aky\AppData\Local\Programs\Python\Python38\courseu\lib\site-packages\django\db\backends\utils.py", line 67, in execute
    return self._execute_with_wrappers(
  File "C:\Users\aky\AppData\Local\Programs\Python\Python38\courseu\lib\site-packages\django\db\backends\utils.py", line 80, in _execute_with_wrappers
    return executor(sql, params, many, context)
  File "C:\Users\aky\AppData\Local\Programs\Python\Python38\courseu\lib\site-packages\django\db\backends\utils.py", line 89, in _execute
    return self.cursor.execute(sql, params)
  File "C:\Users\aky\AppData\Local\Programs\Python\Python38\courseu\lib\site-packages\django\db\utils.py", line 91, in __exit__
    raise dj_exc_value.with_traceback(traceback) from exc_value
  File "C:\Users\aky\AppData\Local\Programs\Python\Python38\courseu\lib\site-packages\django\db\backends\utils.py", line 89, in _execute
    return self.cursor.execute(sql, params)
  File "C:\Users\aky\AppData\Local\Programs\Python\Python38\courseu\lib\site-packages\psycopg\cursor.py", line 737, in execute
    raise ex.with_traceback(None)
django.db.utils.ProgrammingError: column jobs_jobposting.field_id does not exist
LINE 1: ..._jobposting"."link", "jobs_jobposting"."keyword", "jobs_jobp...
                                                             ^
ERROR 2023-11-25 22:07:52,659 django.server Thread-1 2316 basehttp basehttp.py 212 django.server log_message 1084 "GET /admin/jobs/jobposting/ HTTP/1.1" 500 208272
ERROR 2023-11-25 22:08:23,612 django.request Thread-1 2316 log log.py 241 django.request log_response 1084 Internal Server Error: /admin/jobs/jobposting/
Traceback (most recent call last):
  File "C:\Users\aky\AppData\Local\Programs\Python\Python38\courseu\lib\site-packages\django\db\backends\utils.py", line 89, in _execute
    return self.cursor.execute(sql, params)
  File "C:\Users\aky\AppData\Local\Programs\Python\Python38\courseu\lib\site-packages\psycopg\cursor.py", line 737, in execute
    raise ex.with_traceback(None)
psycopg.errors.UndefinedColumn: column jobs_jobposting.field_id does not exist
LINE 1: ..._jobposting"."link", "jobs_jobposting"."keyword", "jobs_jobp...
                                                             ^

The above exception was the direct cause of the following exception:

Traceback (most recent call last):
  File "C:\Users\aky\AppData\Local\Programs\Python\Python38\courseu\lib\site-packages\django\core\handlers\exception.py", line 55, in inner
    response = get_response(request)
  File "C:\Users\aky\AppData\Local\Programs\Python\Python38\courseu\lib\site-packages\django\core\handlers\base.py", line 197, in _get_response
    response = wrapped_callback(request, *callback_args, **callback_kwargs)
  File "C:\Users\aky\AppData\Local\Programs\Python\Python38\courseu\lib\site-packages\django\contrib\admin\options.py", line 688, in wrapper
    return self.admin_site.admin_view(view)(*args, **kwargs)
  File "C:\Users\aky\AppData\Local\Programs\Python\Python38\courseu\lib\site-packages\django\utils\decorators.py", line 134, in _wrapper_view
    response = view_func(request, *args, **kwargs)
  File "C:\Users\aky\AppData\Local\Programs\Python\Python38\courseu\lib\site-packages\django\views\decorators\cache.py", line 62, in _wrapper_view_func
    response = view_func(request, *args, **kwargs)
  File "C:\Users\aky\AppData\Local\Programs\Python\Python38\courseu\lib\site-packages\django\contrib\admin\sites.py", line 242, in inner
    return view(request, *args, **kwargs)
  File "C:\Users\aky\AppData\Local\Programs\Python\Python38\courseu\lib\site-packages\django\utils\decorators.py", line 46, in _wrapper
    return bound_method(*args, **kwargs)
  File "C:\Users\aky\AppData\Local\Programs\Python\Python38\courseu\lib\site-packages\django\utils\decorators.py", line 134, in _wrapper_view
    response = view_func(request, *args, **kwargs)
  File "C:\Users\aky\AppData\Local\Programs\Python\Python38\courseu\lib\site-packages\django\contrib\admin\options.py", line 2065, in changelist_view
    "selection_note": _("0 of %(cnt)s selected") % {"cnt": len(cl.result_list)},
  File "C:\Users\aky\AppData\Local\Programs\Python\Python38\courseu\lib\site-packages\django\db\models\query.py", line 380, in __len__
    self._fetch_all()
  File "C:\Users\aky\AppData\Local\Programs\Python\Python38\courseu\lib\site-packages\django\db\models\query.py", line 1881, in _fetch_all
    self._result_cache = list(self._iterable_class(self))
  File "C:\Users\aky\AppData\Local\Programs\Python\Python38\courseu\lib\site-packages\django\db\models\query.py", line 91, in __iter__
    results = compiler.execute_sql(
  File "C:\Users\aky\AppData\Local\Programs\Python\Python38\courseu\lib\site-packages\django\db\models\sql\compiler.py", line 1562, in execute_sql
    cursor.execute(sql, params)
  File "C:\Users\aky\AppData\Local\Programs\Python\Python38\courseu\lib\site-packages\debug_toolbar\panels\sql\tracking.py", line 252, in execute
    return self._record(super().execute, sql, params)
  File "C:\Users\aky\AppData\Local\Programs\Python\Python38\courseu\lib\site-packages\debug_toolbar\panels\sql\tracking.py", line 177, in _record
    return method(sql, params)
  File "C:\Users\aky\AppData\Local\Programs\Python\Python38\courseu\lib\site-packages\django\db\backends\utils.py", line 102, in execute
    return super().execute(sql, params)
  File "C:\Users\aky\AppData\Local\Programs\Python\Python38\courseu\lib\site-packages\django\db\backends\utils.py", line 67, in execute
    return self._execute_with_wrappers(
  File "C:\Users\aky\AppData\Local\Programs\Python\Python38\courseu\lib\site-packages\django\db\backends\utils.py", line 80, in _execute_with_wrappers
    return executor(sql, params, many, context)
  File "C:\Users\aky\AppData\Local\Programs\Python\Python38\courseu\lib\site-packages\django\db\backends\utils.py", line 89, in _execute
    return self.cursor.execute(sql, params)
  File "C:\Users\aky\AppData\Local\Programs\Python\Python38\courseu\lib\site-packages\django\db\utils.py", line 91, in __exit__
    raise dj_exc_value.with_traceback(traceback) from exc_value
  File "C:\Users\aky\AppData\Local\Programs\Python\Python38\courseu\lib\site-packages\django\db\backends\utils.py", line 89, in _execute
    return self.cursor.execute(sql, params)
  File "C:\Users\aky\AppData\Local\Programs\Python\Python38\courseu\lib\site-packages\psycopg\cursor.py", line 737, in execute
    raise ex.with_traceback(None)
django.db.utils.ProgrammingError: column jobs_jobposting.field_id does not exist
LINE 1: ..._jobposting"."link", "jobs_jobposting"."keyword", "jobs_jobp...
                                                             ^
ERROR 2023-11-25 22:08:23,689 django.server Thread-1 2316 basehttp basehttp.py 212 django.server log_message 1084 "GET /admin/jobs/jobposting/ HTTP/1.1" 500 208135
ERROR 2023-11-25 22:14:19,786 django.request Thread-1 9700 log log.py 241 django.request log_response 10204 Internal Server Error: /admin/jobs/jobposting/
Traceback (most recent call last):
  File "C:\Users\aky\AppData\Local\Programs\Python\Python38\courseu\lib\site-packages\django\db\backends\utils.py", line 89, in _execute
    return self.cursor.execute(sql, params)
  File "C:\Users\aky\AppData\Local\Programs\Python\Python38\courseu\lib\site-packages\psycopg\cursor.py", line 737, in execute
    raise ex.with_traceback(None)
psycopg.errors.UndefinedTable: relation "jobs_jobposting" does not exist
LINE 1: SELECT COUNT(*) AS "__count" FROM "jobs_jobposting"
                                          ^

The above exception was the direct cause of the following exception:

Traceback (most recent call last):
  File "C:\Users\aky\AppData\Local\Programs\Python\Python38\courseu\lib\site-packages\django\core\handlers\exception.py", line 55, in inner
    response = get_response(request)
  File "C:\Users\aky\AppData\Local\Programs\Python\Python38\courseu\lib\site-packages\django\core\handlers\base.py", line 197, in _get_response
    response = wrapped_callback(request, *callback_args, **callback_kwargs)
  File "C:\Users\aky\AppData\Local\Programs\Python\Python38\courseu\lib\site-packages\django\contrib\admin\options.py", line 688, in wrapper
    return self.admin_site.admin_view(view)(*args, **kwargs)
  File "C:\Users\aky\AppData\Local\Programs\Python\Python38\courseu\lib\site-packages\django\utils\decorators.py", line 134, in _wrapper_view
    response = view_func(request, *args, **kwargs)
  File "C:\Users\aky\AppData\Local\Programs\Python\Python38\courseu\lib\site-packages\django\views\decorators\cache.py", line 62, in _wrapper_view_func
    response = view_func(request, *args, **kwargs)
  File "C:\Users\aky\AppData\Local\Programs\Python\Python38\courseu\lib\site-packages\django\contrib\admin\sites.py", line 242, in inner
    return view(request, *args, **kwargs)
  File "C:\Users\aky\AppData\Local\Programs\Python\Python38\courseu\lib\site-packages\django\utils\decorators.py", line 46, in _wrapper
    return bound_method(*args, **kwargs)
  File "C:\Users\aky\AppData\Local\Programs\Python\Python38\courseu\lib\site-packages\django\utils\decorators.py", line 134, in _wrapper_view
    response = view_func(request, *args, **kwargs)
  File "C:\Users\aky\AppData\Local\Programs\Python\Python38\courseu\lib\site-packages\django\contrib\admin\options.py", line 1926, in changelist_view
    cl = self.get_changelist_instance(request)
  File "C:\Users\aky\AppData\Local\Programs\Python\Python38\courseu\lib\site-packages\django\contrib\admin\options.py", line 836, in get_changelist_instance
    return ChangeList(
  File "C:\Users\aky\AppData\Local\Programs\Python\Python38\courseu\lib\site-packages\django\contrib\admin\views\main.py", line 123, in __init__
    self.get_results(request)
  File "C:\Users\aky\AppData\Local\Programs\Python\Python38\courseu\lib\site-packages\django\contrib\admin\views\main.py", line 279, in get_results
    result_count = paginator.count
  File "C:\Users\aky\AppData\Local\Programs\Python\Python38\courseu\lib\site-packages\django\utils\functional.py", line 57, in __get__
    res = instance.__dict__[self.name] = self.func(instance)
  File "C:\Users\aky\AppData\Local\Programs\Python\Python38\courseu\lib\site-packages\django\core\paginator.py", line 93, in count
    return c()
  File "C:\Users\aky\AppData\Local\Programs\Python\Python38\courseu\lib\site-packages\django\db\models\query.py", line 608, in count
    return self.query.get_count(using=self.db)
  File "C:\Users\aky\AppData\Local\Programs\Python\Python38\courseu\lib\site-packages\django\db\models\sql\query.py", line 568, in get_count
    return obj.get_aggregation(using, {"__count": Count("*")})["__count"]
  File "C:\Users\aky\AppData\Local\Programs\Python\Python38\courseu\lib\site-packages\django\db\models\sql\query.py", line 554, in get_aggregation
    result = compiler.execute_sql(SINGLE)
  File "C:\Users\aky\AppData\Local\Programs\Python\Python38\courseu\lib\site-packages\django\db\models\sql\compiler.py", line 1562, in execute_sql
    cursor.execute(sql, params)
  File "C:\Users\aky\AppData\Local\Programs\Python\Python38\courseu\lib\site-packages\debug_toolbar\panels\sql\tracking.py", line 252, in execute
    return self._record(super().execute, sql, params)
  File "C:\Users\aky\AppData\Local\Programs\Python\Python38\courseu\lib\site-packages\debug_toolbar\panels\sql\tracking.py", line 177, in _record
    return method(sql, params)
  File "C:\Users\aky\AppData\Local\Programs\Python\Python38\courseu\lib\site-packages\django\db\backends\utils.py", line 102, in execute
    return super().execute(sql, params)
  File "C:\Users\aky\AppData\Local\Programs\Python\Python38\courseu\lib\site-packages\django\db\backends\utils.py", line 67, in execute
    return self._execute_with_wrappers(
  File "C:\Users\aky\AppData\Local\Programs\Python\Python38\courseu\lib\site-packages\django\db\backends\utils.py", line 80, in _execute_with_wrappers
    return executor(sql, params, many, context)
  File "C:\Users\aky\AppData\Local\Programs\Python\Python38\courseu\lib\site-packages\django\db\backends\utils.py", line 89, in _execute
    return self.cursor.execute(sql, params)
  File "C:\Users\aky\AppData\Local\Programs\Python\Python38\courseu\lib\site-packages\django\db\utils.py", line 91, in __exit__
    raise dj_exc_value.with_traceback(traceback) from exc_value
  File "C:\Users\aky\AppData\Local\Programs\Python\Python38\courseu\lib\site-packages\django\db\backends\utils.py", line 89, in _execute
    return self.cursor.execute(sql, params)
  File "C:\Users\aky\AppData\Local\Programs\Python\Python38\courseu\lib\site-packages\psycopg\cursor.py", line 737, in execute
    raise ex.with_traceback(None)
django.db.utils.ProgrammingError: relation "jobs_jobposting" does not exist
LINE 1: SELECT COUNT(*) AS "__count" FROM "jobs_jobposting"
                                          ^
ERROR 2023-11-25 22:14:19,929 django.server Thread-1 9700 basehttp basehttp.py 212 django.server log_message 10204 "GET /admin/jobs/jobposting/ HTTP/1.1" 500 222173
ERROR 2023-11-25 22:45:27,137 django.request Thread-5 19756 log log.py 241 django.request log_response 4524 Internal Server Error: /admin/website/learningmaterial/upload-csv/
Traceback (most recent call last):
  File "C:\Users\aky\AppData\Local\Programs\Python\Python38\courseu\lib\site-packages\django\core\handlers\exception.py", line 55, in inner
    response = get_response(request)
  File "C:\Users\aky\AppData\Local\Programs\Python\Python38\courseu\lib\site-packages\django\core\handlers\base.py", line 197, in _get_response
    response = wrapped_callback(request, *callback_args, **callback_kwargs)
  File "C:\Users\aky\AppData\Local\Programs\Python\Python38\eng_ver\apps\website\admin.py", line 166, in upload_csv
    created = Specialization.objects.update_or_create(
  File "C:\Users\aky\AppData\Local\Programs\Python\Python38\courseu\lib\site-packages\django\db\models\manager.py", line 87, in manager_method
    return getattr(self.get_queryset(), name)(*args, **kwargs)
  File "C:\Users\aky\AppData\Local\Programs\Python\Python38\courseu\lib\site-packages\django\db\models\query.py", line 949, in update_or_create
    obj, created = self.select_for_update().get_or_create(defaults, **kwargs)
  File "C:\Users\aky\AppData\Local\Programs\Python\Python38\courseu\lib\site-packages\django\db\models\query.py", line 916, in get_or_create
    return self.get(**kwargs), False
  File "C:\Users\aky\AppData\Local\Programs\Python\Python38\courseu\lib\site-packages\django\db\models\query.py", line 623, in get
    clone = self._chain() if self.query.combinator else self.filter(*args, **kwargs)
  File "C:\Users\aky\AppData\Local\Programs\Python\Python38\courseu\lib\site-packages\django\db\models\query.py", line 1436, in filter
    return self._filter_or_exclude(False, args, kwargs)
  File "C:\Users\aky\AppData\Local\Programs\Python\Python38\courseu\lib\site-packages\django\db\models\query.py", line 1454, in _filter_or_exclude
    clone._filter_or_exclude_inplace(negate, args, kwargs)
  File "C:\Users\aky\AppData\Local\Programs\Python\Python38\courseu\lib\site-packages\django\db\models\query.py", line 1461, in _filter_or_exclude_inplace
    self._query.add_q(Q(*args, **kwargs))
  File "C:\Users\aky\AppData\Local\Programs\Python\Python38\courseu\lib\site-packages\django\db\models\sql\query.py", line 1545, in add_q
    clause, _ = self._add_q(q_object, self.used_aliases)
  File "C:\Users\aky\AppData\Local\Programs\Python\Python38\courseu\lib\site-packages\django\db\models\sql\query.py", line 1576, in _add_q
    child_clause, needed_inner = self.build_filter(
  File "C:\Users\aky\AppData\Local\Programs\Python\Python38\courseu\lib\site-packages\django\db\models\sql\query.py", line 1426, in build_filter
    lookups, parts, reffed_expression = self.solve_lookup_type(arg, summarize)
  File "C:\Users\aky\AppData\Local\Programs\Python\Python38\courseu\lib\site-packages\django\db\models\sql\query.py", line 1236, in solve_lookup_type
    _, field, _, lookup_parts = self.names_to_path(lookup_splitted, self.get_meta())
  File "C:\Users\aky\AppData\Local\Programs\Python\Python38\courseu\lib\site-packages\django\db\models\sql\query.py", line 1724, in names_to_path
    raise FieldError(
django.core.exceptions.FieldError: Cannot resolve keyword 'level' into field. Choices are: description, field, field_id, roadmap_id, specialization_id, specializationskills, title
ERROR 2023-11-25 22:45:27,195 django.server Thread-5 19756 basehttp basehttp.py 212 django.server log_message 4524 "POST /admin/website/learningmaterial/upload-csv/ HTTP/1.1" 500 185005
ERROR 2023-11-25 22:49:14,277 django.request Thread-1 15392 log log.py 241 django.request log_response 9292 Internal Server Error: /admin/website/learningmaterial/upload-csv/
Traceback (most recent call last):
  File "C:\Users\aky\AppData\Local\Programs\Python\Python38\courseu\lib\site-packages\django\db\models\query.py", line 916, in get_or_create
    return self.get(**kwargs), False
  File "C:\Users\aky\AppData\Local\Programs\Python\Python38\courseu\lib\site-packages\django\db\models\query.py", line 637, in get
    raise self.model.DoesNotExist(
apps.website.models.LearningMaterial.DoesNotExist: LearningMaterial matching query does not exist.

During handling of the above exception, another exception occurred:

Traceback (most recent call last):
  File "C:\Users\aky\AppData\Local\Programs\Python\Python38\courseu\lib\site-packages\django\db\backends\utils.py", line 89, in _execute
    return self.cursor.execute(sql, params)
  File "C:\Users\aky\AppData\Local\Programs\Python\Python38\courseu\lib\site-packages\psycopg\cursor.py", line 737, in execute
    raise ex.with_traceback(None)
psycopg.errors.StringDataRightTruncation: value too long for type character varying(3000)

The above exception was the direct cause of the following exception:

Traceback (most recent call last):
  File "C:\Users\aky\AppData\Local\Programs\Python\Python38\courseu\lib\site-packages\django\core\handlers\exception.py", line 55, in inner
    response = get_response(request)
  File "C:\Users\aky\AppData\Local\Programs\Python\Python38\courseu\lib\site-packages\django\core\handlers\base.py", line 197, in _get_response
    response = wrapped_callback(request, *callback_args, **callback_kwargs)
  File "C:\Users\aky\AppData\Local\Programs\Python\Python38\eng_ver\apps\website\admin.py", line 166, in upload_csv
    created = LearningMaterial.objects.update_or_create(
  File "C:\Users\aky\AppData\Local\Programs\Python\Python38\courseu\lib\site-packages\django\db\models\manager.py", line 87, in manager_method
    return getattr(self.get_queryset(), name)(*args, **kwargs)
  File "C:\Users\aky\AppData\Local\Programs\Python\Python38\courseu\lib\site-packages\django\db\models\query.py", line 949, in update_or_create
    obj, created = self.select_for_update().get_or_create(defaults, **kwargs)
  File "C:\Users\aky\AppData\Local\Programs\Python\Python38\courseu\lib\site-packages\django\db\models\query.py", line 923, in get_or_create
    return self.create(**params), True
  File "C:\Users\aky\AppData\Local\Programs\Python\Python38\courseu\lib\site-packages\django\db\models\query.py", line 658, in create
    obj.save(force_insert=True, using=self.db)
  File "C:\Users\aky\AppData\Local\Programs\Python\Python38\courseu\lib\site-packages\django\db\models\base.py", line 814, in save
    self.save_base(
  File "C:\Users\aky\AppData\Local\Programs\Python\Python38\courseu\lib\site-packages\django\db\models\base.py", line 877, in save_base
    updated = self._save_table(
  File "C:\Users\aky\AppData\Local\Programs\Python\Python38\courseu\lib\site-packages\django\db\models\base.py", line 1020, in _save_table
    results = self._do_insert(
  File "C:\Users\aky\AppData\Local\Programs\Python\Python38\courseu\lib\site-packages\django\db\models\base.py", line 1061, in _do_insert
    return manager._insert(
  File "C:\Users\aky\AppData\Local\Programs\Python\Python38\courseu\lib\site-packages\django\db\models\manager.py", line 87, in manager_method
    return getattr(self.get_queryset(), name)(*args, **kwargs)
  File "C:\Users\aky\AppData\Local\Programs\Python\Python38\courseu\lib\site-packages\django\db\models\query.py", line 1805, in _insert
    return query.get_compiler(using=using).execute_sql(returning_fields)
  File "C:\Users\aky\AppData\Local\Programs\Python\Python38\courseu\lib\site-packages\django\db\models\sql\compiler.py", line 1822, in execute_sql
    cursor.execute(sql, params)
  File "C:\Users\aky\AppData\Local\Programs\Python\Python38\courseu\lib\site-packages\debug_toolbar\panels\sql\tracking.py", line 252, in execute
    return self._record(super().execute, sql, params)
  File "C:\Users\aky\AppData\Local\Programs\Python\Python38\courseu\lib\site-packages\debug_toolbar\panels\sql\tracking.py", line 177, in _record
    return method(sql, params)
  File "C:\Users\aky\AppData\Local\Programs\Python\Python38\courseu\lib\site-packages\django\db\backends\utils.py", line 102, in execute
    return super().execute(sql, params)
  File "C:\Users\aky\AppData\Local\Programs\Python\Python38\courseu\lib\site-packages\django\db\backends\utils.py", line 67, in execute
    return self._execute_with_wrappers(
  File "C:\Users\aky\AppData\Local\Programs\Python\Python38\courseu\lib\site-packages\django\db\backends\utils.py", line 80, in _execute_with_wrappers
    return executor(sql, params, many, context)
  File "C:\Users\aky\AppData\Local\Programs\Python\Python38\courseu\lib\site-packages\django\db\backends\utils.py", line 89, in _execute
    return self.cursor.execute(sql, params)
  File "C:\Users\aky\AppData\Local\Programs\Python\Python38\courseu\lib\site-packages\django\db\utils.py", line 91, in __exit__
    raise dj_exc_value.with_traceback(traceback) from exc_value
  File "C:\Users\aky\AppData\Local\Programs\Python\Python38\courseu\lib\site-packages\django\db\backends\utils.py", line 89, in _execute
    return self.cursor.execute(sql, params)
  File "C:\Users\aky\AppData\Local\Programs\Python\Python38\courseu\lib\site-packages\psycopg\cursor.py", line 737, in execute
    raise ex.with_traceback(None)
django.db.utils.DataError: value too long for type character varying(3000)
ERROR 2023-11-25 22:49:58,211 django.request Thread-5 17232 log log.py 241 django.request log_response 9292 Internal Server Error: /admin/website/learningmaterial/upload-csv/
Traceback (most recent call last):
  File "C:\Users\aky\AppData\Local\Programs\Python\Python38\courseu\lib\site-packages\django\db\models\query.py", line 916, in get_or_create
    return self.get(**kwargs), False
  File "C:\Users\aky\AppData\Local\Programs\Python\Python38\courseu\lib\site-packages\django\db\models\query.py", line 637, in get
    raise self.model.DoesNotExist(
apps.website.models.LearningMaterial.DoesNotExist: LearningMaterial matching query does not exist.

During handling of the above exception, another exception occurred:

Traceback (most recent call last):
  File "C:\Users\aky\AppData\Local\Programs\Python\Python38\courseu\lib\site-packages\django\db\backends\utils.py", line 89, in _execute
    return self.cursor.execute(sql, params)
  File "C:\Users\aky\AppData\Local\Programs\Python\Python38\courseu\lib\site-packages\psycopg\cursor.py", line 737, in execute
    raise ex.with_traceback(None)
psycopg.errors.StringDataRightTruncation: value too long for type character varying(3000)

The above exception was the direct cause of the following exception:

Traceback (most recent call last):
  File "C:\Users\aky\AppData\Local\Programs\Python\Python38\courseu\lib\site-packages\django\core\handlers\exception.py", line 55, in inner
    response = get_response(request)
  File "C:\Users\aky\AppData\Local\Programs\Python\Python38\courseu\lib\site-packages\django\core\handlers\base.py", line 197, in _get_response
    response = wrapped_callback(request, *callback_args, **callback_kwargs)
  File "C:\Users\aky\AppData\Local\Programs\Python\Python38\eng_ver\apps\website\admin.py", line 166, in upload_csv
    created = LearningMaterial.objects.update_or_create(
  File "C:\Users\aky\AppData\Local\Programs\Python\Python38\courseu\lib\site-packages\django\db\models\manager.py", line 87, in manager_method
    return getattr(self.get_queryset(), name)(*args, **kwargs)
  File "C:\Users\aky\AppData\Local\Programs\Python\Python38\courseu\lib\site-packages\django\db\models\query.py", line 949, in update_or_create
    obj, created = self.select_for_update().get_or_create(defaults, **kwargs)
  File "C:\Users\aky\AppData\Local\Programs\Python\Python38\courseu\lib\site-packages\django\db\models\query.py", line 923, in get_or_create
    return self.create(**params), True
  File "C:\Users\aky\AppData\Local\Programs\Python\Python38\courseu\lib\site-packages\django\db\models\query.py", line 658, in create
    obj.save(force_insert=True, using=self.db)
  File "C:\Users\aky\AppData\Local\Programs\Python\Python38\courseu\lib\site-packages\django\db\models\base.py", line 814, in save
    self.save_base(
  File "C:\Users\aky\AppData\Local\Programs\Python\Python38\courseu\lib\site-packages\django\db\models\base.py", line 877, in save_base
    updated = self._save_table(
  File "C:\Users\aky\AppData\Local\Programs\Python\Python38\courseu\lib\site-packages\django\db\models\base.py", line 1020, in _save_table
    results = self._do_insert(
  File "C:\Users\aky\AppData\Local\Programs\Python\Python38\courseu\lib\site-packages\django\db\models\base.py", line 1061, in _do_insert
    return manager._insert(
  File "C:\Users\aky\AppData\Local\Programs\Python\Python38\courseu\lib\site-packages\django\db\models\manager.py", line 87, in manager_method
    return getattr(self.get_queryset(), name)(*args, **kwargs)
  File "C:\Users\aky\AppData\Local\Programs\Python\Python38\courseu\lib\site-packages\django\db\models\query.py", line 1805, in _insert
    return query.get_compiler(using=using).execute_sql(returning_fields)
  File "C:\Users\aky\AppData\Local\Programs\Python\Python38\courseu\lib\site-packages\django\db\models\sql\compiler.py", line 1822, in execute_sql
    cursor.execute(sql, params)
  File "C:\Users\aky\AppData\Local\Programs\Python\Python38\courseu\lib\site-packages\debug_toolbar\panels\sql\tracking.py", line 252, in execute
    return self._record(super().execute, sql, params)
  File "C:\Users\aky\AppData\Local\Programs\Python\Python38\courseu\lib\site-packages\debug_toolbar\panels\sql\tracking.py", line 177, in _record
    return method(sql, params)
  File "C:\Users\aky\AppData\Local\Programs\Python\Python38\courseu\lib\site-packages\django\db\backends\utils.py", line 102, in execute
    return super().execute(sql, params)
  File "C:\Users\aky\AppData\Local\Programs\Python\Python38\courseu\lib\site-packages\django\db\backends\utils.py", line 67, in execute
    return self._execute_with_wrappers(
  File "C:\Users\aky\AppData\Local\Programs\Python\Python38\courseu\lib\site-packages\django\db\backends\utils.py", line 80, in _execute_with_wrappers
    return executor(sql, params, many, context)
  File "C:\Users\aky\AppData\Local\Programs\Python\Python38\courseu\lib\site-packages\django\db\backends\utils.py", line 89, in _execute
    return self.cursor.execute(sql, params)
  File "C:\Users\aky\AppData\Local\Programs\Python\Python38\courseu\lib\site-packages\django\db\utils.py", line 91, in __exit__
    raise dj_exc_value.with_traceback(traceback) from exc_value
  File "C:\Users\aky\AppData\Local\Programs\Python\Python38\courseu\lib\site-packages\django\db\backends\utils.py", line 89, in _execute
    return self.cursor.execute(sql, params)
  File "C:\Users\aky\AppData\Local\Programs\Python\Python38\courseu\lib\site-packages\psycopg\cursor.py", line 737, in execute
    raise ex.with_traceback(None)
django.db.utils.DataError: value too long for type character varying(3000)
ERROR 2023-11-25 22:50:00,474 django.server Thread-5 17232 basehttp basehttp.py 212 django.server log_message 9292 "POST /admin/website/learningmaterial/upload-csv/ HTTP/1.1" 500 314656
WARNING 2023-11-25 23:20:54,108 django.server Thread-4 3124 basehttp basehttp.py 212 django.server log_message 15768 "GET /static/images/boom.png HTTP/1.1" 404 1905
WARNING 2023-11-25 23:20:54,121 django.server Thread-2 2556 basehttp basehttp.py 212 django.server log_message 15768 "GET /static/images/result.png HTTP/1.1" 404 1911
WARNING 2023-11-25 23:21:02,251 django.server Thread-3 6664 basehttp basehttp.py 212 django.server log_message 15768 "GET /static/images/boom.png HTTP/1.1" 404 1905
WARNING 2023-11-25 23:21:02,263 django.server Thread-1 668 basehttp basehttp.py 212 django.server log_message 15768 "GET /static/images/result.png HTTP/1.1" 404 1911
WARNING 2023-11-25 23:21:13,689 django.server Thread-5 9972 basehttp basehttp.py 212 django.server log_message 15768 "GET /static/css/recommender_failed.css HTTP/1.1" 404 1938
WARNING 2023-11-25 23:21:53,640 django.server Thread-9 2368 basehttp basehttp.py 212 django.server log_message 15768 "GET /static/images/boom.png HTTP/1.1" 404 1905
WARNING 2023-11-25 23:21:53,669 django.server Thread-7 2176 basehttp basehttp.py 212 django.server log_message 15768 "GET /static/images/result.png HTTP/1.1" 404 1911
WARNING 2023-11-25 23:27:27,142 django.server Thread-10 13384 basehttp basehttp.py 212 django.server log_message 15768 "GET /static/images/boom.png HTTP/1.1" 404 1905
WARNING 2023-11-25 23:27:27,213 django.server Thread-12 5008 basehttp basehttp.py 212 django.server log_message 15768 "GET /static/images/result.png HTTP/1.1" 404 1911
WARNING 2023-11-25 23:27:36,355 django.server Thread-13 1796 basehttp basehttp.py 212 django.server log_message 15768 "GET /static/images/boom.png HTTP/1.1" 404 1905
WARNING 2023-11-25 23:27:36,482 django.server Thread-19 14416 basehttp basehttp.py 212 django.server log_message 15768 "GET /static/images/result.png HTTP/1.1" 404 1911
WARNING 2023-11-25 23:27:37,934 django.server Thread-18 11224 basehttp basehttp.py 212 django.server log_message 15768 "GET /static/images/favicon.png HTTP/1.1" 404 1914
WARNING 2023-11-26 00:03:33,762 django.request Thread-2 16272 log log.py 241 django.request log_response 11152 Not Found: /images/profile_pics/IMG_3477_YVMV930.jpg
WARNING 2023-11-26 00:03:33,772 django.server Thread-2 16272 basehttp basehttp.py 212 django.server log_message 11152 "GET /images/profile_pics/IMG_3477_YVMV930.jpg HTTP/1.1" 404 26681
WARNING 2023-11-26 00:03:33,788 django.request Thread-3 13360 log log.py 241 django.request log_response 11152 Not Found: /images/profile_pics/WIN_20230530_14_55_43_Pro.jpg
WARNING 2023-11-26 00:03:33,792 django.server Thread-3 13360 basehttp basehttp.py 212 django.server log_message 11152 "GET /images/profile_pics/WIN_20230530_14_55_43_Pro.jpg HTTP/1.1" 404 26726
WARNING 2023-11-26 00:18:07,395 django.server Thread-8 18128 basehttp basehttp.py 212 django.server log_message 10116 "GET /static/images/no-profile-pic.png HTTP/1.1" 404 1935
WARNING 2023-11-26 00:18:23,278 django.server Thread-6 18844 basehttp basehttp.py 212 django.server log_message 10116 "GET /static/images/no-profile-pic.png HTTP/1.1" 404 1935
WARNING 2023-11-26 00:18:38,325 django.server Thread-9 8324 basehttp basehttp.py 212 django.server log_message 10116 "GET /static/images/no-profile-pic.png HTTP/1.1" 404 1935
WARNING 2023-11-26 00:18:41,952 django.server Thread-11 19924 basehttp basehttp.py 212 django.server log_message 10116 "GET /static/images/no-profile-pic.png HTTP/1.1" 404 1935
WARNING 2023-11-26 00:18:48,469 django.server Thread-10 19744 basehttp basehttp.py 212 django.server log_message 10116 "GET /static/images/no-profile-pic.png HTTP/1.1" 404 1935
WARNING 2023-11-26 00:18:52,641 django.server Thread-14 1244 basehttp basehttp.py 212 django.server log_message 10116 "GET /static/images/no-profile-pic.png HTTP/1.1" 404 1935
WARNING 2023-11-26 00:19:00,003 django.server Thread-15 13036 basehttp basehttp.py 212 django.server log_message 10116 "GET /static/images/no-profile-pic.png HTTP/1.1" 404 1935
WARNING 2023-11-26 00:19:16,967 django.server Thread-13 1236 basehttp basehttp.py 212 django.server log_message 10116 "GET /static/images/no-profile-pic.png HTTP/1.1" 404 1935
ERROR 2023-11-26 00:19:50,530 django.request Thread-12 17152 log log.py 241 django.request log_response 10116 Internal Server Error: /start_test/
Traceback (most recent call last):
  File "C:\Users\aky\AppData\Local\Programs\Python\Python38\courseu\lib\site-packages\django\core\handlers\exception.py", line 55, in inner
    response = get_response(request)
  File "C:\Users\aky\AppData\Local\Programs\Python\Python38\courseu\lib\site-packages\django\core\handlers\base.py", line 197, in _get_response
    response = wrapped_callback(request, *callback_args, **callback_kwargs)
  File "C:\Users\aky\AppData\Local\Programs\Python\Python38\eng_ver\utilities\decorators.py", line 11, in wrapper_func
    return view_func(request,*args,**kwargs)
  File "C:\Users\aky\AppData\Local\Programs\Python\Python38\eng_ver\apps\assessment\views.py", line 118, in start_test
    return redirect('create_new_question_set', last_set=last_set.set_id)
AttributeError: 'NoneType' object has no attribute 'set_id'
ERROR 2023-11-26 00:19:50,606 django.server Thread-12 17152 basehttp basehttp.py 212 django.server log_message 10116 "GET /start_test/ HTTP/1.1" 500 100139
WARNING 2023-11-26 00:19:53,057 django.request Thread-12 17152 log log.py 241 django.request log_response 10116 Not Found: /favicon.ico
WARNING 2023-11-26 00:19:53,060 django.server Thread-12 17152 basehttp basehttp.py 212 django.server log_message 10116 "GET /favicon.ico HTTP/1.1" 404 26452
ERROR 2023-11-26 00:23:02,186 django.request Thread-17 6736 log log.py 241 django.request log_response 10116 Internal Server Error: /start_test/
Traceback (most recent call last):
  File "C:\Users\aky\AppData\Local\Programs\Python\Python38\courseu\lib\site-packages\django\core\handlers\exception.py", line 55, in inner
    response = get_response(request)
  File "C:\Users\aky\AppData\Local\Programs\Python\Python38\courseu\lib\site-packages\django\core\handlers\base.py", line 197, in _get_response
    response = wrapped_callback(request, *callback_args, **callback_kwargs)
  File "C:\Users\aky\AppData\Local\Programs\Python\Python38\eng_ver\utilities\decorators.py", line 11, in wrapper_func
    return view_func(request,*args,**kwargs)
  File "C:\Users\aky\AppData\Local\Programs\Python\Python38\eng_ver\apps\assessment\views.py", line 118, in start_test
    return redirect('create_new_question_set', last_set=last_set.set_id)
AttributeError: 'NoneType' object has no attribute 'set_id'
ERROR 2023-11-26 00:23:02,255 django.server Thread-17 6736 basehttp basehttp.py 212 django.server log_message 10116 "GET /start_test/ HTTP/1.1" 500 100404
WARNING 2023-11-26 00:23:04,462 django.request Thread-17 6736 log log.py 241 django.request log_response 10116 Not Found: /favicon.ico
WARNING 2023-11-26 00:23:04,464 django.server Thread-17 6736 basehttp basehttp.py 212 django.server log_message 10116 "GET /favicon.ico HTTP/1.1" 404 26452
WARNING 2023-11-26 00:42:26,516 django.server Thread-24 18920 basehttp basehttp.py 212 django.server log_message 10116 "GET /static/images/favicon.png HTTP/1.1" 404 1914
ERROR 2023-11-26 01:07:48,792 django.request Thread-1 13536 log log.py 241 django.request log_response 11668 Internal Server Error: /recommender/
Traceback (most recent call last):
  File "C:\Users\aky\AppData\Local\Programs\Python\Python38\courseu\lib\site-packages\django\core\handlers\exception.py", line 55, in inner
    response = get_response(request)
  File "C:\Users\aky\AppData\Local\Programs\Python\Python38\courseu\lib\site-packages\django\core\handlers\base.py", line 197, in _get_response
    response = wrapped_callback(request, *callback_args, **callback_kwargs)
  File "C:\Users\aky\AppData\Local\Programs\Python\Python38\eng_ver\apps\recommender\views.py", line 319, in recommender
    field_name_2 = field_names[1]
IndexError: list index out of range
ERROR 2023-11-26 01:07:48,882 django.server Thread-1 13536 basehttp basehttp.py 212 django.server log_message 11668 "GET /recommender/ HTTP/1.1" 500 132936
ERROR 2023-11-26 01:58:25,552 django.request Thread-19 6784 log log.py 241 django.request log_response 19872 Internal Server Error: /admin/acad/subject/upload-csv/
Traceback (most recent call last):
  File "C:\Users\aky\AppData\Local\Programs\Python\Python38\courseu\lib\site-packages\django\core\handlers\exception.py", line 55, in inner
    response = get_response(request)
  File "C:\Users\aky\AppData\Local\Programs\Python\Python38\courseu\lib\site-packages\django\core\handlers\base.py", line 197, in _get_response
    response = wrapped_callback(request, *callback_args, **callback_kwargs)
  File "C:\Users\aky\AppData\Local\Programs\Python\Python38\eng_ver\apps\acad\admin.py", line 52, in upload_csv
    skills = row['skills'].split(',')
KeyError: 'skills'
ERROR 2023-11-26 01:58:25,615 django.server Thread-19 6784 basehttp basehttp.py 212 django.server log_message 19872 "POST /admin/acad/subject/upload-csv/ HTTP/1.1" 500 97849
ERROR 2023-11-26 02:01:43,086 django.request Thread-1 4556 log log.py 241 django.request log_response 8576 Internal Server Error: /admin/acad/subject/upload-csv/
Traceback (most recent call last):
  File "C:\Users\aky\AppData\Local\Programs\Python\Python38\courseu\lib\site-packages\django\core\handlers\exception.py", line 55, in inner
    response = get_response(request)
  File "C:\Users\aky\AppData\Local\Programs\Python\Python38\courseu\lib\site-packages\django\core\handlers\base.py", line 197, in _get_response
    response = wrapped_callback(request, *callback_args, **callback_kwargs)
  File "C:\Users\aky\AppData\Local\Programs\Python\Python38\eng_ver\apps\acad\admin.py", line 53, in upload_csv
    skill_list = json.loads(row['skill_list'])
  File "C:\Users\aky\AppData\Local\Programs\Python\Python38\lib\json\__init__.py", line 357, in loads
    return _default_decoder.decode(s)
  File "C:\Users\aky\AppData\Local\Programs\Python\Python38\lib\json\decoder.py", line 337, in decode
    obj, end = self.raw_decode(s, idx=_w(s, 0).end())
  File "C:\Users\aky\AppData\Local\Programs\Python\Python38\lib\json\decoder.py", line 355, in raw_decode
    raise JSONDecodeError("Expecting value", s, err.value) from None
json.decoder.JSONDecodeError: Expecting value: line 1 column 2 (char 1)
ERROR 2023-11-26 02:01:43,211 django.server Thread-1 4556 basehttp basehttp.py 212 django.server log_message 8576 "POST /admin/acad/subject/upload-csv/ HTTP/1.1" 500 109981
ERROR 2023-11-26 02:03:08,136 django.request Thread-1 18128 log log.py 241 django.request log_response 17820 Internal Server Error: /admin/acad/subject/upload-csv/
Traceback (most recent call last):
  File "C:\Users\aky\AppData\Local\Programs\Python\Python38\courseu\lib\site-packages\django\core\handlers\exception.py", line 55, in inner
    response = get_response(request)
  File "C:\Users\aky\AppData\Local\Programs\Python\Python38\courseu\lib\site-packages\django\core\handlers\base.py", line 197, in _get_response
    response = wrapped_callback(request, *callback_args, **callback_kwargs)
  File "C:\Users\aky\AppData\Local\Programs\Python\Python38\eng_ver\apps\acad\admin.py", line 53, in upload_csv
    skills = row['skills'].strip('[]').split(',')
KeyError: 'skills'
ERROR 2023-11-26 02:03:08,363 django.server Thread-1 18128 basehttp basehttp.py 212 django.server log_message 17820 "POST /admin/acad/subject/upload-csv/ HTTP/1.1" 500 97899
ERROR 2023-11-26 02:03:39,980 django.request Thread-1 5800 log log.py 241 django.request log_response 11924 Internal Server Error: /admin/acad/subject/upload-csv/
Traceback (most recent call last):
  File "C:\Users\aky\AppData\Local\Programs\Python\Python38\courseu\lib\site-packages\django\core\handlers\exception.py", line 55, in inner
    response = get_response(request)
  File "C:\Users\aky\AppData\Local\Programs\Python\Python38\courseu\lib\site-packages\django\core\handlers\base.py", line 197, in _get_response
    response = wrapped_callback(request, *callback_args, **callback_kwargs)
  File "C:\Users\aky\AppData\Local\Programs\Python\Python38\eng_ver\apps\acad\admin.py", line 55, in upload_csv
    skill_obj, _ = Skill.objects.update_or_create(
NameError: name 'Skill' is not defined
ERROR 2023-11-26 02:03:40,088 django.server Thread-1 5800 basehttp basehttp.py 212 django.server log_message 11924 "POST /admin/acad/subject/upload-csv/ HTTP/1.1" 500 98277
ERROR 2023-11-26 02:06:14,485 django.request Thread-1 6608 log log.py 241 django.request log_response 14704 Internal Server Error: /admin/acad/subject/upload-csv/
Traceback (most recent call last):
  File "C:\Users\aky\AppData\Local\Programs\Python\Python38\courseu\lib\site-packages\django\core\handlers\exception.py", line 55, in inner
    response = get_response(request)
  File "C:\Users\aky\AppData\Local\Programs\Python\Python38\courseu\lib\site-packages\django\core\handlers\base.py", line 197, in _get_response
    response = wrapped_callback(request, *callback_args, **callback_kwargs)
  File "C:\Users\aky\AppData\Local\Programs\Python\Python38\eng_ver\apps\acad\admin.py", line 59, in upload_csv
    skill_obj, _ = Skill.objects.update_or_create(
  File "C:\Users\aky\AppData\Local\Programs\Python\Python38\courseu\lib\site-packages\django\db\models\manager.py", line 87, in manager_method
    return getattr(self.get_queryset(), name)(*args, **kwargs)
  File "C:\Users\aky\AppData\Local\Programs\Python\Python38\courseu\lib\site-packages\django\db\models\query.py", line 949, in update_or_create
    obj, created = self.select_for_update().get_or_create(defaults, **kwargs)
  File "C:\Users\aky\AppData\Local\Programs\Python\Python38\courseu\lib\site-packages\django\db\models\query.py", line 916, in get_or_create
    return self.get(**kwargs), False
  File "C:\Users\aky\AppData\Local\Programs\Python\Python38\courseu\lib\site-packages\django\db\models\query.py", line 623, in get
    clone = self._chain() if self.query.combinator else self.filter(*args, **kwargs)
  File "C:\Users\aky\AppData\Local\Programs\Python\Python38\courseu\lib\site-packages\django\db\models\query.py", line 1436, in filter
    return self._filter_or_exclude(False, args, kwargs)
  File "C:\Users\aky\AppData\Local\Programs\Python\Python38\courseu\lib\site-packages\django\db\models\query.py", line 1454, in _filter_or_exclude
    clone._filter_or_exclude_inplace(negate, args, kwargs)
  File "C:\Users\aky\AppData\Local\Programs\Python\Python38\courseu\lib\site-packages\django\db\models\query.py", line 1461, in _filter_or_exclude_inplace
    self._query.add_q(Q(*args, **kwargs))
  File "C:\Users\aky\AppData\Local\Programs\Python\Python38\courseu\lib\site-packages\django\db\models\sql\query.py", line 1545, in add_q
    clause, _ = self._add_q(q_object, self.used_aliases)
  File "C:\Users\aky\AppData\Local\Programs\Python\Python38\courseu\lib\site-packages\django\db\models\sql\query.py", line 1576, in _add_q
    child_clause, needed_inner = self.build_filter(
  File "C:\Users\aky\AppData\Local\Programs\Python\Python38\courseu\lib\site-packages\django\db\models\sql\query.py", line 1426, in build_filter
    lookups, parts, reffed_expression = self.solve_lookup_type(arg, summarize)
  File "C:\Users\aky\AppData\Local\Programs\Python\Python38\courseu\lib\site-packages\django\db\models\sql\query.py", line 1236, in solve_lookup_type
    _, field, _, lookup_parts = self.names_to_path(lookup_splitted, self.get_meta())
  File "C:\Users\aky\AppData\Local\Programs\Python\Python38\courseu\lib\site-packages\django\db\models\sql\query.py", line 1724, in names_to_path
    raise FieldError(
django.core.exceptions.FieldError: Cannot resolve keyword 'skill_name' into field. Choices are: id, indicator, skill, specializationskills, subject, test, userskill
ERROR 2023-11-26 02:06:14,620 django.server Thread-1 6608 basehttp basehttp.py 212 django.server log_message 14704 "POST /admin/acad/subject/upload-csv/ HTTP/1.1" 500 155000
ERROR 2023-11-26 02:08:02,080 django.request Thread-3 10040 log log.py 241 django.request log_response 7332 Internal Server Error: /admin/acad/subject/upload-csv/
Traceback (most recent call last):
  File "C:\Users\aky\AppData\Local\Programs\Python\Python38\courseu\lib\site-packages\django\core\handlers\exception.py", line 55, in inner
    response = get_response(request)
  File "C:\Users\aky\AppData\Local\Programs\Python\Python38\courseu\lib\site-packages\django\core\handlers\base.py", line 197, in _get_response
    response = wrapped_callback(request, *callback_args, **callback_kwargs)
  File "C:\Users\aky\AppData\Local\Programs\Python\Python38\eng_ver\apps\acad\admin.py", line 62, in upload_csv
    subject_skill, _ = SubjectSkill.objects.update_or_create(
NameError: name 'SubjectSkill' is not defined
ERROR 2023-11-26 02:08:02,253 django.server Thread-3 10040 basehttp basehttp.py 212 django.server log_message 7332 "POST /admin/acad/subject/upload-csv/ HTTP/1.1" 500 98621
ERROR 2023-11-26 02:46:15,181 django.request Thread-1 7796 log log.py 241 django.request log_response 808 Internal Server Error: /admin/assessment/test/upload-csv/
Traceback (most recent call last):
  File "C:\Users\aky\AppData\Local\Programs\Python\Python38\courseu\lib\site-packages\django\core\handlers\exception.py", line 55, in inner
    response = get_response(request)
  File "C:\Users\aky\AppData\Local\Programs\Python\Python38\courseu\lib\site-packages\django\core\handlers\base.py", line 197, in _get_response
    response = wrapped_callback(request, *callback_args, **callback_kwargs)
  File "C:\Users\aky\AppData\Local\Programs\Python\Python38\eng_ver\apps\assessment\admin.py", line 60, in upload_csv
    skill_obj, _ = Skill.objects.update_or_create(
NameError: name 'Skill' is not defined
ERROR 2023-11-26 02:46:15,249 django.server Thread-1 7796 basehttp basehttp.py 212 django.server log_message 808 "POST /admin/assessment/test/upload-csv/ HTTP/1.1" 500 99278
ERROR 2023-11-26 02:47:00,574 django.request Thread-1 14704 log log.py 241 django.request log_response 19972 Internal Server Error: /admin/assessment/test/upload-csv/
Traceback (most recent call last):
  File "C:\Users\aky\AppData\Local\Programs\Python\Python38\courseu\lib\site-packages\django\core\handlers\exception.py", line 55, in inner
    response = get_response(request)
  File "C:\Users\aky\AppData\Local\Programs\Python\Python38\courseu\lib\site-packages\django\core\handlers\base.py", line 197, in _get_response
    response = wrapped_callback(request, *callback_args, **callback_kwargs)
  File "C:\Users\aky\AppData\Local\Programs\Python\Python38\eng_ver\apps\assessment\admin.py", line 47, in upload_csv
    options = json.loads(row['options'])
  File "C:\Users\aky\AppData\Local\Programs\Python\Python38\lib\json\__init__.py", line 357, in loads
    return _default_decoder.decode(s)
  File "C:\Users\aky\AppData\Local\Programs\Python\Python38\lib\json\decoder.py", line 337, in decode
    obj, end = self.raw_decode(s, idx=_w(s, 0).end())
  File "C:\Users\aky\AppData\Local\Programs\Python\Python38\lib\json\decoder.py", line 353, in raw_decode
    obj, end = self.scan_once(s, idx)
json.decoder.JSONDecodeError: Expecting ',' delimiter: line 1 column 7 (char 6)
ERROR 2023-11-26 02:47:00,730 django.server Thread-1 14704 basehttp basehttp.py 212 django.server log_message 19972 "POST /admin/assessment/test/upload-csv/ HTTP/1.1" 500 112208
ERROR 2023-11-26 02:52:40,350 django.request Thread-1 2448 log log.py 241 django.request log_response 18568 Internal Server Error: /admin/assessment/test/upload-csv/
Traceback (most recent call last):
  File "C:\Users\aky\AppData\Local\Programs\Python\Python38\courseu\lib\site-packages\django\core\handlers\exception.py", line 55, in inner
    response = get_response(request)
  File "C:\Users\aky\AppData\Local\Programs\Python\Python38\courseu\lib\site-packages\django\core\handlers\base.py", line 197, in _get_response
    response = wrapped_callback(request, *callback_args, **callback_kwargs)
  File "C:\Users\aky\AppData\Local\Programs\Python\Python38\eng_ver\apps\assessment\admin.py", line 48, in upload_csv
    options = json.loads(row['options'])
  File "C:\Users\aky\AppData\Local\Programs\Python\Python38\lib\json\__init__.py", line 357, in loads
    return _default_decoder.decode(s)
  File "C:\Users\aky\AppData\Local\Programs\Python\Python38\lib\json\decoder.py", line 337, in decode
    obj, end = self.raw_decode(s, idx=_w(s, 0).end())
  File "C:\Users\aky\AppData\Local\Programs\Python\Python38\lib\json\decoder.py", line 353, in raw_decode
    obj, end = self.scan_once(s, idx)
json.decoder.JSONDecodeError: Expecting ',' delimiter: line 1 column 7 (char 6)
ERROR 2023-11-26 02:52:40,475 django.server Thread-1 2448 basehttp basehttp.py 212 django.server log_message 18568 "POST /admin/assessment/test/upload-csv/ HTTP/1.1" 500 112183
ERROR 2023-11-26 02:56:20,686 django.request Thread-1 564 log log.py 241 django.request log_response 17616 Internal Server Error: /admin/assessment/test/upload-csv/
Traceback (most recent call last):
  File "C:\Users\aky\AppData\Local\Programs\Python\Python38\courseu\lib\site-packages\django\core\handlers\exception.py", line 55, in inner
    response = get_response(request)
  File "C:\Users\aky\AppData\Local\Programs\Python\Python38\courseu\lib\site-packages\django\core\handlers\base.py", line 197, in _get_response
    response = wrapped_callback(request, *callback_args, **callback_kwargs)
  File "C:\Users\aky\AppData\Local\Programs\Python\Python38\eng_ver\apps\assessment\admin.py", line 49, in upload_csv
    options = json.loads(row['options'])
  File "C:\Users\aky\AppData\Local\Programs\Python\Python38\lib\json\__init__.py", line 357, in loads
    return _default_decoder.decode(s)
  File "C:\Users\aky\AppData\Local\Programs\Python\Python38\lib\json\decoder.py", line 337, in decode
    obj, end = self.raw_decode(s, idx=_w(s, 0).end())
  File "C:\Users\aky\AppData\Local\Programs\Python\Python38\lib\json\decoder.py", line 355, in raw_decode
    raise JSONDecodeError("Expecting value", s, err.value) from None
json.decoder.JSONDecodeError: Expecting value: line 1 column 2 (char 1)
ERROR 2023-11-26 02:56:20,783 django.server Thread-1 564 basehttp basehttp.py 212 django.server log_message 17616 "POST /admin/assessment/test/upload-csv/ HTTP/1.1" 500 110562
ERROR 2023-11-26 03:00:41,131 django.request Thread-1 18484 log log.py 241 django.request log_response 18728 Internal Server Error: /admin/assessment/test/upload-csv/
Traceback (most recent call last):
  File "C:\Users\aky\AppData\Local\Programs\Python\Python38\courseu\lib\site-packages\django\core\handlers\exception.py", line 55, in inner
    response = get_response(request)
  File "C:\Users\aky\AppData\Local\Programs\Python\Python38\courseu\lib\site-packages\django\core\handlers\base.py", line 197, in _get_response
    response = wrapped_callback(request, *callback_args, **callback_kwargs)
  File "C:\Users\aky\AppData\Local\Programs\Python\Python38\eng_ver\apps\assessment\admin.py", line 50, in upload_csv
    options = json.loads(row['options'].replace("'", '"'))
  File "C:\Users\aky\AppData\Local\Programs\Python\Python38\lib\json\__init__.py", line 357, in loads
    return _default_decoder.decode(s)
  File "C:\Users\aky\AppData\Local\Programs\Python\Python38\lib\json\decoder.py", line 337, in decode
    obj, end = self.raw_decode(s, idx=_w(s, 0).end())
  File "C:\Users\aky\AppData\Local\Programs\Python\Python38\lib\json\decoder.py", line 353, in raw_decode
    obj, end = self.scan_once(s, idx)
json.decoder.JSONDecodeError: Expecting ',' delimiter: line 1 column 7 (char 6)
ERROR 2023-11-26 03:00:41,275 django.server Thread-1 18484 basehttp basehttp.py 212 django.server log_message 18728 "POST /admin/assessment/test/upload-csv/ HTTP/1.1" 500 112382
WARNING 2023-11-26 15:50:06,347 django.request Thread-4 12384 log log.py 241 django.request log_response 15864 Not Found: /favicon.ico
WARNING 2023-11-26 15:50:06,353 django.server Thread-4 12384 basehttp basehttp.py 212 django.server log_message 15864 "GET /favicon.ico HTTP/1.1" 404 26451
WARNING 2023-11-26 15:50:08,230 django.server Thread-8 7016 basehttp basehttp.py 212 django.server log_message 15864 "GET /static/images/favicon.png HTTP/1.1" 404 1914
ERROR 2023-11-26 15:50:15,360 django.request Thread-1 15596 log log.py 241 django.request log_response 15864 Internal Server Error: /recommender/
Traceback (most recent call last):
  File "C:\Users\aky\AppData\Local\Programs\Python\Python38\courseu\lib\site-packages\django\db\models\fields\__init__.py", line 2053, in get_prep_value
    return int(value)
TypeError: int() argument must be a string, a bytes-like object or a number, not 'SimpleLazyObject'

The above exception was the direct cause of the following exception:

Traceback (most recent call last):
  File "C:\Users\aky\AppData\Local\Programs\Python\Python38\courseu\lib\site-packages\django\core\handlers\exception.py", line 55, in inner
    response = get_response(request)
  File "C:\Users\aky\AppData\Local\Programs\Python\Python38\courseu\lib\site-packages\django\core\handlers\base.py", line 197, in _get_response
    response = wrapped_callback(request, *callback_args, **callback_kwargs)
  File "C:\Users\aky\AppData\Local\Programs\Python\Python38\eng_ver\apps\recommender\views.py", line 54, in recommender
    user_skills = UserSkill.objects.filter(user=request.user)
  File "C:\Users\aky\AppData\Local\Programs\Python\Python38\courseu\lib\site-packages\django\db\models\manager.py", line 87, in manager_method
    return getattr(self.get_queryset(), name)(*args, **kwargs)
  File "C:\Users\aky\AppData\Local\Programs\Python\Python38\courseu\lib\site-packages\django\db\models\query.py", line 1436, in filter
    return self._filter_or_exclude(False, args, kwargs)
  File "C:\Users\aky\AppData\Local\Programs\Python\Python38\courseu\lib\site-packages\django\db\models\query.py", line 1454, in _filter_or_exclude
    clone._filter_or_exclude_inplace(negate, args, kwargs)
  File "C:\Users\aky\AppData\Local\Programs\Python\Python38\courseu\lib\site-packages\django\db\models\query.py", line 1461, in _filter_or_exclude_inplace
    self._query.add_q(Q(*args, **kwargs))
  File "C:\Users\aky\AppData\Local\Programs\Python\Python38\courseu\lib\site-packages\django\db\models\sql\query.py", line 1545, in add_q
    clause, _ = self._add_q(q_object, self.used_aliases)
  File "C:\Users\aky\AppData\Local\Programs\Python\Python38\courseu\lib\site-packages\django\db\models\sql\query.py", line 1576, in _add_q
    child_clause, needed_inner = self.build_filter(
  File "C:\Users\aky\AppData\Local\Programs\Python\Python38\courseu\lib\site-packages\django\db\models\sql\query.py", line 1491, in build_filter
    condition = self.build_lookup(lookups, col, value)
  File "C:\Users\aky\AppData\Local\Programs\Python\Python38\courseu\lib\site-packages\django\db\models\sql\query.py", line 1318, in build_lookup
    lookup = lookup_class(lhs, rhs)
  File "C:\Users\aky\AppData\Local\Programs\Python\Python38\courseu\lib\site-packages\django\db\models\lookups.py", line 27, in __init__
    self.rhs = self.get_prep_lookup()
  File "C:\Users\aky\AppData\Local\Programs\Python\Python38\courseu\lib\site-packages\django\db\models\fields\related_lookups.py", line 166, in get_prep_lookup
    self.rhs = target_field.get_prep_value(self.rhs)
  File "C:\Users\aky\AppData\Local\Programs\Python\Python38\courseu\lib\site-packages\django\db\models\fields\__init__.py", line 2055, in get_prep_value
    raise e.__class__(
TypeError: Field 'id' expected a number but got <SimpleLazyObject: <django.contrib.auth.models.AnonymousUser object at 0x000001900C739A30>>.
ERROR 2023-11-26 15:50:20,074 django.request Thread-2 7808 log log.py 241 django.request log_response 15864 Internal Server Error: /recommender/
Traceback (most recent call last):
  File "C:\Users\aky\AppData\Local\Programs\Python\Python38\courseu\lib\site-packages\django\db\models\fields\__init__.py", line 2053, in get_prep_value
    return int(value)
TypeError: int() argument must be a string, a bytes-like object or a number, not 'SimpleLazyObject'

The above exception was the direct cause of the following exception:

Traceback (most recent call last):
  File "C:\Users\aky\AppData\Local\Programs\Python\Python38\courseu\lib\site-packages\django\core\handlers\exception.py", line 55, in inner
    response = get_response(request)
  File "C:\Users\aky\AppData\Local\Programs\Python\Python38\courseu\lib\site-packages\django\core\handlers\base.py", line 197, in _get_response
    response = wrapped_callback(request, *callback_args, **callback_kwargs)
  File "C:\Users\aky\AppData\Local\Programs\Python\Python38\eng_ver\apps\recommender\views.py", line 54, in recommender
    user_skills = UserSkill.objects.filter(user=request.user)
  File "C:\Users\aky\AppData\Local\Programs\Python\Python38\courseu\lib\site-packages\django\db\models\manager.py", line 87, in manager_method
    return getattr(self.get_queryset(), name)(*args, **kwargs)
  File "C:\Users\aky\AppData\Local\Programs\Python\Python38\courseu\lib\site-packages\django\db\models\query.py", line 1436, in filter
    return self._filter_or_exclude(False, args, kwargs)
  File "C:\Users\aky\AppData\Local\Programs\Python\Python38\courseu\lib\site-packages\django\db\models\query.py", line 1454, in _filter_or_exclude
    clone._filter_or_exclude_inplace(negate, args, kwargs)
  File "C:\Users\aky\AppData\Local\Programs\Python\Python38\courseu\lib\site-packages\django\db\models\query.py", line 1461, in _filter_or_exclude_inplace
    self._query.add_q(Q(*args, **kwargs))
  File "C:\Users\aky\AppData\Local\Programs\Python\Python38\courseu\lib\site-packages\django\db\models\sql\query.py", line 1545, in add_q
    clause, _ = self._add_q(q_object, self.used_aliases)
  File "C:\Users\aky\AppData\Local\Programs\Python\Python38\courseu\lib\site-packages\django\db\models\sql\query.py", line 1576, in _add_q
    child_clause, needed_inner = self.build_filter(
  File "C:\Users\aky\AppData\Local\Programs\Python\Python38\courseu\lib\site-packages\django\db\models\sql\query.py", line 1491, in build_filter
    condition = self.build_lookup(lookups, col, value)
  File "C:\Users\aky\AppData\Local\Programs\Python\Python38\courseu\lib\site-packages\django\db\models\sql\query.py", line 1318, in build_lookup
    lookup = lookup_class(lhs, rhs)
  File "C:\Users\aky\AppData\Local\Programs\Python\Python38\courseu\lib\site-packages\django\db\models\lookups.py", line 27, in __init__
    self.rhs = self.get_prep_lookup()
  File "C:\Users\aky\AppData\Local\Programs\Python\Python38\courseu\lib\site-packages\django\db\models\fields\related_lookups.py", line 166, in get_prep_lookup
    self.rhs = target_field.get_prep_value(self.rhs)
  File "C:\Users\aky\AppData\Local\Programs\Python\Python38\courseu\lib\site-packages\django\db\models\fields\__init__.py", line 2055, in get_prep_value
    raise e.__class__(
TypeError: Field 'id' expected a number but got <SimpleLazyObject: <django.contrib.auth.models.AnonymousUser object at 0x000001900CBB2190>>.
WARNING 2023-11-26 15:56:31,829 django.server Thread-16 7948 basehttp basehttp.py 212 django.server log_message 15864 "GET /static/images/favicon.png HTTP/1.1" 404 1914
WARNING 2023-11-26 15:57:53,386 django.request Thread-15 2036 log log.py 241 django.request log_response 15864 Not Found: /images/profile_pics/WIN_20230530_14_55_43_Pro.jpg
WARNING 2023-11-26 15:57:53,390 django.server Thread-15 2036 basehttp basehttp.py 212 django.server log_message 15864 "GET /images/profile_pics/WIN_20230530_14_55_43_Pro.jpg HTTP/1.1" 404 26726
WARNING 2023-11-26 15:57:53,410 django.request Thread-17 11636 log log.py 241 django.request log_response 15864 Not Found: /images/profile_pics/IMG_3477_YVMV930.jpg
WARNING 2023-11-26 15:57:53,415 django.server Thread-17 11636 basehttp basehttp.py 212 django.server log_message 15864 "GET /images/profile_pics/IMG_3477_YVMV930.jpg HTTP/1.1" 404 26681
WARNING 2023-11-26 15:58:15,137 django.request Thread-15 2036 log log.py 241 django.request log_response 15864 Not Found: /images/profile_pics/WIN_20230530_14_55_43_Pro.jpg
WARNING 2023-11-26 15:58:15,140 django.server Thread-15 2036 basehttp basehttp.py 212 django.server log_message 15864 "GET /images/profile_pics/WIN_20230530_14_55_43_Pro.jpg HTTP/1.1" 404 26726
WARNING 2023-11-26 16:06:46,934 django.server Thread-25 11492 basehttp basehttp.py 212 django.server log_message 15864 "GET /static/images/favicon.png HTTP/1.1" 404 1914
WARNING 2023-11-26 16:14:34,423 django.server Thread-29 15624 basehttp basehttp.py 212 django.server log_message 15864 "GET /static/images/favicon.png HTTP/1.1" 404 1914
WARNING 2023-11-26 16:16:16,174 django.server Thread-21 7104 basehttp basehttp.py 212 django.server log_message 15864 "GET /static/images/favicon.png HTTP/1.1" 404 1914
WARNING 2023-11-26 16:20:06,311 django.server Thread-30 5032 basehttp basehttp.py 212 django.server log_message 15864 "GET /static/images/favicon.png HTTP/1.1" 404 1914
WARNING 2023-11-26 16:44:34,779 django.server Thread-34 1576 basehttp basehttp.py 212 django.server log_message 15864 "GET /static/images/favicon.png HTTP/1.1" 404 1914
WARNING 2023-11-26 17:49:45,727 django.server Thread-117 22156 basehttp basehttp.py 212 django.server log_message 15864 "GET /static/images/favicon.png HTTP/1.1" 404 1914
WARNING 2023-11-26 18:28:05,809 django.request Thread-23 11128 log log.py 241 django.request log_response 13240 Not Found: /images/profile_pics/IMG_3477_YVMV930.jpg
WARNING 2023-11-26 18:28:05,814 django.server Thread-23 11128 basehttp basehttp.py 212 django.server log_message 13240 "GET /images/profile_pics/IMG_3477_YVMV930.jpg HTTP/1.1" 404 26681
WARNING 2023-11-26 18:28:05,875 django.request Thread-24 12012 log log.py 241 django.request log_response 13240 Not Found: /images/profile_pics/WIN_20230530_14_55_43_Pro.jpg
WARNING 2023-11-26 18:28:05,881 django.server Thread-24 12012 basehttp basehttp.py 212 django.server log_message 13240 "GET /images/profile_pics/WIN_20230530_14_55_43_Pro.jpg HTTP/1.1" 404 26726
WARNING 2023-11-26 19:06:35,749 django.server Thread-13 12264 basehttp basehttp.py 212 django.server log_message 22432 "GET /static/images/favicon.png HTTP/1.1" 404 1914
WARNING 2023-11-26 19:08:36,289 django.server Thread-25 20676 basehttp basehttp.py 212 django.server log_message 22432 "GET /static/images/favicon.png HTTP/1.1" 404 1914
WARNING 2023-11-26 19:10:26,795 django.server Thread-35 21416 basehttp basehttp.py 212 django.server log_message 22432 "GET /static/images/favicon.png HTTP/1.1" 404 1914
ERROR 2023-11-26 19:30:46,542 django.request Thread-1 22000 log log.py 241 django.request log_response 22720 Internal Server Error: /home
Traceback (most recent call last):
  File "C:\Users\aky\AppData\Local\Programs\Python\Python38\courseu\lib\site-packages\django\core\handlers\exception.py", line 55, in inner
    response = get_response(request)
  File "C:\Users\aky\AppData\Local\Programs\Python\Python38\courseu\lib\site-packages\django\core\handlers\base.py", line 197, in _get_response
    response = wrapped_callback(request, *callback_args, **callback_kwargs)
  File "C:\Users\aky\AppData\Local\Programs\Python\Python38\courseu\lib\site-packages\django\contrib\auth\decorators.py", line 23, in _wrapper_view
    return view_func(request, *args, **kwargs)
  File "C:\Users\aky\AppData\Local\Programs\Python\Python38\eng_ver\apps\website\views.py", line 73, in home
    highest_skill_level = user_skills.order_by('-skill_level').first()
  File "C:\Users\aky\AppData\Local\Programs\Python\Python38\courseu\lib\site-packages\django\db\models\query.py", line 1659, in order_by
    obj.query.add_ordering(*field_names)
  File "C:\Users\aky\AppData\Local\Programs\Python\Python38\courseu\lib\site-packages\django\db\models\sql\query.py", line 2221, in add_ordering
    self.names_to_path(item.split(LOOKUP_SEP), self.model._meta)
  File "C:\Users\aky\AppData\Local\Programs\Python\Python38\courseu\lib\site-packages\django\db\models\sql\query.py", line 1724, in names_to_path
    raise FieldError(
django.core.exceptions.FieldError: Cannot resolve keyword 'skill_level' into field. Choices are: id, level, skill, skill_id, user, user_id, userskillsource
ERROR 2023-11-26 19:30:47,478 django.server Thread-1 22000 basehttp basehttp.py 212 django.server log_message 22720 "GET /home HTTP/1.1" 500 120313
WARNING 2023-11-26 19:30:50,076 django.request Thread-1 22000 log log.py 241 django.request log_response 22720 Not Found: /favicon.ico
WARNING 2023-11-26 19:30:50,078 django.server Thread-1 22000 basehttp basehttp.py 212 django.server log_message 22720 "GET /favicon.ico HTTP/1.1" 404 26452
WARNING 2023-11-26 20:04:40,819 django.request Thread-115 9064 log log.py 241 django.request log_response 20932 Not Found: /images/profile_pics/WIN_20230530_14_55_43_Pro.jpg
WARNING 2023-11-26 20:04:40,833 django.request Thread-116 22656 log log.py 241 django.request log_response 20932 Not Found: /images/profile_pics/IMG_3477_YVMV930.jpg
WARNING 2023-11-26 20:04:40,835 django.server Thread-115 9064 basehttp basehttp.py 212 django.server log_message 20932 "GET /images/profile_pics/WIN_20230530_14_55_43_Pro.jpg HTTP/1.1" 404 26726
WARNING 2023-11-26 20:04:40,836 django.server Thread-116 22656 basehttp basehttp.py 212 django.server log_message 20932 "GET /images/profile_pics/IMG_3477_YVMV930.jpg HTTP/1.1" 404 26681
WARNING 2023-11-26 20:08:30,511 django.server Thread-126 11128 basehttp basehttp.py 212 django.server log_message 20932 "GET /static/images/favicon.png HTTP/1.1" 404 1914
WARNING 2023-11-26 20:11:47,986 django.server Thread-132 6756 basehttp basehttp.py 212 django.server log_message 20932 "GET /static/images/favicon.png HTTP/1.1" 404 1914
WARNING 2023-11-26 20:34:37,021 django.server Thread-154 6568 basehttp basehttp.py 212 django.server log_message 20932 "GET /static/images/favicon.png HTTP/1.1" 404 1914
WARNING 2023-11-26 20:35:58,802 django.server Thread-160 5096 basehttp basehttp.py 212 django.server log_message 20932 "GET /static/images/favicon.png HTTP/1.1" 404 1914
WARNING 2023-11-26 20:36:59,112 django.server Thread-162 5860 basehttp basehttp.py 212 django.server log_message 20932 "GET /static/images/favicon.png HTTP/1.1" 404 1914
WARNING 2023-11-26 21:09:00,685 django.server Thread-257 1576 basehttp basehttp.py 212 django.server log_message 20932 "GET /static/images/favicon.png HTTP/1.1" 404 1914
